File: DataAnalyzer/TestFiles/CompiledData.csv
Specimen properties : Specimen label,"orgn_80_NA_2_wblk_3ptbnd_run1"
Maximum Load : Flexure extension at Maximum Load,"1.50294",in
Maximum Load : Maximum Load,"131.18347",lbf

Time,Extension,Load
(s),(in),(lbf)
"0.00000","0.71953","15.15737"
"0.40000","0.72036","15.38442"
"0.80000","0.72057","15.22249"
"1.20000","0.72104","14.79037"
"1.60000","0.72156","15.23481"
"2.00000","0.72211","15.07904"
"2.40000","0.72264","14.79037"
"2.80000","0.72316","14.69797"
"3.20000","0.72367","14.59236"
"3.60000","0.72420","15.15296"
"4.00000","0.72473","15.33690"
"4.40000","0.72527","14.93031"
"4.80000","0.72578","15.01391"
"5.20000","0.72631","14.99191"
"5.60000","0.72683","14.96639"
"6.00000","0.72736","15.12832"
"6.40000","0.72789","15.19433"
"6.80000","0.72840","15.18465"
"7.20000","0.72894","15.44515"
"7.60000","0.72947","15.22865"
"8.00000","0.72997","15.53228"
"8.40000","0.73049","15.56044"
"8.80000","0.73102","15.78574"
"9.20000","0.73155","15.44867"
"9.60000","0.73208","15.49355"
"10.00000","0.73259","15.32546"
"10.40000","0.73312","15.57364"
"10.80000","0.73365","15.85526"
"11.20000","0.73418","15.92039"
"11.60000","0.73469","15.84294"
"12.00000","0.73523","15.64317"
"12.40000","0.73575","15.80246"
"12.80000","0.73630","16.28210"
"13.20000","0.73678","16.06120"
"13.60000","0.73732","16.21961"
"14.00000","0.73786","16.03832"
"14.40000","0.73839","16.30410"
"14.80000","0.73891","15.96087"
"15.20000","0.73943","15.97055"
"15.60000","0.73997","16.34810"
"16.00000","0.74048","16.49508"
"16.40000","0.74100","16.17209"
"16.80000","0.74153","16.47395"
"17.20000","0.74205","16.78902"
"17.60000","0.74258","16.73093"
"18.00000","0.74311","16.87527"
"18.40000","0.74362","16.62709"
"18.80000","0.74414","16.87439"
"19.20000","0.74469","16.70717"
"19.60000","0.74521","16.51532"
"20.00000","0.74573","16.95359"
"20.40000","0.74625","16.89111"
"20.80000","0.74679","17.01432"
"21.20000","0.74731","16.88231"
"21.60000","0.74782","17.09353"
"22.00000","0.74836","16.71509"
"22.40000","0.74888","16.73798"
"22.80000","0.74940","16.94303"
"23.20000","0.74992","17.18329"
"23.60000","0.75044","17.35755"
"24.00000","0.75097","17.02488"
"24.40000","0.75151","17.38307"
"24.80000","0.75201","17.27482"
"25.20000","0.75254","17.76326"
"25.60000","0.75308","17.48340"
"26.00000","0.75361","17.47283"
"26.40000","0.75413","17.38923"
"26.80000","0.75465","17.95952"
"27.20000","0.75519","17.82662"
"27.60000","0.75571","17.70782"
"28.00000","0.75622","18.03696"
"28.40000","0.75674","18.16457"
"28.80000","0.75727","18.07216"
"29.20000","0.75781","18.05192"
"29.60000","0.75834","18.15313"
"30.00000","0.75884","18.10561"
"30.40000","0.75937","18.26050"
"30.80000","0.75991","18.04136"
"31.20000","0.76043","17.42355"
"31.60000","0.76094","18.34851"
"32.00000","0.76148","18.20330"
"32.40000","0.76201","18.22530"
"32.80000","0.76255","18.58437"
"33.20000","0.76304","18.61869"
"33.60000","0.76358","18.66974"
"34.00000","0.76410","18.68469"
"34.40000","0.76463","18.62749"
"34.80000","0.76515","18.85543"
"35.20000","0.76568","18.83695"
"35.60000","0.76620","18.86071"
"36.00000","0.76673","18.82463"
"36.40000","0.76726","18.78854"
"36.80000","0.76777","19.30163"
"37.20000","0.76830","18.94960"
"37.60000","0.76883","19.04200"
"38.00000","0.76934","18.87391"
"38.40000","0.76986","19.43276"
"38.80000","0.77039","19.08249"
"39.20000","0.77094","18.99624"
"39.60000","0.77145","19.55245"
"40.00000","0.77198","19.29371"
"40.40000","0.77251","19.48028"
"40.80000","0.77303","19.78567"
"41.20000","0.77356","19.48468"
"41.60000","0.77407","19.66510"
"42.00000","0.77460","19.85607"
"42.40000","0.77514","19.75927"
"42.80000","0.77566","19.88511"
"43.20000","0.77617","19.68622"
"43.60000","0.77669","19.64309"
"44.00000","0.77723","20.00656"
"44.40000","0.77777","19.88775"
"44.80000","0.77827","19.96080"
"45.20000","0.77879","20.37708"
"45.60000","0.77933","19.98720"
"46.00000","0.77985","20.06377"
"46.40000","0.78038","20.08313"
"46.80000","0.78090","20.26707"
"47.20000","0.78142","20.11217"
"47.60000","0.78196","20.72294"
"48.00000","0.78248","20.58565"
"48.40000","0.78299","20.63318"
"48.80000","0.78352","20.67894"
"49.20000","0.78406","20.65430"
"49.60000","0.78458","20.61821"
"50.00000","0.78509","20.68422"
"50.40000","0.78562","21.06001"
"50.80000","0.78616","21.19994"
"51.20000","0.78667","21.02921"
"51.60000","0.78719","21.11281"
"52.00000","0.78772","20.61909"
"52.40000","0.78824","21.17266"
"52.80000","0.78877","21.43404"
"53.20000","0.78927","20.76695"
"53.60000","0.78981","21.08465"
"54.00000","0.79035","21.07585"
"54.40000","0.79088","21.32931"
"54.80000","0.79139","21.91896"
"55.20000","0.79191","21.15682"
"55.60000","0.79245","21.63646"
"56.00000","0.79298","21.70510"
"56.40000","0.79349","21.59509"
"56.80000","0.79402","21.63030"
"57.20000","0.79455","21.34692"
"57.60000","0.79508","21.78519"
"58.00000","0.79560","22.02281"
"58.40000","0.79612","21.84239"
"58.80000","0.79663","21.57925"
"59.20000","0.79718","22.08442"
"59.60000","0.79770","22.01929"
"60.00000","0.79823","22.39420"
"60.40000","0.79874","22.28947"
"60.80000","0.79927","22.67582"
"61.20000","0.79981","22.15306"
"61.60000","0.80031","22.24107"
"62.00000","0.80085","22.65206"
"62.40000","0.80138","22.45141"
"62.80000","0.80190","22.23491"
"63.20000","0.80242","22.77791"
"63.60000","0.80294","22.86064"
"64.00000","0.80349","22.47429"
"64.40000","0.80401","22.69695"
"64.80000","0.80452","22.85448"
"65.20000","0.80503","22.92840"
"65.60000","0.80557","23.10618"
"66.00000","0.80609","23.16778"
"66.40000","0.80662","23.12906"
"66.80000","0.80713","23.07009"
"67.20000","0.80767","23.48725"
"67.60000","0.80821","23.49605"
"68.00000","0.80871","23.34556"
"68.40000","0.80923","23.62454"
"68.80000","0.80976","23.42564"
"69.20000","0.81031","23.44501"
"69.60000","0.81083","23.86392"
"70.00000","0.81134","23.99857"
"70.40000","0.81188","23.84368"
"70.80000","0.81240","23.97481"
"71.20000","0.81292","24.09714"
"71.60000","0.81345","23.81288"
"72.00000","0.81396","23.94753"
"72.40000","0.81449","24.29868"
"72.80000","0.81503","23.92113"
"73.20000","0.81553","24.31100"
"73.60000","0.81607","24.28900"
"74.00000","0.81660","24.40869"
"74.40000","0.81713","24.27052"
"74.80000","0.81765","24.17547"
"75.20000","0.81817","24.50462"
"75.60000","0.81870","24.12178"
"76.00000","0.81922","24.45621"
"76.40000","0.81975","25.14267"
"76.80000","0.82028","24.64454"
"77.20000","0.82080","25.08194"
"77.60000","0.82132","24.87512"
"78.00000","0.82185","24.80384"
"78.40000","0.82235","24.76424"
"78.80000","0.82289","24.89713"
"79.20000","0.82343","25.34772"
"79.60000","0.82395","25.40317"
"80.00000","0.82446","24.95961"
"80.40000","0.82499","25.45685"
"80.80000","0.82552","25.41373"
"81.20000","0.82604","25.60823"
"81.60000","0.82656","25.11098"
"82.00000","0.82710","25.55278"
"82.40000","0.82762","25.55102"
"82.80000","0.82814","25.68831"
"83.20000","0.82867","25.73495"
"83.60000","0.82918","25.94881"
"84.00000","0.82972","25.79128"
"84.40000","0.83026","26.02802"
"84.80000","0.83076","26.06322"
"85.20000","0.83129","25.84937"
"85.60000","0.83182","25.89249"
"86.00000","0.83235","25.79480"
"86.40000","0.83287","26.52350"
"86.80000","0.83339","26.24980"
"87.20000","0.83393","26.33781"
"87.60000","0.83446","26.34837"
"88.00000","0.83497","26.22867"
"88.40000","0.83549","26.15563"
"88.80000","0.83601","25.97257"
"89.20000","0.83654","26.67223"
"89.60000","0.83708","26.64495"
"90.00000","0.83758","26.44429"
"90.40000","0.83811","26.53318"
"90.80000","0.83865","26.68543"
"91.20000","0.83917","26.53670"
"91.60000","0.83969","26.19523"
"92.00000","0.84021","26.48918"
"92.40000","0.84074","26.59038"
"92.80000","0.84127","26.70831"
"93.20000","0.84178","26.71975"
"93.60000","0.84231","26.93185"
"94.00000","0.84285","27.25924"
"94.40000","0.84337","27.33757"
"94.80000","0.84389","27.31028"
"95.20000","0.84440","27.12811"
"95.60000","0.84494","28.01346"
"96.00000","0.84547","27.33140"
"96.40000","0.84599","27.22228"
"96.80000","0.84650","27.63239"
"97.20000","0.84704","27.69840"
"97.60000","0.84757","27.88497"
"98.00000","0.84809","27.87265"
"98.40000","0.84861","27.75472"
"98.80000","0.84914","27.97738"
"99.20000","0.84968","28.32413"
"99.60000","0.85019","28.53359"
"100.00000","0.85071","27.97034"
"100.40000","0.85123","28.29332"
"100.80000","0.85176","28.34877"
"101.20000","0.85229","28.04515"
"101.60000","0.85281","27.97298"
"102.00000","0.85334","28.09619"
"102.40000","0.85387","28.59255"
"102.80000","0.85440","28.24844"
"103.20000","0.85490","28.52831"
"103.60000","0.85543","28.72456"
"104.00000","0.85597","28.53975"
"104.40000","0.85651","28.81169"
"104.80000","0.85701","28.87241"
"105.20000","0.85754","29.11003"
"105.60000","0.85807","29.19980"
"106.00000","0.85859","29.09331"
"106.40000","0.85912","29.04314"
"106.80000","0.85964","29.47174"
"107.20000","0.86017","29.38021"
"107.60000","0.86070","29.28341"
"108.00000","0.86122","29.53247"
"108.40000","0.86172","29.29925"
"108.80000","0.86225","29.72344"
"109.20000","0.86279","29.49375"
"109.60000","0.86332","29.51134"
"110.00000","0.86383","29.88010"
"110.40000","0.86436","29.55271"
"110.80000","0.86490","29.77097"
"111.20000","0.86541","29.83257"
"111.60000","0.86593","29.79121"
"112.00000","0.86647","30.02355"
"112.40000","0.86699","30.23917"
"112.80000","0.86752","30.50759"
"113.20000","0.86803","30.23917"
"113.60000","0.86855","30.49967"
"114.00000","0.86909","30.26381"
"114.40000","0.86962","30.35885"
"114.80000","0.87013","30.59560"
"115.20000","0.87065","30.64488"
"115.60000","0.87119","30.88514"
"116.00000","0.87172","30.66776"
"116.40000","0.87223","30.83673"
"116.80000","0.87276","30.95202"
"117.20000","0.87329","30.84290"
"117.60000","0.87383","30.74169"
"118.00000","0.87434","31.28821"
"118.40000","0.87485","31.13244"
"118.80000","0.87538","30.83233"
"119.20000","0.87592","30.96259"
"119.60000","0.87644","31.34454"
"120.00000","0.87697","31.53199"
"120.40000","0.87748","31.44838"
"120.80000","0.87802","31.03563"
"121.20000","0.87854","31.18084"
"121.60000","0.87905","31.27941"
"122.00000","0.87959","31.44310"
"122.40000","0.88012","32.14100"
"122.80000","0.88063","31.85146"
"123.20000","0.88115","31.49767"
"123.60000","0.88168","31.82858"
"124.00000","0.88220","31.73969"
"124.40000","0.88274","31.93066"
"124.80000","0.88326","32.04771"
"125.20000","0.88377","31.99579"
"125.60000","0.88431","32.13660"
"126.00000","0.88484","32.14364"
"126.40000","0.88537","32.21229"
"126.80000","0.88588","32.26333"
"127.20000","0.88642","32.76497"
"127.60000","0.88696","32.15860"
"128.00000","0.88746","32.41647"
"128.40000","0.88797","32.64000"
"128.80000","0.88850","32.71217"
"129.20000","0.88905","32.73065"
"129.60000","0.88957","32.80898"
"130.00000","0.89008","32.56256"
"130.40000","0.89060","32.65057"
"130.80000","0.89114","32.99555"
"131.20000","0.89166","33.19709"
"131.60000","0.89218","32.90667"
"132.00000","0.89271","33.04748"
"132.40000","0.89323","33.44263"
"132.80000","0.89377","33.39335"
"133.20000","0.89426","33.38542"
"133.60000","0.89481","33.75857"
"134.00000","0.89535","33.78058"
"134.40000","0.89587","33.06508"
"134.80000","0.89639","33.37310"
"135.20000","0.89691","33.58960"
"135.60000","0.89744","33.69433"
"136.00000","0.89796","33.80170"
"136.40000","0.89848","33.80786"
"136.80000","0.89901","33.83954"
"137.20000","0.89953","33.94867"
"137.60000","0.90006","34.29982"
"138.00000","0.90058","34.29366"
"138.40000","0.90109","34.43007"
"138.80000","0.90162","34.14933"
"139.20000","0.90217","34.47759"
"139.60000","0.90269","34.22061"
"140.00000","0.90321","34.36142"
"140.40000","0.90373","34.64745"
"140.80000","0.90427","34.74866"
"141.20000","0.90479","34.54536"
"141.60000","0.90530","34.62985"
"142.00000","0.90585","34.61841"
"142.40000","0.90636","35.20981"
"142.80000","0.90689","34.59200"
"143.20000","0.90741","34.85074"
"143.60000","0.90792","35.21334"
"144.00000","0.90846","35.29782"
"144.40000","0.90899","35.35502"
"144.80000","0.90951","35.16229"
"145.20000","0.91002","35.33303"
"145.60000","0.91056","35.31190"
"146.00000","0.91109","35.11917"
"146.40000","0.91161","35.33566"
"146.80000","0.91213","35.94467"
"147.20000","0.91267","35.83115"
"147.60000","0.91320","35.90155"
"148.00000","0.91371","36.05997"
"148.40000","0.91423","35.99484"
"148.80000","0.91475","35.60849"
"149.20000","0.91529","35.84875"
"149.60000","0.91582","36.54225"
"150.00000","0.91634","36.15853"
"150.40000","0.91685","36.12333"
"150.80000","0.91738","35.90771"
"151.20000","0.91789","36.32311"
"151.60000","0.91842","36.64433"
"152.00000","0.91895","36.14093"
"152.40000","0.91948","36.33455"
"152.80000","0.92001","36.48944"
"153.20000","0.92052","36.36447"
"153.60000","0.92105","36.39087"
"154.00000","0.92159","37.01484"
"154.40000","0.92211","36.39087"
"154.80000","0.92264","37.06061"
"155.20000","0.92316","37.38711"
"155.60000","0.92368","36.97084"
"156.00000","0.92421","36.97524"
"156.40000","0.92474","36.83355"
"156.80000","0.92525","37.02453"
"157.20000","0.92578","37.30967"
"157.60000","0.92632","37.32111"
"158.00000","0.92683","37.31143"
"158.40000","0.92734","37.91252"
"158.80000","0.92788","37.60801"
"159.20000","0.92842","37.68458"
"159.60000","0.92893","37.86764"
"160.00000","0.92946","38.01197"
"160.40000","0.92998","37.96972"
"160.80000","0.93050","37.89755"
"161.20000","0.93104","38.12022"
"161.60000","0.93155","37.92044"
"162.00000","0.93208","38.16950"
"162.40000","0.93260","38.14838"
"162.80000","0.93314","37.89667"
"163.20000","0.93364","37.83067"
"163.60000","0.93417","38.32967"
"164.00000","0.93471","38.45464"
"164.40000","0.93525","38.20206"
"164.80000","0.93575","38.62537"
"165.20000","0.93627","38.80315"
"165.60000","0.93681","38.63154"
"166.00000","0.93732","39.18070"
"166.40000","0.93786","38.89204"
"166.80000","0.93837","39.10590"
"167.20000","0.93890","38.64122"
"167.60000","0.93944","39.22294"
"168.00000","0.93995","39.35848"
"168.40000","0.94047","39.37520"
"168.80000","0.94099","39.04341"
"169.20000","0.94154","39.83460"
"169.60000","0.94207","39.49489"
"170.00000","0.94257","39.56089"
"170.40000","0.94311","39.87420"
"170.80000","0.94364","39.48873"
"171.20000","0.94415","39.45088"
"171.60000","0.94468","39.96573"
"172.00000","0.94521","39.91732"
"172.40000","0.94573","39.67794"
"172.80000","0.94626","40.04669"
"173.20000","0.94677","40.32128"
"173.60000","0.94729","40.06694"
"174.00000","0.94783","39.72635"
"174.40000","0.94836","40.02821"
"174.80000","0.94889","40.06342"
"175.20000","0.94939","40.41544"
"175.60000","0.94993","40.37320"
"176.00000","0.95046","40.76659"
"176.40000","0.95097","40.41104"
"176.80000","0.95150","40.80268"
"177.20000","0.95203","41.14767"
"177.60000","0.95257","40.85284"
"178.00000","0.95308","40.85548"
"178.40000","0.95359","41.26383"
"178.80000","0.95412","41.23655"
"179.20000","0.95466","41.39496"
"179.60000","0.95518","40.79388"
"180.00000","0.95569","41.49705"
"180.40000","0.95622","41.46801"
"180.80000","0.95675","41.38000"
"181.20000","0.95728","41.64051"
"181.60000","0.95778","41.36768"
"182.00000","0.95832","41.76988"
"182.40000","0.95886","41.68275"
"182.80000","0.95938","41.74083"
"183.20000","0.95990","41.68275"
"183.60000","0.96042","41.92476"
"184.00000","0.96094","42.13510"
"184.40000","0.96149","41.96173"
"184.80000","0.96200","41.65458"
"185.20000","0.96253","41.79891"
"185.60000","0.96305","41.81916"
"186.00000","0.96358","42.40353"
"186.40000","0.96411","42.17999"
"186.80000","0.96461","42.53378"
"187.20000","0.96515","42.20287"
"187.60000","0.96569","42.58834"
"188.00000","0.96619","42.37008"
"188.40000","0.96672","42.56282"
"188.80000","0.96725","42.65083"
"189.20000","0.96779","42.79252"
"189.60000","0.96831","42.73883"
"190.00000","0.96882","42.77140"
"190.40000","0.96935","43.24223"
"190.80000","0.96988","42.91925"
"191.20000","0.97040","43.10494"
"191.60000","0.97093","43.20263"
"192.00000","0.97145","43.20087"
"192.40000","0.97198","43.50362"
"192.80000","0.97251","43.57226"
"193.20000","0.97301","43.64267"
"193.60000","0.97354","43.60923"
"194.00000","0.97408","43.89437"
"194.40000","0.97461","43.82220"
"194.80000","0.97512","43.53794"
"195.20000","0.97564","44.07302"
"195.60000","0.97616","43.86973"
"196.00000","0.97670","44.11791"
"196.40000","0.97722","44.18743"
"196.80000","0.97775","44.07126"
"197.20000","0.97827","44.38017"
"197.60000","0.97880","44.28688"
"198.00000","0.97933","44.19975"
"198.40000","0.97983","44.46818"
"198.80000","0.98037","44.44969"
"199.20000","0.98091","44.73748"
"199.60000","0.98143","44.45234"
"200.00000","0.98194","44.92670"
"200.40000","0.98247","44.75772"
"200.80000","0.98300","44.81140"
"201.20000","0.98353","44.79204"
"201.60000","0.98404","44.81404"
"202.00000","0.98458","45.04198"
"202.40000","0.98510","45.21799"
"202.80000","0.98563","44.97334"
"203.20000","0.98614","45.55067"
"203.60000","0.98666","45.33681"
"204.00000","0.98720","45.55330"
"204.40000","0.98774","45.75044"
"204.80000","0.98825","45.70292"
"205.20000","0.98877","45.64307"
"205.60000","0.98930","45.68356"
"206.00000","0.98983","45.91765"
"206.40000","0.99035","45.79093"
"206.80000","0.99086","45.94934"
"207.20000","0.99141","46.29433"
"207.60000","0.99195","45.90094"
"208.00000","0.99245","46.09455"
"208.40000","0.99296","46.41490"
"208.80000","0.99348","46.19840"
"209.20000","0.99402","46.45186"
"209.60000","0.99456","46.16320"
"210.00000","0.99506","46.84349"
"210.40000","0.99559","46.57947"
"210.80000","0.99612","46.72644"
"211.20000","0.99664","47.12424"
"211.60000","0.99716","46.62435"
"212.00000","0.99770","47.25273"
"212.40000","0.99823","46.97110"
"212.80000","0.99877","46.90862"
"213.20000","0.99927","46.94118"
"213.60000","0.99980","47.09255"
"214.00000","1.00033","47.37858"
"214.40000","1.00085","47.50355"
"214.80000","1.00138","47.20960"
"215.20000","1.00190","47.09871"
"215.60000","1.00242","47.63204"
"216.00000","1.00295","47.52203"
"216.40000","1.00347","47.90574"
"216.80000","1.00399","47.75613"
"217.20000","1.00452","47.48418"
"217.60000","1.00506","47.57747"
"218.00000","1.00557","48.09759"
"218.40000","1.00608","47.87142"
"218.80000","1.00662","48.10463"
"219.20000","1.00716","48.01135"
"219.60000","1.00767","48.38362"
"220.00000","1.00819","48.58779"
"220.40000","1.00872","48.08615"
"220.80000","1.00925","48.51123"
"221.20000","1.00978","48.51563"
"221.60000","1.01029","48.73125"
"222.00000","1.01082","48.71101"
"222.40000","1.01135","49.00935"
"222.80000","1.01187","49.00583"
"223.20000","1.01238","48.69605"
"223.60000","1.01290","49.05775"
"224.00000","1.01344","48.96095"
"224.40000","1.01398","48.94775"
"224.80000","1.01449","49.37106"
"225.20000","1.01501","49.30066"
"225.60000","1.01555","49.67381"
"226.00000","1.01607","49.69405"
"226.40000","1.01660","49.45379"
"226.80000","1.01712","49.77325"
"227.20000","1.01765","49.89910"
"227.60000","1.01818","49.98095"
"228.00000","1.01869","49.87622"
"228.40000","1.01921","49.55499"
"228.80000","1.01974","50.27401"
"229.20000","1.02028","49.89998"
"229.60000","1.02081","50.05928"
"230.00000","1.02132","50.12528"
"230.40000","1.02184","50.05048"
"230.80000","1.02238","50.37610"
"231.20000","1.02289","50.46147"
"231.60000","1.02342","50.13584"
"232.00000","1.02395","50.48611"
"232.40000","1.02447","50.23177"
"232.80000","1.02500","51.27906"
"233.20000","1.02551","50.68325"
"233.60000","1.02604","50.99743"
"234.00000","1.02657","50.95519"
"234.40000","1.02710","51.14089"
"234.80000","1.02762","51.12504"
"235.20000","1.02813","50.86630"
"235.60000","1.02867","51.33362"
"236.00000","1.02920","51.65573"
"236.40000","1.02971","51.77014"
"236.80000","1.03024","51.42339"
"237.20000","1.03078","51.68125"
"237.60000","1.03129","51.27730"
"238.00000","1.03182","51.45419"
"238.40000","1.03233","51.79566"
"238.80000","1.03285","51.92063"
"239.20000","1.03339","52.19785"
"239.60000","1.03392","52.19169"
"240.00000","1.03445","51.82470"
"240.40000","1.03496","52.16793"
"240.80000","1.03550","51.95583"
"241.20000","1.03603","52.29202"
"241.60000","1.03653","51.97168"
"242.00000","1.03707","52.16881"
"242.40000","1.03760","52.56484"
"242.80000","1.03813","52.43987"
"243.20000","1.03863","52.56836"
"243.60000","1.03916","52.84999"
"244.00000","1.03968","52.85351"
"244.40000","1.04023","52.60620"
"244.80000","1.04074","52.99520"
"245.20000","1.04125","52.93095"
"245.60000","1.04179","53.20201"
"246.00000","1.04232","52.82182"
"246.40000","1.04285","53.31203"
"246.80000","1.04336","53.16857"
"247.20000","1.04390","53.45988"
"247.60000","1.04443","53.01104"
"248.00000","1.04493","53.79342"
"248.40000","1.04546","53.61741"
"248.80000","1.04599","53.76350"
"249.20000","1.04653","54.65765"
"249.60000","1.04704","53.93247"
"250.00000","1.04756","53.84447"
"250.40000","1.04809","53.70629"
"250.80000","1.04862","54.15161"
"251.20000","1.04914","54.24138"
"251.60000","1.04966","53.92807"
"252.00000","1.05018","54.34523"
"252.40000","1.05071","54.29243"
"252.80000","1.05124","54.40155"
"253.20000","1.05175","54.67350"
"253.60000","1.05228","55.06865"
"254.00000","1.05282","54.37691"
"254.40000","1.05335","54.98504"
"254.80000","1.05386","54.77823"
"255.20000","1.05439","55.10034"
"255.60000","1.05492","54.78175"
"256.00000","1.05544","55.02728"
"256.40000","1.05596","55.50781"
"256.80000","1.05650","55.22706"
"257.20000","1.05702","55.53861"
"257.60000","1.05755","55.27370"
"258.00000","1.05808","55.37403"
"258.40000","1.05858","55.38812"
"258.80000","1.05910","55.16017"
"259.20000","1.05965","55.86423"
"259.60000","1.06017","55.87656"
"260.00000","1.06069","55.61693"
"260.40000","1.06121","56.02441"
"260.80000","1.06175","55.71198"
"261.20000","1.06227","56.43188"
"261.60000","1.06278","55.90383"
"262.00000","1.06332","56.45301"
"262.40000","1.06384","56.24795"
"262.80000","1.06437","56.26555"
"263.20000","1.06488","56.31659"
"263.60000","1.06540","56.55157"
"264.00000","1.06594","56.75223"
"264.40000","1.06647","56.45388"
"264.80000","1.06699","56.85696"
"265.20000","1.06750","57.14826"
"265.60000","1.06804","57.16850"
"266.00000","1.06856","56.48997"
"266.40000","1.06908","56.97137"
"266.80000","1.06960","57.03033"
"267.20000","1.07014","57.31108"
"267.60000","1.07068","56.90360"
"268.00000","1.07118","57.16938"
"268.40000","1.07170","57.16674"
"268.80000","1.07222","57.85232"
"269.20000","1.07277","57.62086"
"269.60000","1.07330","57.64990"
"270.00000","1.07382","57.59269"
"270.40000","1.07434","57.94913"
"270.80000","1.07487","57.99665"
"271.20000","1.07539","57.75552"
"271.60000","1.07590","58.02570"
"272.00000","1.07644","58.27212"
"272.40000","1.07697","58.44461"
"272.80000","1.07750","58.63118"
"273.20000","1.07800","58.55549"
"273.60000","1.07854","58.07233"
"274.00000","1.07907","58.46397"
"274.40000","1.07960","58.64262"
"274.80000","1.08011","58.77904"
"275.20000","1.08062","58.72447"
"275.60000","1.08116","59.07738"
"276.00000","1.08169","58.90928"
"276.40000","1.08221","58.48773"
"276.80000","1.08273","59.33437"
"277.20000","1.08326","59.46197"
"277.60000","1.08379","59.22788"
"278.00000","1.08431","59.71719"
"278.40000","1.08483","59.44701"
"278.80000","1.08536","59.57198"
"279.20000","1.08590","59.53942"
"279.60000","1.08641","59.49189"
"280.00000","1.08693","59.53678"
"280.40000","1.08746","59.53238"
"280.80000","1.08798","60.11499"
"281.20000","1.08851","60.13699"
"281.60000","1.08903","59.85008"
"282.00000","1.08955","59.91873"
"282.40000","1.09009","60.54798"
"282.80000","1.09061","60.01818"
"283.20000","1.09112","60.48461"
"283.60000","1.09165","60.73808"
"284.00000","1.09219","60.24964"
"284.40000","1.09273","60.73808"
"284.80000","1.09323","60.41244"
"285.20000","1.09376","61.04963"
"285.60000","1.09429","60.38693"
"286.00000","1.09481","60.69847"
"286.40000","1.09534","60.63511"
"286.80000","1.09586","61.10946"
"287.20000","1.09640","61.06458"
"287.60000","1.09692","60.81640"
"288.00000","1.09743","61.42981"
"288.40000","1.09794","60.90353"
"288.80000","1.09847","61.42541"
"289.20000","1.09902","62.10835"
"289.60000","1.09955","61.12971"
"290.00000","1.10005","62.02475"
"290.40000","1.10058","61.47734"
"290.80000","1.10112","61.68943"
"291.20000","1.10163","61.88569"
"291.60000","1.10216","61.89186"
"292.00000","1.10269","62.15235"
"292.40000","1.10323","62.05994"
"292.80000","1.10374","62.38557"
"293.20000","1.10425","62.27732"
"293.60000","1.10477","62.12595"
"294.00000","1.10531","62.76576"
"294.40000","1.10583","62.75961"
"294.80000","1.10637","62.59063"
"295.20000","1.10687","62.97786"
"295.60000","1.10741","62.98666"
"296.00000","1.10794","62.71032"
"296.40000","1.10845","62.70152"
"296.80000","1.10898","63.14332"
"297.20000","1.10951","63.14772"
"297.60000","1.11003","63.33869"
"298.00000","1.11056","63.13187"
"298.40000","1.11107","63.04035"
"298.80000","1.11160","63.26300"
"299.20000","1.11214","63.81745"
"299.60000","1.11266","63.86586"
"300.00000","1.11318","63.27004"
"300.40000","1.11370","63.46894"
"300.80000","1.11423","63.58951"
"301.20000","1.11477","64.00403"
"301.60000","1.11527","63.84121"
"302.00000","1.11581","63.71448"
"302.40000","1.11634","64.09643"
"302.80000","1.11687","64.50567"
"303.20000","1.11738","64.19852"
"303.60000","1.11790","64.53471"
"304.00000","1.11844","64.36486"
"304.40000","1.11897","64.78113"
"304.80000","1.11948","64.38862"
"305.20000","1.12001","65.03019"
"305.60000","1.12053","64.54615"
"306.00000","1.12106","64.15980"
"306.40000","1.12159","65.06891"
"306.80000","1.12210","64.64120"
"307.20000","1.12263","65.11908"
"307.60000","1.12317","64.82777"
"308.00000","1.12367","65.33557"
"308.40000","1.12420","65.06188"
"308.80000","1.12472","65.48870"
"309.20000","1.12526","65.44734"
"309.60000","1.12577","65.73337"
"310.00000","1.12629","65.51775"
"310.40000","1.12683","65.82754"
"310.80000","1.12736","66.04491"
"311.20000","1.12788","65.90058"
"311.60000","1.12840","66.11180"
"312.00000","1.12892","66.37758"
"312.40000","1.12946","65.91554"
"312.80000","1.12999","66.11180"
"313.20000","1.13049","66.24381"
"313.60000","1.13102","66.23941"
"314.00000","1.13156","66.51839"
"314.40000","1.13209","66.44535"
"314.80000","1.13260","66.80881"
"315.20000","1.13313","66.74281"
"315.60000","1.13366","66.94875"
"316.00000","1.13418","66.86778"
"316.40000","1.13470","67.21717"
"316.80000","1.13524","67.14500"
"317.20000","1.13577","67.20045"
"317.60000","1.13629","67.16788"
"318.00000","1.13681","67.20309"
"318.40000","1.13731","67.08956"
"318.80000","1.13785","67.22773"
"319.20000","1.13839","67.29550"
"319.60000","1.13892","67.22421"
"320.00000","1.13943","67.29021"
"320.40000","1.13995","67.47239"
"320.80000","1.14049","67.92034"
"321.20000","1.14101","67.97843"
"321.60000","1.14152","67.87722"
"322.00000","1.14205","67.79978"
"322.40000","1.14257","68.01540"
"322.80000","1.14310","67.91155"
"323.20000","1.14363","68.32870"
"323.60000","1.14414","68.21165"
"324.00000","1.14467","68.48184"
"324.40000","1.14521","68.25917"
"324.80000","1.14571","68.70449"
"325.20000","1.14625","68.50295"
"325.60000","1.14678","68.74497"
"326.00000","1.14731","68.98084"
"326.40000","1.14783","68.78370"
"326.80000","1.14835","69.16741"
"327.20000","1.14889","68.92715"
"327.60000","1.14942","69.26246"
"328.00000","1.14993","68.94035"
"328.40000","1.15044","69.02747"
"328.80000","1.15097","69.79226"
"329.20000","1.15150","68.94299"
"329.60000","1.15203","69.59072"
"330.00000","1.15256","69.68402"
"330.40000","1.15308","69.43583"
"330.80000","1.15361","69.73418"
"331.20000","1.15413","69.53264"
"331.60000","1.15465","69.82130"
"332.00000","1.15517","69.81691"
"332.40000","1.15570","70.19181"
"332.80000","1.15624","70.33439"
"333.20000","1.15673","70.53329"
"333.60000","1.15728","70.60545"
"334.00000","1.15781","70.69170"
"334.40000","1.15833","70.60545"
"334.80000","1.15885","70.37839"
"335.20000","1.15938","70.78762"
"335.60000","1.15991","71.26374"
"336.00000","1.16044","70.89059"
"336.40000","1.16095","70.92931"
"336.80000","1.16147","71.34559"
"337.20000","1.16200","71.37727"
"337.60000","1.16253","71.26815"
"338.00000","1.16306","71.28751"
"338.40000","1.16356","71.08333"
"338.80000","1.16409","71.39575"
"339.20000","1.16464","71.63865"
"339.60000","1.16515","71.32799"
"340.00000","1.16568","71.58233"
"340.40000","1.16620","71.96428"
"340.80000","1.16673","71.95372"
"341.20000","1.16725","71.83667"
"341.60000","1.16777","71.57881"
"342.00000","1.16830","72.13766"
"342.40000","1.16883","72.04701"
"342.80000","1.16936","72.10510"
"343.20000","1.16987","72.36207"
"343.60000","1.17039","72.67010"
"344.00000","1.17093","72.69122"
"344.40000","1.17147","72.24678"
"344.80000","1.17197","72.56449"
"345.20000","1.17250","72.74315"
"345.60000","1.17303","72.85755"
"346.00000","1.17355","73.09605"
"346.40000","1.17408","72.76162"
"346.80000","1.17460","73.26943"
"347.20000","1.17514","73.43312"
"347.60000","1.17566","72.93588"
"348.00000","1.17618","73.33631"
"348.40000","1.17669","73.32487"
"348.80000","1.17722","73.95412"
"349.20000","1.17776","73.71475"
"349.60000","1.17829","73.70858"
"350.00000","1.17880","73.62498"
"350.40000","1.17932","74.12134"
"350.80000","1.17986","73.75347"
"351.20000","1.18037","74.58865"
"351.60000","1.18089","74.51561"
"352.00000","1.18142","74.18734"
"352.40000","1.18194","74.46193"
"352.80000","1.18247","74.44960"
"353.20000","1.18298","74.37568"
"353.60000","1.18351","74.58602"
"354.00000","1.18405","74.72331"
"354.40000","1.18457","74.73123"
"354.80000","1.18510","74.92837"
"355.20000","1.18561","74.98205"
"355.60000","1.18615","75.14310"
"356.00000","1.18668","75.12902"
"356.40000","1.18719","75.24783"
"356.80000","1.18772","74.90020"
"357.20000","1.18826","75.15719"
"357.60000","1.18879","75.17918"
"358.00000","1.18930","75.72747"
"358.40000","1.18981","75.52329"
"358.80000","1.19034","75.21526"
"359.20000","1.19088","75.34815"
"359.60000","1.19140","75.55234"
"360.00000","1.19193","75.94485"
"360.40000","1.19244","76.25640"
"360.80000","1.19298","75.88236"
"361.20000","1.19350","76.18686"
"361.60000","1.19401","76.22295"
"362.00000","1.19455","76.28367"
"362.40000","1.19508","76.61986"
"362.80000","1.19561","76.58114"
"363.20000","1.19612","76.77828"
"363.60000","1.19664","76.60667"
"364.00000","1.19718","76.59522"
"364.40000","1.19771","76.67883"
"364.80000","1.19822","77.06606"
"365.20000","1.19873","77.24912"
"365.60000","1.19927","77.31952"
"366.00000","1.19979","77.39433"
"366.40000","1.20032","77.15318"
"366.80000","1.20083","77.53249"
"367.20000","1.20137","77.97870"
"367.60000","1.20191","77.71116"
"368.00000","1.20243","77.75604"
"368.40000","1.20294","77.90653"
"368.80000","1.20347","77.65131"
"369.20000","1.20401","77.65659"
"369.60000","1.20452","77.71995"
"370.00000","1.20504","78.17935"
"370.40000","1.20557","78.21103"
"370.80000","1.20610","78.56130"
"371.20000","1.20662","78.51730"
"371.60000","1.20714","78.72147"
"372.00000","1.20767","78.32456"
"372.40000","1.20820","78.57274"
"372.80000","1.20874","78.87461"
"373.20000","1.20923","79.02686"
"373.60000","1.20976","78.76020"
"374.00000","1.21030","78.94853"
"374.40000","1.21083","79.27856"
"374.80000","1.21134","78.89045"
"375.20000","1.21186","78.98198"
"375.60000","1.21240","79.17911"
"376.00000","1.21292","79.46514"
"376.40000","1.21345","79.38593"
"376.80000","1.21397","79.61563"
"377.20000","1.21449","79.54082"
"377.60000","1.21502","79.36217"
"378.00000","1.21555","79.44049"
"378.40000","1.21605","79.60507"
"378.80000","1.21659","80.00638"
"379.20000","1.21713","80.27744"
"379.60000","1.21765","80.56523"
"380.00000","1.21817","80.25104"
"380.40000","1.21869","80.24048"
"380.80000","1.21922","80.58195"
"381.20000","1.21974","80.27128"
"381.60000","1.22025","80.68140"
"382.00000","1.22080","80.71835"
"382.40000","1.22132","81.19272"
"382.80000","1.22185","80.58371"
"383.20000","1.22237","80.89614"
"383.60000","1.22288","80.41826"
"384.00000","1.22342","80.93134"
"384.40000","1.22396","81.29305"
"384.80000","1.22447","81.26576"
"385.20000","1.22499","81.37930"
"385.60000","1.22552","81.41889"
"386.00000","1.22605","81.69877"
"386.40000","1.22657","81.39778"
"386.80000","1.22708","81.66004"
"387.20000","1.22762","81.87390"
"387.60000","1.22816","82.03671"
"388.00000","1.22866","81.65652"
"388.40000","1.22919","81.85365"
"388.80000","1.22970","81.87302"
"389.20000","1.23025","82.03231"
"389.60000","1.23078","82.35529"
"390.00000","1.23129","82.53043"
"390.40000","1.23181","82.51811"
"390.80000","1.23235","82.50931"
"391.20000","1.23287","82.65188"
"391.60000","1.23339","83.02503"
"392.00000","1.23392","82.81734"
"392.40000","1.23445","82.29457"
"392.80000","1.23499","83.02767"
"393.20000","1.23548","83.09456"
"393.60000","1.23601","82.57708"
"394.00000","1.23653","82.94934"
"394.40000","1.23707","82.92206"
"394.80000","1.23759","83.88134"
"395.20000","1.23810","83.23801"
"395.60000","1.23864","83.88574"
"396.00000","1.23917","83.58739"
"396.40000","1.23969","83.86374"
"396.80000","1.24020","83.53107"
"397.20000","1.24074","84.15593"
"397.60000","1.24128","84.15680"
"398.00000","1.24180","84.00896"
"398.40000","1.24231","84.02391"
"398.80000","1.24284","84.02743"
"399.20000","1.24338","84.48595"
"399.60000","1.24389","84.31610"
"400.00000","1.24441","84.62060"
"400.40000","1.24494","84.85822"
"400.80000","1.24546","84.77461"
"401.20000","1.24600","84.70421"
"401.60000","1.24651","84.67956"
"402.00000","1.24704","84.77989"
"402.40000","1.24757","85.11256"
"402.80000","1.24810","84.42610"
"403.20000","1.24860","85.58516"
"403.60000","1.24913","84.97439"
"404.00000","1.24967","85.53500"
"404.40000","1.25021","85.47691"
"404.80000","1.25071","85.58956"
"405.20000","1.25124","85.55083"
"405.60000","1.25177","85.88966"
"406.00000","1.25229","86.00055"
"406.40000","1.25282","85.76469"
"406.80000","1.25334","86.16777"
"407.20000","1.25386","85.99439"
"407.60000","1.25440","86.19329"
"408.00000","1.25492","86.09912"
"408.40000","1.25542","86.35259"
"408.80000","1.25595","85.88614"
"409.20000","1.25650","86.20034"
"409.60000","1.25703","86.59812"
"410.00000","1.25753","86.75126"
"410.40000","1.25806","87.30306"
"410.80000","1.25860","87.17017"
"411.20000","1.25911","87.09889"
"411.60000","1.25963","87.10064"
"412.00000","1.26017","86.99592"
"412.40000","1.26071","87.26522"
"412.80000","1.26123","86.96512"
"413.20000","1.26173","87.22649"
"413.60000","1.26225","87.27402"
"414.00000","1.26279","87.09624"
"414.40000","1.26332","87.45532"
"414.80000","1.26385","87.62077"
"415.20000","1.26436","88.05288"
"415.60000","1.26489","87.85135"
"416.00000","1.26542","87.73782"
"416.40000","1.26593","87.82230"
"416.80000","1.26646","87.99216"
"417.20000","1.26699","88.30107"
"417.60000","1.26753","88.38907"
"418.00000","1.26804","88.32218"
"418.40000","1.26855","88.12153"
"418.80000","1.26908","88.66717"
"419.20000","1.26962","88.42339"
"419.60000","1.27014","88.56156"
"420.00000","1.27066","88.76222"
"420.40000","1.27118","89.38883"
"420.80000","1.27171","88.95584"
"421.20000","1.27224","89.04472"
"421.60000","1.27275","89.30523"
"422.00000","1.27329","89.73030"
"422.40000","1.27382","89.69510"
"422.80000","1.27435","89.62821"
"423.20000","1.27485","89.65198"
"423.60000","1.27538","90.07353"
"424.00000","1.27592","89.73030"
"424.40000","1.27645","89.93800"
"424.80000","1.27696","90.48189"
"425.20000","1.27749","90.18354"
"425.60000","1.27801","90.21434"
"426.00000","1.27854","90.35867"
"426.40000","1.27907","89.82006"
"426.80000","1.27958","90.68694"
"427.20000","1.28012","90.25219"
"427.60000","1.28065","90.47484"
"428.00000","1.28115","90.49948"
"428.40000","1.28168","91.02489"
"428.80000","1.28221","90.79431"
"429.20000","1.28274","91.02225"
"429.60000","1.28327","90.86735"
"430.00000","1.28378","90.71334"
"430.40000","1.28431","91.44908"
"430.80000","1.28484","91.09969"
"431.20000","1.28536","91.45965"
"431.60000","1.28588","91.65502"
"432.00000","1.28640","91.81519"
"432.40000","1.28694","91.97184"
"432.80000","1.28747","91.98329"
"433.20000","1.28796","91.45173"
"433.60000","1.28851","92.03169"
"434.00000","1.28904","91.80111"
"434.40000","1.28957","91.81519"
"434.80000","1.29009","92.36964"
"435.20000","1.29060","92.16723"
"435.60000","1.29114","92.36612"
"436.00000","1.29166","92.17779"
"436.40000","1.29218","92.68999"
"436.80000","1.29271","92.81407"
"437.20000","1.29323","92.91440"
"437.60000","1.29376","92.93288"
"438.00000","1.29429","93.27876"
"438.40000","1.29478","93.32627"
"438.80000","1.29532","93.10274"
"439.20000","1.29587","93.40108"
"439.60000","1.29639","93.47765"
"440.00000","1.29690","92.79999"
"440.40000","1.29743","93.69767"
"440.80000","1.29797","93.47765"
"441.20000","1.29849","93.69239"
"441.60000","1.29900","94.13067"
"442.00000","1.29954","93.61142"
"442.40000","1.30008","93.55862"
"442.80000","1.30059","94.08490"
"443.20000","1.30110","93.81912"
"443.60000","1.30162","93.95641"
"444.00000","1.30215","93.87720"
"444.40000","1.30270","94.18611"
"444.80000","1.30322","94.13859"
"445.20000","1.30373","94.87785"
"445.60000","1.30426","94.53901"
"446.00000","1.30479","94.67895"
"446.40000","1.30531","94.76256"
"446.80000","1.30583","94.71591"
"447.20000","1.30636","94.99841"
"447.60000","1.30690","95.19291"
"448.00000","1.30741","95.13835"
"448.40000","1.30792","95.17707"
"448.80000","1.30846","95.22283"
"449.20000","1.30899","95.56166"
"449.60000","1.30952","95.26684"
"450.00000","1.31003","95.70071"
"450.40000","1.31055","95.44989"
"450.80000","1.31108","95.58190"
"451.20000","1.31160","95.90225"
"451.60000","1.31212","95.63031"
"452.00000","1.31265","95.82920"
"452.40000","1.31318","95.81864"
"452.80000","1.31372","95.99993"
"453.20000","1.31422","95.86265"
"453.60000","1.31475","96.20939"
"454.00000","1.31527","96.49190"
"454.40000","1.31581","96.27276"
"454.80000","1.31634","96.12843"
"455.20000","1.31686","96.30972"
"455.60000","1.31738","96.68816"
"456.00000","1.31791","97.19243"
"456.40000","1.31843","96.69783"
"456.80000","1.31895","97.08594"
"457.20000","1.31949","97.45909"
"457.60000","1.32002","97.33236"
"458.00000","1.32054","97.02611"
"458.40000","1.32105","97.02170"
"458.80000","1.32158","97.31388"
"459.20000","1.32212","97.34821"
"459.60000","1.32263","97.99771"
"460.00000","1.32316","98.02234"
"460.40000","1.32368","98.07603"
"460.80000","1.32421","97.76624"
"461.20000","1.32474","98.12795"
"461.60000","1.32525","98.31365"
"462.00000","1.32578","98.36469"
"462.40000","1.32631","98.17108"
"462.80000","1.32684","98.28372"
"463.20000","1.32734","98.60935"
"463.60000","1.32787","98.53719"
"464.00000","1.32840","98.30749"
"464.40000","1.32895","98.67272"
"464.80000","1.32945","98.82233"
"465.20000","1.32997","98.44830"
"465.60000","1.33051","98.94290"
"466.00000","1.33103","98.75017"
"466.40000","1.33156","99.30461"
"466.80000","1.33207","98.96050"
"467.20000","1.33260","99.11891"
"467.60000","1.33314","99.27293"
"468.00000","1.33365","99.45334"
"468.40000","1.33417","99.67512"
"468.80000","1.33470","99.95323"
"469.20000","1.33524","99.70768"
"469.60000","1.33577","100.17236"
"470.00000","1.33627","99.89689"
"470.40000","1.33681","99.61968"
"470.80000","1.33734","100.18204"
"471.20000","1.33785","100.52878"
"471.60000","1.33838","100.46982"
"472.00000","1.33891","100.54463"
"472.40000","1.33944","100.85530"
"472.80000","1.33996","100.70040"
"473.20000","1.34047","100.86058"
"473.60000","1.34099","100.82889"
"474.00000","1.34153","101.22228"
"474.40000","1.34206","101.27774"
"474.80000","1.34259","101.11932"
"475.20000","1.34309","101.30501"
"475.60000","1.34362","101.31645"
"476.00000","1.34416","101.46343"
"476.40000","1.34467","101.67729"
"476.80000","1.34520","101.59984"
"477.20000","1.34574","101.80841"
"477.60000","1.34627","101.91490"
"478.00000","1.34678","102.04956"
"478.40000","1.34729","101.77673"
"478.80000","1.34781","102.03372"
"479.20000","1.34836","102.43150"
"479.60000","1.34888","102.22557"
"480.00000","1.34940","102.19741"
"480.40000","1.34992","102.51951"
"480.80000","1.35045","103.16197"
"481.20000","1.35098","102.73337"
"481.60000","1.35148","102.52216"
"482.00000","1.35203","102.45791"
"482.40000","1.35255","102.83546"
"482.80000","1.35307","103.11796"
"483.20000","1.35359","103.19101"
"483.60000","1.35412","103.10124"
"484.00000","1.35466","103.22797"
"484.40000","1.35519","103.41894"
"484.80000","1.35569","103.27637"
"485.20000","1.35622","103.18485"
"485.60000","1.35675","103.48407"
"486.00000","1.35728","103.82642"
"486.40000","1.35781","103.82642"
"486.80000","1.35831","103.95139"
"487.20000","1.35885","104.15029"
"487.60000","1.35939","103.81498"
"488.00000","1.35989","104.23565"
"488.40000","1.36042","104.37383"
"488.80000","1.36094","104.51904"
"489.20000","1.36149","104.41343"
"489.60000","1.36201","104.59560"
"490.00000","1.36253","104.51200"
"490.40000","1.36305","104.63520"
"490.80000","1.36358","104.84995"
"491.20000","1.36410","104.85083"
"491.60000","1.36463","104.57800"
"492.00000","1.36515","104.88867"
"492.40000","1.36568","105.50120"
"492.80000","1.36621","104.90451"
"493.20000","1.36671","105.31903"
"493.60000","1.36724","105.32782"
"494.00000","1.36778","105.63233"
"494.40000","1.36831","106.01604"
"494.80000","1.36883","105.91660"
"495.20000","1.36934","105.92891"
"495.60000","1.36987","106.22550"
"496.00000","1.37040","106.09789"
"496.40000","1.37092","105.94212"
"496.80000","1.37145","106.10757"
"497.20000","1.37197","106.46752"
"497.60000","1.37251","106.31791"
"498.00000","1.37303","106.31086"
"498.40000","1.37353","106.86179"
"498.80000","1.37406","106.74562"
"499.20000","1.37461","106.69282"
"499.60000","1.37513","106.71834"
"500.00000","1.37564","107.27543"
"500.40000","1.37617","107.49016"
"500.80000","1.37671","107.36783"
"501.20000","1.37723","107.38544"
"501.60000","1.37774","107.31502"
"502.00000","1.37829","107.46200"
"502.40000","1.37881","107.50072"
"502.80000","1.37933","107.81843"
"503.20000","1.37984","108.00324"
"503.60000","1.38036","108.15197"
"504.00000","1.38090","108.25759"
"504.40000","1.38144","108.41952"
"504.80000","1.38195","108.53217"
"505.20000","1.38247","107.97068"
"505.60000","1.38300","108.30951"
"506.00000","1.38353","108.34647"
"506.40000","1.38404","108.32359"
"506.80000","1.38456","108.56825"
"507.20000","1.38510","108.53745"
"507.60000","1.38564","108.65186"
"508.00000","1.38615","108.77067"
"508.40000","1.38667","108.64834"
"508.80000","1.38718","109.04877"
"509.20000","1.38771","108.90972"
"509.60000","1.38825","109.13590"
"510.00000","1.38875","109.43160"
"510.40000","1.38929","109.71587"
"510.80000","1.38982","109.83644"
"511.20000","1.39034","109.36999"
"511.60000","1.39086","109.52313"
"512.00000","1.39140","109.47473"
"512.40000","1.39194","110.15591"
"512.80000","1.39247","109.95525"
"513.20000","1.39296","110.04414"
"513.60000","1.39349","110.48858"
"514.00000","1.39403","110.37153"
"514.40000","1.39455","110.33983"
"514.80000","1.39508","110.69803"
"515.20000","1.39559","110.94709"
"515.60000","1.39612","110.79044"
"516.00000","1.39665","110.67163"
"516.40000","1.39717","111.10462"
"516.80000","1.39769","110.98669"
"517.20000","1.39822","111.40208"
"517.60000","1.39876","111.42585"
"518.00000","1.39928","111.35457"
"518.40000","1.39978","111.56666"
"518.80000","1.40032","111.70131"
"519.20000","1.40086","111.74884"
"519.60000","1.40137","111.79724"
"520.00000","1.40190","111.90197"
"520.40000","1.40242","112.21263"
"520.80000","1.40294","112.23904"
"521.20000","1.40347","111.81485"
"521.60000","1.40399","112.12022"
"522.00000","1.40452","112.19591"
"522.40000","1.40505","112.69579"
"522.80000","1.40558","112.55323"
"523.20000","1.40610","112.27864"
"523.60000","1.40661","112.49778"
"524.00000","1.40714","112.80844"
"524.40000","1.40768","112.78643"
"524.80000","1.40819","112.58138"
"525.20000","1.40872","113.32945"
"525.60000","1.40925","113.80205"
"526.00000","1.40977","113.34793"
"526.40000","1.41029","113.48522"
"526.80000","1.41082","113.40954"
"527.20000","1.41136","113.69995"
"527.60000","1.41188","113.67971"
"528.00000","1.41240","113.92966"
"528.40000","1.41291","114.28696"
"528.80000","1.41344","113.71756"
"529.20000","1.41398","114.14000"
"529.60000","1.41451","114.24032"
"530.00000","1.41501","114.17872"
"530.40000","1.41555","114.13647"
"530.80000","1.41608","114.68828"
"531.20000","1.41659","114.93382"
"531.60000","1.41711","115.05527"
"532.00000","1.41764","114.71996"
"532.40000","1.41818","114.90742"
"532.80000","1.41870","114.96990"
"533.20000","1.41921","114.90478"
"533.60000","1.41973","115.36858"
"534.00000","1.42027","115.45835"
"534.40000","1.42080","115.30258"
"534.80000","1.42132","115.25240"
"535.20000","1.42184","115.26736"
"535.60000","1.42237","115.86230"
"536.00000","1.42290","115.88606"
"536.40000","1.42341","116.15272"
"536.80000","1.42394","115.98022"
"537.20000","1.42447","116.26273"
"537.60000","1.42500","116.26273"
"538.00000","1.42551","116.59275"
"538.40000","1.42603","116.35866"
"538.80000","1.42657","116.23720"
"539.20000","1.42710","116.59715"
"539.60000","1.42762","116.54699"
"540.00000","1.42815","116.57867"
"540.40000","1.42866","117.00374"
"540.80000","1.42920","116.96502"
"541.20000","1.42972","116.81189"
"541.60000","1.43023","117.36810"
"542.00000","1.43076","117.14544"
"542.40000","1.43130","117.06272"
"542.80000","1.43183","117.05831"
"543.20000","1.43233","117.38747"
"543.60000","1.43286","117.59780"
"544.00000","1.43340","117.72364"
"544.40000","1.43393","117.73508"
"544.80000","1.43444","118.02023"
"545.20000","1.43497","117.93576"
"545.60000","1.43549","118.23145"
"546.00000","1.43602","118.40922"
"546.40000","1.43655","118.24816"
"546.80000","1.43706","118.84751"
"547.20000","1.43760","118.80789"
"547.60000","1.43813","118.64773"
"548.00000","1.43865","118.53771"
"548.40000","1.43916","118.89415"
"548.80000","1.43969","119.21536"
"549.20000","1.44023","119.18808"
"549.60000","1.44075","119.18281"
"550.00000","1.44126","119.36146"
"550.40000","1.44179","118.93815"
"550.80000","1.44231","119.61844"
"551.20000","1.44284","119.63869"
"551.60000","1.44336","119.75487"
"552.00000","1.44388","120.00919"
"552.40000","1.44441","119.83847"
"552.80000","1.44494","120.02416"
"553.20000","1.44544","120.22129"
"553.60000","1.44598","120.43956"
"554.00000","1.44652","120.49676"
"554.40000","1.44705","120.13944"
"554.80000","1.44757","120.67629"
"555.20000","1.44809","120.51612"
"555.60000","1.44862","120.87870"
"556.00000","1.44916","120.48883"
"556.40000","1.44966","121.19289"
"556.80000","1.45019","120.91479"
"557.20000","1.45073","120.96408"
"557.60000","1.45125","121.20169"
"558.00000","1.45177","121.07320"
"558.40000","1.45227","120.98697"
"558.80000","1.45280","121.42083"
"559.20000","1.45335","121.67694"
"559.60000","1.45387","121.89080"
"560.00000","1.45439","121.80014"
"560.40000","1.45492","121.84943"
"560.80000","1.45545","122.23226"
"561.20000","1.45596","122.12137"
"561.60000","1.45648","122.02720"
"562.00000","1.45702","122.32114"
"562.40000","1.45755","122.38978"
"562.80000","1.45807","122.30706"
"563.20000","1.45858","122.42588"
"563.60000","1.45912","122.92664"
"564.00000","1.45964","122.73390"
"564.40000","1.46018","122.79023"
"564.80000","1.46069","123.05778"
"565.20000","1.46120","122.94248"
"565.60000","1.46173","123.12904"
"566.00000","1.46226","122.88527"
"566.40000","1.46277","123.81463"
"566.80000","1.46330","123.60077"
"567.20000","1.46384","123.25579"
"567.60000","1.46438","123.76270"
"568.00000","1.46489","123.69141"
"568.40000","1.46541","123.79702"
"568.80000","1.46594","124.20450"
"569.20000","1.46647","124.08218"
"569.60000","1.46700","123.91496"
"570.00000","1.46751","124.54862"
"570.40000","1.46803","124.22915"
"570.80000","1.46857","124.21505"
"571.20000","1.46909","124.60054"
"571.60000","1.46960","124.52573"
"572.00000","1.47014","124.84431"
"572.40000","1.47066","124.89447"
"572.80000","1.47120","124.85224"
"573.20000","1.47170","125.23859"
"573.60000","1.47224","125.38028"
"574.00000","1.47277","125.14266"
"574.40000","1.47329","125.41900"
"574.80000","1.47382","125.17874"
"575.20000","1.47433","125.16026"
"575.60000","1.47486","125.72176"
"576.00000","1.47539","125.71558"
"576.40000","1.47591","125.82383"
"576.80000","1.47643","125.70591"
"577.20000","1.47697","126.33515"
"577.60000","1.47750","126.33604"
"578.00000","1.47802","126.10721"
"578.40000","1.47852","126.62647"
"578.80000","1.47906","126.13449"
"579.20000","1.47960","126.26211"
"579.60000","1.48011","126.66605"
"580.00000","1.48063","126.72062"
"580.40000","1.48116","126.74967"
"580.80000","1.48169","126.82007"
"581.20000","1.48221","126.81126"
"581.60000","1.48273","126.88344"
"582.00000","1.48325","126.83680"
"582.40000","1.48379","127.33317"
"582.80000","1.48432","126.95648"
"583.20000","1.48482","127.51973"
"583.60000","1.48535","127.41589"
"584.00000","1.48588","127.75559"
"584.40000","1.48643","127.70983"
"584.80000","1.48693","127.86296"
"585.20000","1.48746","128.12610"
"585.60000","1.48799","127.93337"
"586.00000","1.48850","128.03458"
"586.40000","1.48903","128.56527"
"586.80000","1.48955","128.18418"
"587.20000","1.49008","128.53446"
"587.60000","1.49062","128.73775"
"588.00000","1.49114","128.86624"
"588.40000","1.49166","128.98505"
"588.80000","1.49217","128.93313"
"589.20000","1.49272","128.97449"
"589.60000","1.49325","129.33003"
"590.00000","1.49375","129.30716"
"590.40000","1.49428","129.55270"
"590.80000","1.49482","128.98242"
"591.20000","1.49533","129.71464"
"591.60000","1.49586","129.24996"
"592.00000","1.49639","129.75336"
"592.40000","1.49692","129.52542"
"592.80000","1.49744","129.66976"
"593.20000","1.49795","129.96985"
"593.60000","1.49849","129.75600"
"594.00000","1.49901","130.09834"
"594.40000","1.49953","130.35445"
"594.80000","1.50006","130.54542"
"595.20000","1.50057","130.19604"
"595.60000","1.50111","130.41253"
"596.00000","1.50165","130.51110"
"596.40000","1.50215","130.59735"
"596.80000","1.50267","130.83321"
"597.20000","1.50321","130.83409"
"597.58200","1.50371","130.93970"