File: DataAnalyzer/TestFiles/Specimen_RawData_2.csv
Specimen properties : Specimen label,"orgn_80_NA_2_wblk_3ptbnd_run2"
Maximum Load : Flexure extension at Maximum Load,"1.56568",in
Maximum Load : Maximum Load,"127.62533",lbf

Time,Extension,Load
(s),(in),(lbf)
"0.00000","0.76875","15.11248"
"0.50000","0.76960","14.43131"
"1.00000","0.77000","14.60820"
"1.50000","0.77066","14.63196"
"2.00000","0.77133","14.56596"
"2.50000","0.77197","14.44011"
"3.00000","0.77264","14.87662"
"3.50000","0.77330","14.62316"
"4.00000","0.77395","14.44538"
"4.50000","0.77461","14.80886"
"5.00000","0.77527","15.34130"
"5.50000","0.77592","14.79125"
"6.00000","0.77657","15.11160"
"6.50000","0.77723","14.96375"
"7.00000","0.77789","15.08256"
"7.50000","0.77854","14.64956"
"8.00000","0.77920","14.73317"
"8.50000","0.77985","14.98135"
"9.00000","0.78050","15.24097"
"9.50000","0.78117","15.01303"
"10.00000","0.78183","15.24361"
"10.50000","0.78247","15.45747"
"11.00000","0.78313","14.94439"
"11.50000","0.78380","15.06056"
"12.00000","0.78445","15.27353"
"12.50000","0.78510","15.50852"
"13.00000","0.78576","15.37386"
"13.50000","0.78643","15.77870"
"14.00000","0.78707","15.78486"
"14.50000","0.78772","15.54900"
"15.00000","0.78839","16.02688"
"15.50000","0.78904","16.18001"
"16.00000","0.78968","15.97847"
"16.50000","0.79036","15.57188"
"17.00000","0.79101","16.34106"
"17.50000","0.79165","16.32346"
"18.00000","0.79231","16.21873"
"18.50000","0.79299","15.96087"
"19.00000","0.79364","16.23105"
"19.50000","0.79428","16.65613"
"20.00000","0.79495","16.79694"
"20.50000","0.79560","16.42643"
"21.00000","0.79625","16.41323"
"21.50000","0.79691","16.39827"
"22.00000","0.79758","16.76878"
"22.50000","0.79823","16.76086"
"23.00000","0.79888","16.63501"
"23.50000","0.79955","16.51884"
"24.00000","0.80020","16.92367"
"24.50000","0.80086","17.03016"
"25.00000","0.80151","17.24402"
"25.50000","0.80217","16.82158"
"26.00000","0.80282","17.39979"
"26.50000","0.80347","16.95095"
"27.00000","0.80414","16.80574"
"27.50000","0.80478","17.29330"
"28.00000","0.80545","17.34875"
"28.50000","0.80610","17.27482"
"29.00000","0.80675","17.65677"
"29.50000","0.80741","17.61981"
"30.00000","0.80807","17.72718"
"30.50000","0.80872","17.74126"
"31.00000","0.80937","17.81078"
"31.50000","0.81005","18.19890"
"32.00000","0.81070","18.25082"
"32.50000","0.81135","17.89791"
"33.00000","0.81201","18.11089"
"33.50000","0.81267","17.90495"
"34.00000","0.81331","18.23058"
"34.50000","0.81397","18.52364"
"35.00000","0.81464","18.24994"
"35.50000","0.81530","18.79295"
"36.00000","0.81594","18.48932"
"36.50000","0.81660","18.72870"
"37.00000","0.81726","18.57293"
"37.50000","0.81790","18.63805"
"38.00000","0.81856","19.02528"
"38.50000","0.81923","18.79911"
"39.00000","0.81988","18.76566"
"39.50000","0.82054","18.74630"
"40.00000","0.82120","18.82111"
"40.50000","0.82186","19.06665"
"41.00000","0.82250","19.35971"
"41.50000","0.82316","19.27963"
"42.00000","0.82382","19.31747"
"42.50000","0.82447","19.47852"
"43.00000","0.82512","19.45036"
"43.50000","0.82578","19.78126"
"44.00000","0.82644","19.88599"
"44.50000","0.82710","19.30427"
"45.00000","0.82776","19.44156"
"45.50000","0.82841","20.17554"
"46.00000","0.82907","19.75310"
"46.50000","0.82973","19.83407"
"47.00000","0.83038","20.32251"
"47.50000","0.83102","19.85519"
"48.00000","0.83168","19.92912"
"48.50000","0.83235","20.41492"
"49.00000","0.83300","20.49148"
"49.50000","0.83366","20.46772"
"50.00000","0.83433","20.59973"
"50.50000","0.83497","20.46420"
"51.00000","0.83562","20.56013"
"51.50000","0.83629","20.29523"
"52.00000","0.83695","20.55485"
"52.50000","0.83760","21.03009"
"53.00000","0.83825","20.78807"
"53.50000","0.83892","20.92888"
"54.00000","0.83957","20.55661"
"54.50000","0.84022","21.09081"
"55.00000","0.84088","21.07321"
"55.50000","0.84153","20.79687"
"56.00000","0.84218","20.96936"
"56.50000","0.84285","21.07321"
"57.00000","0.84351","21.24306"
"57.50000","0.84413","21.06617"
"58.00000","0.84481","21.79311"
"58.50000","0.84548","21.97353"
"59.00000","0.84612","21.52821"
"59.50000","0.84677","21.39180"
"60.00000","0.84744","21.81687"
"60.50000","0.84809","21.82656"
"61.00000","0.84874","21.55109"
"61.50000","0.84941","21.64086"
"62.00000","0.85007","21.72710"
"62.50000","0.85072","21.95769"
"63.00000","0.85137","22.02193"
"63.50000","0.85204","22.17418"
"64.00000","0.85269","21.88552"
"64.50000","0.85335","22.15306"
"65.00000","0.85399","22.80871"
"65.50000","0.85466","21.87320"
"66.00000","0.85531","22.74975"
"66.50000","0.85597","22.54557"
"67.00000","0.85663","22.71191"
"67.50000","0.85727","23.05074"
"68.00000","0.85794","22.68462"
"68.50000","0.85859","22.90376"
"69.00000","0.85924","22.83336"
"69.50000","0.85991","23.08946"
"70.00000","0.86057","23.10618"
"70.50000","0.86122","22.91608"
"71.00000","0.86187","22.94513"
"71.50000","0.86253","22.83336"
"72.00000","0.86319","23.36052"
"72.50000","0.86384","23.69495"
"73.00000","0.86450","23.47493"
"73.50000","0.86517","23.47229"
"74.00000","0.86581","23.44677"
"74.50000","0.86647","23.57262"
"75.00000","0.86714","23.73807"
"75.50000","0.86779","23.69495"
"76.00000","0.86843","24.03730"
"76.50000","0.86909","23.69407"
"77.00000","0.86975","23.86480"
"77.50000","0.87039","24.19747"
"78.00000","0.87105","24.80208"
"78.50000","0.87172","24.16491"
"79.00000","0.87238","24.69647"
"79.50000","0.87303","24.66919"
"80.00000","0.87370","24.59614"
"80.50000","0.87435","24.66743"
"81.00000","0.87498","24.43421"
"81.50000","0.87566","24.79680"
"82.00000","0.87633","24.51957"
"82.50000","0.87697","24.69119"
"83.00000","0.87763","25.01506"
"83.50000","0.87829","24.98161"
"84.00000","0.87894","24.78448"
"84.50000","0.87960","24.90153"
"85.00000","0.88025","25.17171"
"85.50000","0.88090","25.39173"
"86.00000","0.88155","25.57126"
"86.50000","0.88222","25.53694"
"87.00000","0.88288","25.02210"
"87.50000","0.88352","25.39789"
"88.00000","0.88419","25.63287"
"88.50000","0.88485","25.71736"
"89.00000","0.88549","25.93121"
"89.50000","0.88615","25.82120"
"90.00000","0.88682","26.02978"
"90.50000","0.88746","25.88281"
"91.00000","0.88811","26.15739"
"91.50000","0.88879","26.19611"
"92.00000","0.88945","26.29908"
"92.50000","0.89009","26.19259"
"93.00000","0.89075","26.44253"
"93.50000","0.89141","26.27532"
"94.00000","0.89205","26.44253"
"94.50000","0.89271","26.72680"
"95.00000","0.89338","26.55694"
"95.50000","0.89403","26.53934"
"96.00000","0.89468","26.60535"
"96.50000","0.89535","26.75056"
"97.00000","0.89600","26.92393"
"97.50000","0.89664","27.02426"
"98.00000","0.89730","27.21436"
"98.50000","0.89797","27.10523"
"99.00000","0.89862","27.10259"
"99.50000","0.89928","27.04626"
"100.00000","0.89994","27.10523"
"100.50000","0.90059","27.31469"
"101.00000","0.90123","27.25748"
"101.50000","0.90190","27.30589"
"102.00000","0.90256","27.66143"
"102.50000","0.90321","27.50742"
"103.00000","0.90387","27.62623"
"103.50000","0.90454","27.62271"
"104.00000","0.90518","28.00026"
"104.50000","0.90585","27.98530"
"105.00000","0.90650","28.25108"
"105.50000","0.90715","27.95626"
"106.00000","0.90780","27.95714"
"106.50000","0.90847","28.16043"
"107.00000","0.90911","28.13579"
"107.50000","0.90976","28.30389"
"108.00000","0.91044","28.58375"
"108.50000","0.91109","28.15163"
"109.00000","0.91174","28.40774"
"109.50000","0.91240","28.81169"
"110.00000","0.91307","28.82225"
"110.50000","0.91371","28.60927"
"111.00000","0.91436","28.98066"
"111.50000","0.91503","28.92346"
"112.00000","0.91569","29.09419"
"112.50000","0.91634","29.08891"
"113.00000","0.91700","29.22884"
"113.50000","0.91766","29.29221"
"114.00000","0.91830","29.31773"
"114.50000","0.91896","29.58791"
"115.00000","0.91962","29.72344"
"115.50000","0.92027","29.21300"
"116.00000","0.92091","29.71904"
"116.50000","0.92160","29.70408"
"117.00000","0.92226","29.85898"
"117.50000","0.92289","29.73928"
"118.00000","0.92355","29.85809"
"118.50000","0.92422","29.81057"
"119.00000","0.92486","29.70672"
"119.50000","0.92551","30.07019"
"120.00000","0.92618","30.07899"
"120.50000","0.92683","30.40726"
"121.00000","0.92749","30.26733"
"121.50000","0.92815","30.34125"
"122.00000","0.92882","30.45655"
"122.50000","0.92946","30.25941"
"123.00000","0.93011","30.50495"
"123.50000","0.93078","30.70296"
"124.00000","0.93143","30.24885"
"124.50000","0.93210","30.94674"
"125.00000","0.93275","30.97490"
"125.50000","0.93340","30.75401"
"126.00000","0.93405","30.83233"
"126.50000","0.93472","31.04355"
"127.00000","0.93537","30.87898"
"127.50000","0.93602","30.89746"
"128.00000","0.93667","31.58480"
"128.50000","0.93733","31.66576"
"129.00000","0.93798","31.63672"
"129.50000","0.93865","31.85762"
"130.00000","0.93931","31.76785"
"130.50000","0.93996","31.37886"
"131.00000","0.94061","31.47303"
"131.50000","0.94127","32.04684"
"132.00000","0.94193","32.32230"
"132.50000","0.94258","32.19733"
"133.00000","0.94324","32.17532"
"133.50000","0.94391","32.04067"
"134.00000","0.94455","31.96851"
"134.50000","0.94521","32.63032"
"135.00000","0.94588","32.33902"
"135.50000","0.94653","32.35486"
"136.00000","0.94717","32.80282"
"136.50000","0.94783","32.74913"
"137.00000","0.94849","32.62856"
"137.50000","0.94913","32.68929"
"138.00000","0.94979","32.76585"
"138.50000","0.95047","33.45319"
"139.00000","0.95112","32.70073"
"139.50000","0.95176","32.98235"
"140.00000","0.95243","33.24021"
"140.50000","0.95308","33.09500"
"141.00000","0.95373","33.13549"
"141.50000","0.95440","33.40303"
"142.00000","0.95506","33.65913"
"142.50000","0.95571","33.22085"
"143.00000","0.95636","33.98211"
"143.50000","0.95702","33.53152"
"144.00000","0.95767","33.73921"
"144.50000","0.95833","33.64945"
"145.00000","0.95899","34.02348"
"145.50000","0.95964","34.02524"
"146.00000","0.96029","34.28398"
"146.50000","0.96096","33.98739"
"147.00000","0.96161","34.08948"
"147.50000","0.96227","34.10884"
"148.00000","0.96293","34.45207"
"148.50000","0.96358","34.38519"
"149.00000","0.96423","34.72578"
"149.50000","0.96489","34.93787"
"150.00000","0.96555","34.56648"
"150.50000","0.96620","34.82082"
"151.00000","0.96686","34.81466"
"151.50000","0.96753","34.70906"
"152.00000","0.96818","34.88859"
"152.50000","0.96883","35.36999"
"153.00000","0.96949","35.22213"
"153.50000","0.97015","35.61465"
"154.00000","0.97079","35.69209"
"154.50000","0.97145","35.64897"
"155.00000","0.97212","35.42191"
"155.50000","0.97277","35.45535"
"156.00000","0.97342","36.15677"
"156.50000","0.97409","36.12597"
"157.00000","0.97474","35.96492"
"157.50000","0.97537","35.84611"
"158.00000","0.97604","35.76778"
"158.50000","0.97670","36.32311"
"159.00000","0.97735","36.35303"
"159.50000","0.97800","36.45512"
"160.00000","0.97868","35.94291"
"160.50000","0.97934","36.22102"
"161.00000","0.97998","36.04764"
"161.50000","0.98064","36.61793"
"162.00000","0.98130","36.73322"
"162.50000","0.98195","36.95148"
"163.00000","0.98260","36.67161"
"163.50000","0.98328","36.81419"
"164.00000","0.98393","36.93916"
"164.50000","0.98458","36.68482"
"165.00000","0.98524","37.30791"
"165.50000","0.98589","37.15566"
"166.00000","0.98654","37.44080"
"166.50000","0.98720","36.96644"
"167.00000","0.98785","37.24014"
"167.50000","0.98851","37.75938"
"168.00000","0.98918","37.67226"
"168.50000","0.98984","37.56929"
"169.00000","0.99048","37.68810"
"169.50000","0.99114","37.74002"
"170.00000","0.99180","37.99348"
"170.50000","0.99245","38.13342"
"171.00000","0.99310","38.21790"
"171.50000","0.99376","38.52681"
"172.00000","0.99444","38.54001"
"172.50000","0.99506","38.87268"
"173.00000","0.99574","38.55585"
"173.50000","0.99640","38.85859"
"174.00000","0.99704","38.94396"
"174.50000","0.99770","38.16422"
"175.00000","0.99837","38.88324"
"175.50000","0.99901","38.91052"
"176.00000","0.99966","39.01349"
"176.50000","1.00034","39.23614"
"177.00000","1.00099","39.16222"
"177.50000","1.00163","39.32327"
"178.00000","1.00229","39.18246"
"178.50000","1.00296","39.47464"
"179.00000","1.00361","39.45441"
"179.50000","1.00425","39.81435"
"180.00000","1.00494","40.08365"
"180.50000","1.00559","39.44560"
"181.00000","1.00621","40.22271"
"181.50000","1.00690","40.15582"
"182.00000","1.00756","39.99301"
"182.50000","1.00820","39.89620"
"183.00000","1.00886","40.09510"
"183.50000","1.00952","40.45857"
"184.00000","1.01017","40.70146"
"184.50000","1.01082","40.48937"
"185.00000","1.01149","40.70939"
"185.50000","1.01214","40.56329"
"186.00000","1.01279","40.85020"
"186.50000","1.01345","41.04293"
"187.00000","1.01411","41.05966"
"187.50000","1.01475","40.85724"
"188.00000","1.01542","40.66538"
"188.50000","1.01607","41.39144"
"189.00000","1.01672","41.20575"
"189.50000","1.01740","40.99453"
"190.00000","1.01806","41.45745"
"190.50000","1.01870","41.30607"
"191.00000","1.01935","41.25943"
"191.50000","1.02002","41.59914"
"192.00000","1.02068","41.61498"
"192.50000","1.02132","41.86140"
"193.00000","1.02198","41.88604"
"193.50000","1.02265","41.72323"
"194.00000","1.02330","41.84908"
"194.50000","1.02395","42.26887"
"195.00000","1.02462","42.17735"
"195.50000","1.02527","42.48449"
"196.00000","1.02591","42.20111"
"196.50000","1.02658","42.51002"
"197.00000","1.02724","42.59802"
"197.50000","1.02787","42.47833"
"198.00000","1.02853","42.90957"
"198.50000","1.02920","42.68075"
"199.00000","1.02985","42.63763"
"199.50000","1.03050","42.65259"
"200.00000","1.03117","43.26776"
"200.50000","1.03182","42.95269"
"201.00000","1.03247","43.38569"
"201.50000","1.03313","43.66467"
"202.00000","1.03380","43.51506"
"202.50000","1.03445","43.78436"
"203.00000","1.03511","43.42529"
"203.50000","1.03577","43.44025"
"204.00000","1.03642","43.84156"
"204.50000","1.03707","43.82661"
"205.00000","1.03773","43.97886"
"205.50000","1.03838","44.02814"
"206.00000","1.03903","44.39689"
"206.50000","1.03970","44.27280"
"207.00000","1.04036","44.57027"
"207.50000","1.04101","44.39073"
"208.00000","1.04167","44.24464"
"208.50000","1.04232","44.53682"
"209.00000","1.04298","44.66883"
"209.50000","1.04363","44.82021"
"210.00000","1.04431","44.60987"
"210.50000","1.04494","45.34121"
"211.00000","1.04560","44.70316"
"211.50000","1.04627","45.10711"
"212.00000","1.04692","45.35001"
"212.50000","1.04757","45.19952"
"213.00000","1.04823","45.07631"
"213.50000","1.04889","45.29017"
"214.00000","1.04953","45.38257"
"214.50000","1.05019","45.16255"
"215.00000","1.05086","45.40018"
"215.50000","1.05151","45.37113"
"216.00000","1.05216","45.74428"
"216.50000","1.05283","46.27233"
"217.00000","1.05348","46.27321"
"217.50000","1.05412","45.86045"
"218.00000","1.05478","46.02678"
"218.50000","1.05545","46.23888"
"219.00000","1.05611","45.97134"
"219.50000","1.05676","46.16320"
"220.00000","1.05742","46.94910"
"220.50000","1.05808","47.06087"
"221.00000","1.05872","46.71412"
"221.50000","1.05938","46.78189"
"222.00000","1.06004","46.59355"
"222.50000","1.06069","47.13392"
"223.00000","1.06135","46.89102"
"223.50000","1.06202","47.43050"
"224.00000","1.06267","47.40234"
"224.50000","1.06333","47.35217"
"225.00000","1.06399","46.95702"
"225.50000","1.06463","47.41290"
"226.00000","1.06528","47.92246"
"226.50000","1.06595","47.54315"
"227.00000","1.06660","47.58891"
"227.50000","1.06725","47.89694"
"228.00000","1.06791","48.51299"
"228.50000","1.06857","48.06943"
"229.00000","1.06922","47.96206"
"229.50000","1.06988","47.95062"
"230.00000","1.07054","48.40298"
"230.50000","1.07119","48.69868"
"231.00000","1.07184","48.38450"
"231.50000","1.07252","48.70044"
"232.00000","1.07317","48.90902"
"232.50000","1.07382","48.48307"
"233.00000","1.07449","48.74357"
"233.50000","1.07514","49.04015"
"234.00000","1.07578","48.72156"
"234.50000","1.07644","48.77525"
"235.00000","1.07711","48.89758"
"235.50000","1.07776","49.23729"
"236.00000","1.07840","49.43531"
"236.50000","1.07908","49.43355"
"237.00000","1.07974","49.51627"
"237.50000","1.08037","49.92991"
"238.00000","1.08103","49.77149"
"238.50000","1.08170","49.83310"
"239.00000","1.08234","50.06104"
"239.50000","1.08299","49.90967"
"240.00000","1.08366","50.25289"
"240.50000","1.08433","50.05928"
"241.00000","1.08497","50.18073"
"241.50000","1.08563","50.10240"
"242.00000","1.08629","50.29249"
"242.50000","1.08694","50.36730"
"243.00000","1.08759","50.59348"
"243.50000","1.08825","50.72197"
"244.00000","1.08890","50.68941"
"244.50000","1.08956","50.76422"
"245.00000","1.09023","51.26673"
"245.50000","1.09088","50.88215"
"246.00000","1.09153","51.14529"
"246.50000","1.09220","51.03792"
"247.00000","1.09285","51.60908"
"247.50000","1.09350","51.34154"
"248.00000","1.09416","51.81326"
"248.50000","1.09481","51.40403"
"249.00000","1.09546","52.02184"
"249.50000","1.09613","51.56772"
"250.00000","1.09680","51.79654"
"250.50000","1.09744","52.25330"
"251.00000","1.09809","52.30874"
"251.50000","1.09876","51.93823"
"252.00000","1.09942","52.32370"
"252.50000","1.10006","52.09752"
"253.00000","1.10072","52.63789"
"253.50000","1.10139","52.40203"
"254.00000","1.10203","52.82182"
"254.50000","1.10269","52.67661"
"255.00000","1.10335","52.64933"
"255.50000","1.10400","53.22314"
"256.00000","1.10465","52.55868"
"256.50000","1.10531","52.96439"
"257.00000","1.10597","53.25570"
"257.50000","1.10661","53.11577"
"258.00000","1.10728","53.23282"
"258.50000","1.10794","53.35163"
"259.00000","1.10859","53.75822"
"259.50000","1.10924","53.79166"
"260.00000","1.10991","53.80134"
"260.50000","1.11056","54.32763"
"261.00000","1.11121","54.11025"
"261.50000","1.11189","54.03457"
"262.00000","1.11254","54.22114"
"262.50000","1.11319","54.16746"
"263.00000","1.11385","54.10849"
"263.50000","1.11451","54.04336"
"264.00000","1.11516","54.66998"
"264.50000","1.11581","54.70430"
"265.00000","1.11646","54.69198"
"265.50000","1.11712","55.06073"
"266.00000","1.11777","54.73598"
"266.50000","1.11845","54.88824"
"267.00000","1.11910","54.90143"
"267.50000","1.11974","54.66998"
"268.00000","1.12041","55.25963"
"268.50000","1.12107","55.24202"
"269.00000","1.12171","55.57293"
"269.50000","1.12237","55.30011"
"270.00000","1.12303","55.33267"
"270.50000","1.12368","55.78327"
"271.00000","1.12434","55.75775"
"271.50000","1.12500","55.58701"
"272.00000","1.12565","55.95576"
"272.50000","1.12630","56.10890"
"273.00000","1.12696","56.46005"
"273.50000","1.12763","56.25234"
"274.00000","1.12827","56.23387"
"274.50000","1.12893","56.26467"
"275.00000","1.12960","56.50933"
"275.50000","1.13025","56.58238"
"276.00000","1.13090","56.68710"
"276.50000","1.13156","56.68446"
"277.00000","1.13222","56.69414"
"277.50000","1.13286","56.62022"
"278.00000","1.13353","57.23891"
"278.50000","1.13418","56.96873"
"279.00000","1.13483","56.82792"
"279.50000","1.13550","57.21779"
"280.00000","1.13616","57.82856"
"280.50000","1.13682","57.11306"
"281.00000","1.13746","57.19667"
"281.50000","1.13812","57.41757"
"282.00000","1.13878","57.73263"
"282.50000","1.13943","57.98961"
"283.00000","1.14009","57.83824"
"283.50000","1.14076","57.94296"
"284.00000","1.14141","57.89456"
"284.50000","1.14206","58.18147"
"285.00000","1.14272","58.27827"
"285.50000","1.14337","58.10138"
"286.00000","1.14402","58.49213"
"286.50000","1.14468","58.60390"
"287.00000","1.14533","58.64439"
"287.50000","1.14598","58.29588"
"288.00000","1.14665","58.65846"
"288.50000","1.14732","58.89520"
"289.00000","1.14796","58.58189"
"289.50000","1.14862","58.85121"
"290.00000","1.14929","59.02369"
"290.50000","1.14993","59.06066"
"291.00000","1.15058","59.33084"
"291.50000","1.15126","59.32468"
"292.00000","1.15192","59.21027"
"292.50000","1.15256","59.27276"
"293.00000","1.15322","59.70752"
"293.50000","1.15388","59.77264"
"294.00000","1.15452","59.70752"
"294.50000","1.15518","59.93457"
"295.00000","1.15584","60.01642"
"295.50000","1.15650","60.06218"
"296.00000","1.15714","60.71783"
"296.50000","1.15782","60.09738"
"297.00000","1.15847","60.22587"
"297.50000","1.15911","60.15811"
"298.00000","1.15978","60.25404"
"298.50000","1.16044","60.67823"
"299.00000","1.16109","60.52598"
"299.50000","1.16174","60.98978"
"300.00000","1.16240","60.90881"
"300.50000","1.16306","60.97921"
"301.00000","1.16371","60.91322"
"301.50000","1.16437","60.97921"
"302.00000","1.16504","60.73104"
"302.50000","1.16568","61.02586"
"303.00000","1.16634","61.27316"
"303.50000","1.16700","61.14731"
"304.00000","1.16765","61.42629"
"304.50000","1.16830","61.02058"
"305.00000","1.16897","61.61375"
"305.50000","1.16962","61.01002"
"306.00000","1.17028","61.81528"
"306.50000","1.17093","61.47205"
"307.00000","1.17159","61.37876"
"307.50000","1.17224","61.49934"
"308.00000","1.17290","61.67623"
"308.50000","1.17355","61.57239"
"309.00000","1.17420","61.40429"
"309.50000","1.17487","61.50022"
"310.00000","1.17553","61.51782"
"310.50000","1.17618","61.62343"
"311.00000","1.17683","61.56711"
"311.50000","1.17750","61.58119"
"312.00000","1.17816","61.72816"
"312.50000","1.17880","61.28372"
"313.00000","1.17946","61.77128"
"313.50000","1.18013","61.53718"
"314.00000","1.18077","61.41133"
"314.50000","1.18143","61.61815"
"315.00000","1.18209","61.50813"
"315.50000","1.18274","60.90705"
"316.00000","1.18339","61.02674"
"316.50000","1.18405","61.01706"
"317.00000","1.18471","60.70991"
"317.50000","1.18535","60.58670"
"318.00000","1.18602","60.64215"
"318.50000","1.18669","60.61927"
"319.00000","1.18733","60.79440"
"319.50000","1.18798","61.11563"
"320.00000","1.18865","61.24324"
"320.50000","1.18930","61.21331"
"321.00000","1.18994","61.60055"
"321.50000","1.19061","61.65864"
"322.00000","1.19128","61.81000"
"322.50000","1.19193","62.16555"
"323.00000","1.19259","62.40317"
"323.50000","1.19324","62.47710"
"324.00000","1.19390","62.09339"
"324.50000","1.19456","62.51846"
"325.00000","1.19521","62.67512"
"325.50000","1.19587","62.56951"
"326.00000","1.19653","62.61527"
"326.50000","1.19718","62.92594"
"327.00000","1.19784","63.01130"
"327.50000","1.19848","63.32813"
"328.00000","1.19914","63.36686"
"328.50000","1.19980","63.58335"
"329.00000","1.20045","63.45222"
"329.50000","1.20111","63.65200"
"330.00000","1.20177","63.74529"
"330.50000","1.20243","63.74264"
"331.00000","1.20308","63.75496"
"331.50000","1.20375","64.22580"
"332.00000","1.20440","64.15892"
"332.50000","1.20504","64.58311"
"333.00000","1.20571","64.41414"
"333.50000","1.20637","64.44318"
"334.00000","1.20701","64.51183"
"334.50000","1.20767","64.18972"
"335.00000","1.20835","64.36309"
"335.50000","1.20900","64.41237"
"336.00000","1.20964","64.18620"
"336.50000","1.21030","64.91578"
"337.00000","1.21097","64.66320"
"337.50000","1.21160","64.63239"
"338.00000","1.21226","65.04339"
"338.50000","1.21294","65.12612"
"339.00000","1.21359","65.25197"
"339.50000","1.21422","65.15779"
"340.00000","1.21490","65.63656"
"340.50000","1.21555","65.65856"
"341.00000","1.21620","66.07044"
"341.50000","1.21686","65.81609"
"342.00000","1.21752","66.09332"
"342.50000","1.21817","66.39343"
"343.00000","1.21882","66.52455"
"343.50000","1.21949","66.34414"
"344.00000","1.22014","66.34062"
"344.50000","1.22080","66.62928"
"345.00000","1.22146","66.60816"
"345.50000","1.22212","67.13004"
"346.00000","1.22276","67.18988"
"346.50000","1.22343","66.97779"
"347.00000","1.22408","67.19517"
"347.50000","1.22472","67.15908"
"348.00000","1.22540","67.53840"
"348.50000","1.22605","67.33774"
"349.00000","1.22670","67.82618"
"349.50000","1.22736","68.08756"
"350.00000","1.22802","68.32255"
"350.50000","1.22867","68.57424"
"351.00000","1.22932","68.41759"
"351.50000","1.23000","68.69657"
"352.00000","1.23065","68.79602"
"352.50000","1.23130","69.10844"
"353.00000","1.23196","68.81450"
"353.50000","1.23262","68.97996"
"354.00000","1.23326","69.16213"
"354.50000","1.23392","69.31174"
"355.00000","1.23458","69.41472"
"355.50000","1.23524","69.56784"
"356.00000","1.23588","69.66905"
"356.50000","1.23656","70.06508"
"357.00000","1.23721","69.88731"
"357.50000","1.23784","69.86267"
"358.00000","1.23851","69.81426"
"358.50000","1.23918","70.57553"
"359.00000","1.23982","70.32030"
"359.50000","1.24047","70.45055"
"360.00000","1.24114","70.65649"
"360.50000","1.24181","70.81755"
"361.00000","1.24245","71.01996"
"361.50000","1.24311","70.69170"
"362.00000","1.24377","71.46000"
"362.50000","1.24442","71.38343"
"363.00000","1.24507","71.54977"
"363.50000","1.24574","71.57705"
"364.00000","1.24638","71.68001"
"364.50000","1.24704","71.84899"
"365.00000","1.24770","72.03380"
"365.50000","1.24836","71.95724"
"366.00000","1.24901","72.38143"
"366.50000","1.24967","72.33919"
"367.00000","1.25033","72.52665"
"367.50000","1.25098","72.90948"
"368.00000","1.25164","72.67361"
"368.50000","1.25229","72.56625"
"369.00000","1.25296","72.93500"
"369.50000","1.25361","72.86636"
"370.00000","1.25427","72.85052"
"370.50000","1.25492","73.04765"
"371.00000","1.25556","73.19550"
"371.50000","1.25623","73.28703"
"372.00000","1.25689","73.60122"
"372.50000","1.25754","73.94180"
"373.00000","1.25821","73.69098"
"373.50000","1.25887","74.20583"
"374.00000","1.25951","73.97349"
"374.50000","1.26017","74.35543"
"375.00000","1.26084","74.28151"
"375.50000","1.26148","74.30880"
"376.00000","1.26213","74.64498"
"376.50000","1.26279","74.84388"
"377.00000","1.26345","74.75587"
"377.50000","1.26409","75.14574"
"378.00000","1.26476","75.23375"
"378.50000","1.26543","75.50569"
"379.00000","1.26608","75.04013"
"379.50000","1.26672","75.51537"
"380.00000","1.26740","75.97037"
"380.50000","1.26805","75.70107"
"381.00000","1.26869","75.87268"
"381.50000","1.26935","75.99766"
"382.00000","1.27002","76.39896"
"382.50000","1.27067","75.94221"
"383.00000","1.27133","76.63482"
"383.50000","1.27199","76.52481"
"384.00000","1.27264","76.79148"
"384.50000","1.27330","76.75188"
"385.00000","1.27395","76.93405"
"385.50000","1.27460","77.03966"
"386.00000","1.27525","77.28432"
"386.50000","1.27592","77.00445"
"387.00000","1.27658","77.33800"
"387.50000","1.27722","77.50257"
"388.00000","1.27788","77.74460"
"388.50000","1.27855","77.77980"
"389.00000","1.27919","77.80708"
"389.50000","1.27985","78.04559"
"390.00000","1.28053","78.01566"
"390.50000","1.28117","78.40729"
"391.00000","1.28182","78.62203"
"391.50000","1.28249","78.40729"
"392.00000","1.28314","78.54986"
"392.50000","1.28378","78.84645"
"393.00000","1.28445","78.62643"
"393.50000","1.28511","79.42201"
"394.00000","1.28576","79.19056"
"394.50000","1.28641","79.13247"
"395.00000","1.28708","79.17559"
"395.50000","1.28773","79.66932"
"396.00000","1.28838","79.67988"
"396.50000","1.28905","79.56019"
"397.00000","1.28970","79.95357"
"397.50000","1.29034","80.22024"
"398.00000","1.29100","80.69108"
"398.50000","1.29168","80.24840"
"399.00000","1.29231","80.36986"
"399.50000","1.29297","80.79141"
"400.00000","1.29364","80.78348"
"400.50000","1.29429","81.22968"
"401.00000","1.29493","80.92693"
"401.50000","1.29560","81.09327"
"402.00000","1.29626","80.29945"
"402.50000","1.29691","80.73332"
"403.00000","1.29758","80.68228"
"403.50000","1.29824","81.00527"
"404.00000","1.29889","80.97006"
"404.50000","1.29955","80.78612"
"405.00000","1.30020","80.97094"
"405.50000","1.30085","81.15048"
"406.00000","1.30150","81.17511"
"406.50000","1.30216","80.95686"
"407.00000","1.30281","81.28864"
"407.50000","1.30347","81.52627"
"408.00000","1.30413","81.91174"
"408.50000","1.30479","81.85541"
"409.00000","1.30544","81.67412"
"409.50000","1.30610","81.72692"
"410.00000","1.30676","82.19864"
"410.50000","1.30741","82.51547"
"411.00000","1.30806","82.78917"
"411.50000","1.30874","82.40369"
"412.00000","1.30940","82.67212"
"412.50000","1.31004","83.05583"
"413.00000","1.31069","83.01887"
"413.50000","1.31135","82.90621"
"414.00000","1.31200","83.29081"
"414.50000","1.31266","83.20456"
"415.00000","1.31331","83.40699"
"415.50000","1.31397","83.64196"
"416.00000","1.31462","83.46330"
"416.50000","1.31529","83.84526"
"417.00000","1.31596","83.65604"
"417.50000","1.31660","83.95262"
"418.00000","1.31725","84.12864"
"418.50000","1.31792","84.36362"
"419.00000","1.31857","84.42610"
"419.50000","1.31921","84.39354"
"420.00000","1.31988","84.79574"
"420.50000","1.32055","84.91542"
"421.00000","1.32119","84.88286"
"421.50000","1.32185","84.98407"
"422.00000","1.32251","84.92951"
"422.50000","1.32316","85.21553"
"423.00000","1.32382","85.10200"
"423.50000","1.32448","84.89079"
"424.00000","1.32513","85.29914"
"424.50000","1.32580","85.80342"
"425.00000","1.32645","85.84830"
"425.50000","1.32710","85.49539"
"426.00000","1.32776","86.02168"
"426.50000","1.32841","85.96007"
"427.00000","1.32907","86.25314"
"427.50000","1.32971","85.99880"
"428.00000","1.33038","86.75126"
"428.50000","1.33103","86.48811"
"429.00000","1.33168","86.65885"
"429.50000","1.33235","86.40187"
"430.00000","1.33301","86.77766"
"430.50000","1.33366","87.26522"
"431.00000","1.33430","86.98007"
"431.50000","1.33498","87.35586"
"432.00000","1.33563","87.05488"
"432.50000","1.33628","87.54244"
"433.00000","1.33695","88.05729"
"433.50000","1.33762","87.70613"
"434.00000","1.33825","87.86895"
"434.50000","1.33891","88.30986"
"435.00000","1.33958","88.20513"
"435.50000","1.34023","88.67861"
"436.00000","1.34087","88.72262"
"436.50000","1.34154","88.65837"
"437.00000","1.34221","88.80534"
"437.50000","1.34283","88.77542"
"438.00000","1.34348","88.50700"
"438.50000","1.34417","88.90215"
"439.00000","1.34482","88.81414"
"439.50000","1.34547","89.24099"
"440.00000","1.34614","89.29467"
"440.50000","1.34678","89.55693"
"441.00000","1.34742","89.52172"
"441.50000","1.34809","89.57717"
"442.00000","1.34877","89.89224"
"442.50000","1.34941","89.75054"
"443.00000","1.35006","90.18265"
"443.50000","1.35072","90.09553"
"444.00000","1.35137","90.07089"
"444.50000","1.35203","90.41236"
"445.00000","1.35269","90.73006"
"445.50000","1.35334","90.41236"
"446.00000","1.35399","90.61478"
"446.50000","1.35467","90.92807"
"447.00000","1.35531","91.00465"
"447.50000","1.35596","90.91664"
"448.00000","1.35663","91.37868"
"448.50000","1.35728","91.38308"
"449.00000","1.35793","91.63214"
"449.50000","1.35859","91.55557"
"450.00000","1.35925","91.67878"
"450.50000","1.35991","91.98857"
"451.00000","1.36056","91.58725"
"451.50000","1.36123","91.78615"
"452.00000","1.36188","92.46645"
"452.50000","1.36253","92.36524"
"453.00000","1.36319","92.40924"
"453.50000","1.36385","92.65918"
"454.00000","1.36450","92.82552"
"454.50000","1.36517","92.66006"
"455.00000","1.36583","92.70407"
"455.50000","1.36647","92.89240"
"456.00000","1.36712","93.14587"
"456.50000","1.36779","93.38788"
"457.00000","1.36844","92.73399"
"457.50000","1.36908","93.27259"
"458.00000","1.36974","93.43805"
"458.50000","1.37042","93.55069"
"459.00000","1.37107","93.70999"
"459.50000","1.37171","93.90448"
"460.00000","1.37239","93.89833"
"460.50000","1.37303","93.59734"
"461.00000","1.37367","93.75223"
"461.50000","1.37434","94.32868"
"462.00000","1.37500","94.10426"
"462.50000","1.37565","94.30844"
"463.00000","1.37630","94.68159"
"463.50000","1.37698","94.54342"
"464.00000","1.37763","94.83736"
"464.50000","1.37828","94.99225"
"465.00000","1.37894","94.88928"
"465.50000","1.37959","94.94561"
"466.00000","1.38024","95.36540"
"466.50000","1.38090","95.13219"
"467.00000","1.38156","95.14011"
"467.50000","1.38222","95.60655"
"468.00000","1.38288","95.32844"
"468.50000","1.38353","95.68752"
"469.00000","1.38418","95.63999"
"469.50000","1.38484","95.39797"
"470.00000","1.38551","95.82304"
"470.50000","1.38615","95.64791"
"471.00000","1.38680","96.11875"
"471.50000","1.38746","96.00170"
"472.00000","1.38813","96.25868"
"472.50000","1.38877","96.53590"
"473.00000","1.38943","96.33437"
"473.50000","1.39010","96.54647"
"474.00000","1.39074","96.92489"
"474.50000","1.39140","96.94953"
"475.00000","1.39206","96.99706"
"475.50000","1.39272","96.96538"
"476.00000","1.39335","97.25052"
"476.50000","1.39403","97.41245"
"477.00000","1.39470","97.69495"
"477.50000","1.39533","97.61135"
"478.00000","1.39599","98.10155"
"478.50000","1.39666","97.47406"
"479.00000","1.39730","97.94489"
"479.50000","1.39795","97.94489"
"480.00000","1.39863","98.02674"
"480.50000","1.39928","98.49143"
"481.00000","1.39991","98.67360"
"481.50000","1.40060","98.91650"
"482.00000","1.40125","98.66568"
"482.50000","1.40191","98.72200"
"483.00000","1.40256","98.67888"
"483.50000","1.40322","99.17348"
"484.00000","1.40387","99.05115"
"484.50000","1.40452","99.15060"
"485.00000","1.40518","99.46655"
"485.50000","1.40584","99.45950"
"486.00000","1.40649","99.47270"
"486.50000","1.40714","99.59327"
"487.00000","1.40781","100.07643"
"487.50000","1.40845","99.79657"
"488.00000","1.40912","100.31669"
"488.50000","1.40977","99.73848"
"489.00000","1.41042","100.65728"
"489.50000","1.41109","100.79458"
"490.00000","1.41175","100.62560"
"490.50000","1.41240","100.15916"
"491.00000","1.41305","100.72153"
"491.50000","1.41372","100.73297"
"492.00000","1.41437","100.77873"
"492.50000","1.41502","101.09819"
"493.00000","1.41569","100.95122"
"493.50000","1.41635","100.93010"
"494.00000","1.41699","101.39830"
"494.50000","1.41765","101.46959"
"495.00000","1.41832","101.61040"
"495.50000","1.41897","101.54527"
"496.00000","1.41961","101.58400"
"496.50000","1.42027","102.17189"
"497.00000","1.42093","102.54856"
"497.50000","1.42157","102.27485"
"498.00000","1.42224","102.47991"
"498.50000","1.42290","102.58640"
"499.00000","1.42355","102.67881"
"499.50000","1.42421","102.72722"
"500.00000","1.42487","102.76065"
"500.50000","1.42552","103.26669"
"501.00000","1.42617","103.26141"
"501.50000","1.42683","103.18572"
"502.00000","1.42750","103.27198"
"502.50000","1.42815","103.68913"
"503.00000","1.42881","103.25701"
"503.50000","1.42947","103.79122"
"504.00000","1.43012","103.79210"
"504.50000","1.43077","103.72873"
"505.00000","1.43143","104.26822"
"505.50000","1.43208","104.02532"
"506.00000","1.43273","104.53136"
"506.50000","1.43341","104.58769"
"507.00000","1.43406","104.55688"
"507.50000","1.43470","104.82178"
"508.00000","1.43537","104.73817"
"508.50000","1.43603","104.76898"
"509.00000","1.43667","104.96259"
"509.50000","1.43733","105.03740"
"510.00000","1.43801","105.31023"
"510.50000","1.43865","105.70362"
"511.00000","1.43930","105.04268"
"511.50000","1.43997","105.49063"
"512.00000","1.44062","105.64641"
"512.50000","1.44126","105.66489"
"513.00000","1.44193","106.03452"
"513.50000","1.44259","106.33199"
"514.00000","1.44322","106.14366"
"514.50000","1.44389","106.45696"
"515.00000","1.44456","106.65673"
"515.50000","1.44521","106.82306"
"516.00000","1.44586","106.66641"
"516.50000","1.44653","107.00436"
"517.00000","1.44718","107.53856"
"517.50000","1.44782","107.25871"
"518.00000","1.44849","107.70490"
"518.50000","1.44916","107.52712"
"519.00000","1.44981","107.93988"
"519.50000","1.45045","107.89852"
"520.00000","1.45112","108.19510"
"520.50000","1.45178","107.76298"
"521.00000","1.45241","108.20830"
"521.50000","1.45308","108.07541"
"522.00000","1.45375","108.49432"
"522.50000","1.45439","108.33239"
"523.00000","1.45506","108.43096"
"523.50000","1.45572","108.52776"
"524.00000","1.45636","108.86044"
"524.50000","1.45702","109.32071"
"525.00000","1.45768","108.83755"
"525.50000","1.45833","108.71522"
"526.00000","1.45898","108.98981"
"526.50000","1.45964","109.16670"
"527.00000","1.46030","109.27319"
"527.50000","1.46096","109.40080"
"528.00000","1.46162","109.19926"
"528.50000","1.46226","109.27055"
"529.00000","1.46291","109.78804"
"529.50000","1.46358","110.14886"
"530.00000","1.46425","110.03533"
"530.50000","1.46489","109.66306"
"531.00000","1.46553","110.57482"
"531.50000","1.46622","110.32665"
"532.00000","1.46687","110.11718"
"532.50000","1.46752","110.64083"
"533.00000","1.46819","110.60034"
"533.50000","1.46884","110.80187"
"534.00000","1.46948","110.96558"
"534.50000","1.47014","111.15127"
"535.00000","1.47080","111.35103"
"535.50000","1.47147","111.43818"
"536.00000","1.47210","111.50857"
"536.50000","1.47278","111.45929"
"537.00000","1.47344","111.38801"
"537.50000","1.47407","111.21728"
"538.00000","1.47473","111.93190"
"538.50000","1.47540","111.90021"
"539.00000","1.47605","111.49889"
"539.50000","1.47670","111.90021"
"540.00000","1.47737","111.74443"
"540.50000","1.47802","112.06038"
"541.00000","1.47866","112.27424"
"541.50000","1.47934","112.80316"
"542.00000","1.47999","112.48545"
"542.50000","1.48064","112.80140"
"543.00000","1.48129","112.87181"
"543.50000","1.48195","112.78733"
"544.00000","1.48260","113.14023"
"544.50000","1.48327","113.42978"
"545.00000","1.48393","113.28016"
"545.50000","1.48458","113.47027"
"546.00000","1.48523","113.88565"
"546.50000","1.48589","114.11624"
"547.00000","1.48654","114.13647"
"547.50000","1.48720","113.80468"
"548.00000","1.48785","113.84077"
"548.50000","1.48850","114.36001"
"549.00000","1.48916","114.13207"
"549.50000","1.48983","114.56595"
"550.00000","1.49049","114.44977"
"550.50000","1.49114","114.26849"
"551.00000","1.49179","114.49730"
"551.50000","1.49246","114.75691"
"552.00000","1.49311","114.98398"
"552.50000","1.49376","114.46826"
"553.00000","1.49443","115.18111"
"553.50000","1.49509","114.92237"
"554.00000","1.49573","115.04383"
"554.50000","1.49639","115.30520"
"555.00000","1.49706","115.38705"
"555.50000","1.49771","115.85614"
"556.00000","1.49835","116.01278"
"556.50000","1.49902","115.89574"
"557.00000","1.49967","115.84998"
"557.50000","1.50031","116.31113"
"558.00000","1.50098","116.59099"
"558.50000","1.50165","116.35777"
"559.00000","1.50230","116.64644"
"559.50000","1.50294","116.62092"
"560.00000","1.50361","117.12520"
"560.50000","1.50426","116.73269"
"561.00000","1.50491","117.38570"
"561.50000","1.50559","117.18328"
"562.00000","1.50624","117.17272"
"562.50000","1.50689","117.24049"
"563.00000","1.50754","117.69371"
"563.50000","1.50820","117.58724"
"564.00000","1.50885","117.70868"
"564.50000","1.50951","117.80550"
"565.00000","1.51017","118.28337"
"565.50000","1.51082","117.96918"
"566.00000","1.51147","118.82286"
"566.50000","1.51215","118.47083"
"567.00000","1.51280","118.42506"
"567.50000","1.51344","118.52100"
"568.00000","1.51411","118.38370"
"568.50000","1.51477","118.36962"
"569.00000","1.51541","119.24000"
"569.50000","1.51607","118.71021"
"570.00000","1.51675","119.19424"
"570.50000","1.51739","119.31746"
"571.00000","1.51804","119.17577"
"571.50000","1.51870","119.20921"
"572.00000","1.51936","119.97135"
"572.50000","1.52000","119.90447"
"573.00000","1.52067","119.61492"
"573.50000","1.52133","119.66684"
"574.00000","1.52197","119.47236"
"574.50000","1.52264","119.80149"
"575.00000","1.52330","120.23449"
"575.50000","1.52396","120.39906"
"576.00000","1.52460","120.51788"
"576.50000","1.52526","120.37177"
"577.00000","1.52592","120.40171"
"577.50000","1.52656","120.52228"
"578.00000","1.52723","120.80918"
"578.50000","1.52788","120.72645"
"579.00000","1.52854","120.93679"
"579.50000","1.52920","120.90423"
"580.00000","1.52985","121.30025"
"580.50000","1.53051","121.69277"
"581.00000","1.53115","121.50619"
"581.50000","1.53182","121.70862"
"582.00000","1.53248","121.86351"
"582.50000","1.53313","121.78958"
"583.00000","1.53380","122.11696"
"583.50000","1.53446","122.47165"
"584.00000","1.53511","122.05009"
"584.50000","1.53577","122.10201"
"585.00000","1.53642","122.05625"
"585.50000","1.53708","122.86151"
"586.00000","1.53772","122.29033"
"586.50000","1.53838","123.35347"
"587.00000","1.53904","122.73302"
"587.50000","1.53968","123.18274"
"588.00000","1.54035","122.99968"
"588.50000","1.54102","123.55676"
"589.00000","1.54167","123.43709"
"589.50000","1.54232","123.52332"
"590.00000","1.54298","123.18802"
"590.50000","1.54363","123.59022"
"591.00000","1.54428","123.92287"
"591.50000","1.54496","124.04344"
"592.00000","1.54561","124.42803"
"592.50000","1.54626","123.72221"
"593.00000","1.54692","124.31979"
"593.50000","1.54758","124.35059"
"594.00000","1.54822","124.76775"
"594.50000","1.54888","124.48348"
"595.00000","1.54955","124.58820"
"595.50000","1.55019","124.89712"
"596.00000","1.55084","125.02826"
"596.50000","1.55151","125.11360"
"597.00000","1.55217","125.06080"
"597.50000","1.55281","125.14530"
"598.00000","1.55347","125.16817"
"598.50000","1.55414","125.33011"
"599.00000","1.55479","125.12682"
"599.50000","1.55544","125.53077"
"600.00000","1.55612","125.29492"
"600.50000","1.55676","125.95937"
"601.00000","1.55741","125.79127"
"601.50000","1.55807","126.16617"
"602.00000","1.55874","125.74110"
"602.50000","1.55938","126.04121"
"603.00000","1.56004","125.96025"
"603.50000","1.56070","126.32723"
"604.00000","1.56135","126.65197"
"604.50000","1.56202","126.77872"
"605.00000","1.56267","127.08322"
"605.50000","1.56333","126.88695"
"606.00000","1.56397","127.09993"
"606.50000","1.56463","127.11227"
"607.00000","1.56529","127.09907"
"607.50000","1.56593","127.38420"
"607.78800","1.56632","127.47749"