File: DataAnalyzer/TestFiles/Specimen_RawData_3.csv
Specimen properties : Specimen label,"orgn_80_NA_2_wblk_3ptbnd_run3"
Maximum Load : Flexure extension at Maximum Load,"1.57921",in
Maximum Load : Maximum Load,"129.29661",lbf

Time,Extension,Load
(s),(in),(lbf)
"0.00000","0.79618","14.97959"
"0.40000","0.79703","14.77805"
"0.80000","0.79724","14.93207"
"1.20000","0.79770","14.36354"
"1.60000","0.79823","14.53515"
"2.00000","0.79875","14.73845"
"2.40000","0.79929","14.56772"
"2.80000","0.79982","14.46211"
"3.20000","0.80032","14.64076"
"3.60000","0.80087","14.48587"
"4.00000","0.80140","14.72349"
"4.40000","0.80193","14.64076"
"4.80000","0.80243","14.71381"
"5.20000","0.80296","14.54220"
"5.60000","0.80349","14.57388"
"6.00000","0.80402","14.79037"
"6.40000","0.80453","14.99719"
"6.80000","0.80506","14.86430"
"7.20000","0.80559","14.62668"
"7.60000","0.80610","14.46563"
"8.00000","0.80663","15.10016"
"8.40000","0.80714","15.15296"
"8.80000","0.80770","15.13008"
"9.20000","0.80823","15.34042"
"9.60000","0.80874","15.35362"
"10.00000","0.80925","15.43635"
"10.40000","0.80979","15.52436"
"10.80000","0.81032","15.33338"
"11.20000","0.81084","15.49707"
"11.60000","0.81135","15.42843"
"12.00000","0.81189","15.76021"
"12.40000","0.81241","15.39938"
"12.80000","0.81293","15.50235"
"13.20000","0.81346","15.34482"
"13.60000","0.81398","15.65285"
"14.00000","0.81451","15.70917"
"14.40000","0.81505","15.95207"
"14.80000","0.81554","15.61236"
"15.20000","0.81608","15.97231"
"15.60000","0.81661","15.66957"
"16.00000","0.81714","15.67925"
"16.40000","0.81766","16.06296"
"16.80000","0.81818","16.24601"
"17.20000","0.81872","15.70037"
"17.60000","0.81925","15.93535"
"18.00000","0.81976","15.99343"
"18.40000","0.82029","16.42995"
"18.80000","0.82082","16.28210"
"19.20000","0.82134","16.20201"
"19.60000","0.82186","16.51356"
"20.00000","0.82237","16.09464"
"20.40000","0.82290","16.01280"
"20.80000","0.82344","16.37890"
"21.20000","0.82397","16.51532"
"21.60000","0.82448","16.72565"
"22.00000","0.82501","16.55668"
"22.40000","0.82554","16.91927"
"22.80000","0.82605","16.75558"
"23.20000","0.82657","16.59716"
"23.60000","0.82711","16.47835"
"24.00000","0.82764","16.94831"
"24.40000","0.82816","17.07504"
"24.80000","0.82869","16.95975"
"25.20000","0.82921","17.04248"
"25.60000","0.82974","17.17537"
"26.00000","0.83027","16.78638"
"26.40000","0.83079","17.21850"
"26.80000","0.83131","17.22906"
"27.20000","0.83184","17.39627"
"27.60000","0.83237","17.58196"
"28.00000","0.83290","17.35403"
"28.40000","0.83341","17.53268"
"28.80000","0.83395","17.47019"
"29.20000","0.83447","17.33114"
"29.60000","0.83498","17.30210"
"30.00000","0.83550","17.67965"
"30.40000","0.83603","17.77118"
"30.80000","0.83656","17.53532"
"31.20000","0.83709","17.62157"
"31.60000","0.83760","18.14169"
"32.00000","0.83812","18.24202"
"32.40000","0.83866","17.97096"
"32.80000","0.83918","17.98592"
"33.20000","0.83970","18.06512"
"33.60000","0.84023","17.79054"
"34.00000","0.84076","18.11705"
"34.40000","0.84130","18.20593"
"34.80000","0.84179","18.16721"
"35.20000","0.84232","18.20593"
"35.60000","0.84286","18.65917"
"36.00000","0.84338","18.36347"
"36.40000","0.84391","18.06160"
"36.80000","0.84443","18.38371"
"37.20000","0.84496","18.42243"
"37.60000","0.84548","18.52012"
"38.00000","0.84600","18.50604"
"38.40000","0.84652","18.25082"
"38.80000","0.84705","19.14145"
"39.20000","0.84758","18.67501"
"39.60000","0.84811","18.52540"
"40.00000","0.84862","18.77798"
"40.40000","0.84915","19.02088"
"40.80000","0.84969","19.38259"
"41.20000","0.85020","19.32187"
"41.60000","0.85073","19.17841"
"42.00000","0.85126","19.28315"
"42.40000","0.85178","19.34387"
"42.80000","0.85231","19.45916"
"43.20000","0.85282","19.24794"
"43.60000","0.85337","19.37731"
"44.00000","0.85388","19.38875"
"44.40000","0.85441","19.55685"
"44.80000","0.85493","19.54101"
"45.20000","0.85545","19.51548"
"45.60000","0.85598","19.10713"
"46.00000","0.85653","19.80767"
"46.40000","0.85702","19.61493"
"46.80000","0.85755","20.28819"
"47.20000","0.85809","19.70910"
"47.60000","0.85862","19.70470"
"48.00000","0.85914","19.74782"
"48.40000","0.85965","20.22482"
"48.80000","0.86019","19.93440"
"49.20000","0.86071","20.17290"
"49.60000","0.86123","20.39556"
"50.00000","0.86174","20.22306"
"50.40000","0.86226","20.39556"
"50.80000","0.86281","20.31195"
"51.20000","0.86334","20.26443"
"51.60000","0.86385","20.27763"
"52.00000","0.86438","20.58389"
"52.40000","0.86492","20.29787"
"52.80000","0.86542","20.73614"
"53.20000","0.86595","20.60941"
"53.60000","0.86648","20.51437"
"54.00000","0.86702","20.55749"
"54.40000","0.86754","21.50445"
"54.80000","0.86804","21.11634"
"55.20000","0.86858","20.58037"
"55.60000","0.86910","20.81887"
"56.00000","0.86963","21.07937"
"56.40000","0.87015","20.95880"
"56.80000","0.87066","21.04329"
"57.20000","0.87121","21.10753"
"57.60000","0.87174","21.04857"
"58.00000","0.87224","21.21666"
"58.40000","0.87277","21.55021"
"58.80000","0.87331","21.60742"
"59.20000","0.87385","21.29763"
"59.60000","0.87436","21.95152"
"60.00000","0.87487","21.46396"
"60.40000","0.87541","21.70246"
"60.80000","0.87595","21.84063"
"61.20000","0.87646","21.44724"
"61.60000","0.87699","21.66726"
"62.00000","0.87750","22.06681"
"62.40000","0.87804","21.42348"
"62.80000","0.87856","21.92512"
"63.20000","0.87906","21.68134"
"63.60000","0.87961","22.16010"
"64.00000","0.88013","22.05713"
"64.40000","0.88066","21.95504"
"64.80000","0.88117","22.66790"
"65.20000","0.88170","21.90488"
"65.60000","0.88223","22.17242"
"66.00000","0.88276","22.42236"
"66.40000","0.88327","22.79463"
"66.80000","0.88380","22.41180"
"67.20000","0.88433","22.61334"
"67.60000","0.88486","22.37836"
"68.00000","0.88538","22.43468"
"68.40000","0.88589","22.37572"
"68.80000","0.88643","22.52357"
"69.20000","0.88696","23.01025"
"69.60000","0.88748","23.18891"
"70.00000","0.88799","23.06130"
"70.40000","0.88852","22.87120"
"70.80000","0.88906","22.83864"
"71.20000","0.88958","23.06042"
"71.60000","0.89010","23.06306"
"72.00000","0.89063","22.93984"
"72.40000","0.89115","23.31564"
"72.80000","0.89167","23.11146"
"73.20000","0.89219","23.19155"
"73.60000","0.89271","23.03841"
"74.00000","0.89326","23.64478"
"74.40000","0.89379","23.43797"
"74.80000","0.89428","23.61838"
"75.20000","0.89483","23.70815"
"75.60000","0.89536","23.38692"
"76.00000","0.89589","23.06130"
"76.40000","0.89640","23.84808"
"76.80000","0.89692","23.73807"
"77.20000","0.89746","23.41157"
"77.60000","0.89799","24.05578"
"78.00000","0.89850","23.89296"
"78.40000","0.89903","23.56205"
"78.80000","0.89954","23.81728"
"79.20000","0.90007","23.69847"
"79.60000","0.90060","24.09098"
"80.00000","0.90110","24.15787"
"80.40000","0.90164","24.52133"
"80.80000","0.90218","24.18251"
"81.20000","0.90270","24.07250"
"81.60000","0.90322","24.34180"
"82.00000","0.90375","24.50197"
"82.40000","0.90428","24.30220"
"82.80000","0.90481","24.24147"
"83.20000","0.90531","24.37260"
"83.60000","0.90586","24.50197"
"84.00000","0.90639","24.40517"
"84.40000","0.90690","24.70263"
"84.80000","0.90742","24.73871"
"85.20000","0.90795","25.03178"
"85.60000","0.90848","24.56798"
"86.00000","0.90901","24.97897"
"86.40000","0.90953","25.11362"
"86.80000","0.91004","24.79856"
"87.20000","0.91057","25.40405"
"87.60000","0.91110","24.99129"
"88.00000","0.91164","25.30020"
"88.40000","0.91214","25.17611"
"88.80000","0.91268","25.28700"
"89.20000","0.91322","25.17347"
"89.60000","0.91371","25.19811"
"90.00000","0.91424","25.63903"
"90.40000","0.91477","25.65399"
"90.80000","0.91530","25.79040"
"91.20000","0.91583","25.68567"
"91.60000","0.91635","25.64519"
"92.00000","0.91687","25.65311"
"92.40000","0.91740","25.84056"
"92.80000","0.91792","26.08874"
"93.20000","0.91846","25.90393"
"93.60000","0.91897","26.09666"
"94.00000","0.91950","26.05090"
"94.40000","0.92003","26.15387"
"94.80000","0.92054","26.35453"
"95.20000","0.92107","26.01746"
"95.60000","0.92161","26.39061"
"96.00000","0.92213","26.37125"
"96.40000","0.92265","26.25684"
"96.80000","0.92317","26.42229"
"97.20000","0.92371","26.21988"
"97.60000","0.92423","26.66255"
"98.00000","0.92475","27.06562"
"98.40000","0.92526","26.51558"
"98.80000","0.92580","26.55254"
"99.20000","0.92633","26.61415"
"99.60000","0.92685","26.87817"
"100.00000","0.92736","26.85529"
"100.40000","0.92789","26.87113"
"100.80000","0.92843","27.29268"
"101.20000","0.92895","27.09643"
"101.60000","0.92947","27.18883"
"102.00000","0.92999","27.07178"
"102.40000","0.93054","27.56199"
"102.80000","0.93105","27.38509"
"103.20000","0.93157","27.40885"
"103.60000","0.93211","27.69576"
"104.00000","0.93263","27.66759"
"104.40000","0.93315","27.64031"
"104.80000","0.93367","27.64119"
"105.20000","0.93419","27.94834"
"105.60000","0.93473","27.98706"
"106.00000","0.93526","27.76880"
"106.40000","0.93576","27.31821"
"106.80000","0.93629","28.10763"
"107.20000","0.93682","28.34085"
"107.60000","0.93734","28.22820"
"108.00000","0.93786","27.96330"
"108.40000","0.93839","28.22732"
"108.80000","0.93893","28.31709"
"109.20000","0.93945","28.33117"
"109.60000","0.93997","28.37781"
"110.00000","0.94049","28.43062"
"110.40000","0.94101","28.22908"
"110.80000","0.94155","28.69816"
"111.20000","0.94208","28.46670"
"111.60000","0.94259","28.87506"
"112.00000","0.94313","28.73424"
"112.40000","0.94365","29.02379"
"112.80000","0.94418","28.63919"
"113.20000","0.94469","28.67440"
"113.60000","0.94522","28.65592"
"114.00000","0.94576","29.02994"
"114.40000","0.94628","29.08275"
"114.80000","0.94679","29.16284"
"115.20000","0.94732","28.94810"
"115.60000","0.94784","29.27197"
"116.00000","0.94838","29.08187"
"116.40000","0.94890","29.02203"
"116.80000","0.94941","29.31069"
"117.20000","0.94994","29.78417"
"117.60000","0.95048","29.22268"
"118.00000","0.95100","29.61959"
"118.40000","0.95152","29.64160"
"118.80000","0.95205","29.73576"
"119.20000","0.95259","29.79209"
"119.60000","0.95309","29.48846"
"120.00000","0.95360","29.62048"
"120.40000","0.95414","29.95490"
"120.80000","0.95467","29.79737"
"121.20000","0.95520","30.17844"
"121.60000","0.95572","29.87042"
"122.00000","0.95623","30.01915"
"122.40000","0.95677","29.92586"
"122.80000","0.95729","30.22596"
"123.20000","0.95779","29.87305"
"123.60000","0.95834","30.08339"
"124.00000","0.95887","30.85786"
"124.40000","0.95941","30.46094"
"124.80000","0.95991","30.46183"
"125.20000","0.96044","30.42398"
"125.60000","0.96098","30.51815"
"126.00000","0.96150","30.51551"
"126.40000","0.96202","30.76545"
"126.80000","0.96255","30.68536"
"127.20000","0.96308","30.95467"
"127.60000","0.96359","30.74961"
"128.00000","0.96412","30.89042"
"128.40000","0.96463","30.74961"
"128.80000","0.96517","31.13772"
"129.20000","0.96571","31.36390"
"129.60000","0.96622","31.14564"
"130.00000","0.96673","31.43255"
"130.40000","0.96726","31.53991"
"130.80000","0.96780","31.41054"
"131.20000","0.96832","31.83474"
"131.60000","0.96884","31.42286"
"132.00000","0.96937","31.60328"
"132.40000","0.96989","31.82681"
"132.80000","0.97042","31.61208"
"133.20000","0.97094","31.70097"
"133.60000","0.97147","31.51439"
"134.00000","0.97199","31.70977"
"134.40000","0.97253","32.20701"
"134.80000","0.97304","31.69129"
"135.20000","0.97356","31.91746"
"135.60000","0.97409","32.12604"
"136.00000","0.97463","31.88930"
"136.40000","0.97514","32.34958"
"136.80000","0.97566","32.15860"
"137.20000","0.97620","32.50095"
"137.60000","0.97673","32.32934"
"138.00000","0.97723","31.95355"
"138.40000","0.97777","32.61624"
"138.80000","0.97828","32.60832"
"139.20000","0.97882","32.41822"
"139.60000","0.97935","32.51591"
"140.00000","0.97984","32.58720"
"140.40000","0.98039","32.74473"
"140.80000","0.98092","32.47983"
"141.20000","0.98145","32.97179"
"141.60000","0.98196","32.63208"
"142.00000","0.98248","32.90226"
"142.40000","0.98302","33.59488"
"142.80000","0.98355","33.41447"
"143.20000","0.98406","33.20853"
"143.60000","0.98459","33.02195"
"144.00000","0.98513","33.26573"
"144.40000","0.98564","33.29302"
"144.80000","0.98616","33.61160"
"145.20000","0.98667","33.55440"
"145.60000","0.98721","33.69785"
"146.00000","0.98775","33.49983"
"146.40000","0.98827","33.74537"
"146.80000","0.98878","33.71457"
"147.20000","0.98932","33.77442"
"147.60000","0.98985","33.79906"
"148.00000","0.99037","34.53040"
"148.40000","0.99088","34.02436"
"148.80000","0.99142","34.00412"
"149.20000","0.99195","34.07188"
"149.60000","0.99246","34.09476"
"150.00000","0.99298","33.85450"
"150.40000","0.99351","34.22942"
"150.80000","0.99404","34.75306"
"151.20000","0.99457","34.41071"
"151.60000","0.99508","34.42743"
"152.00000","0.99561","34.56912"
"152.40000","0.99614","34.28926"
"152.80000","0.99666","34.70730"
"153.20000","0.99718","34.18717"
"153.60000","0.99771","34.51808"
"154.00000","0.99825","34.52424"
"154.40000","0.99878","34.68001"
"154.80000","0.99928","34.93875"
"155.20000","0.99981","34.71169"
"155.60000","1.00035","34.94755"
"156.00000","1.00086","34.77946"
"156.40000","1.00139","35.09012"
"156.80000","1.00191","35.05492"
"157.20000","1.00245","35.03820"
"157.60000","1.00297","35.12005"
"158.00000","1.00349","35.45888"
"158.40000","1.00400","35.18077"
"158.80000","1.00453","35.16405"
"159.20000","1.00507","35.09365"
"159.60000","1.00560","35.43335"
"160.00000","1.00610","35.31102"
"160.40000","1.00664","35.38935"
"160.80000","1.00717","35.37879"
"161.20000","1.00769","35.23358"
"161.60000","1.00821","35.31807"
"162.00000","1.00874","35.77922"
"162.40000","1.00928","36.11453"
"162.80000","1.00979","35.93323"
"163.20000","1.01031","35.76778"
"163.60000","1.01084","35.72642"
"164.00000","1.01137","35.97900"
"164.40000","1.01189","36.30198"
"164.80000","1.01241","35.98868"
"165.20000","1.01292","36.29494"
"165.60000","1.01346","35.96052"
"166.00000","1.01400","36.50528"
"166.40000","1.01450","36.06788"
"166.80000","1.01503","36.65577"
"167.20000","1.01556","36.27294"
"167.60000","1.01608","36.76227"
"168.00000","1.01661","36.68306"
"168.40000","1.01713","36.56072"
"168.80000","1.01768","36.40319"
"169.20000","1.01820","36.52200"
"169.60000","1.01871","36.42255"
"170.00000","1.01923","36.55545"
"170.40000","1.01975","36.45512"
"170.80000","1.02030","36.57833"
"171.20000","1.02082","36.88547"
"171.60000","1.02133","36.68834"
"172.00000","1.02186","37.34751"
"172.40000","1.02239","37.31671"
"172.80000","1.02290","36.74994"
"173.20000","1.02343","36.72794"
"173.60000","1.02396","37.28238"
"174.00000","1.02449","37.64498"
"174.40000","1.02502","37.04477"
"174.80000","1.02553","37.22166"
"175.20000","1.02606","37.73298"
"175.60000","1.02658","37.04477"
"176.00000","1.02712","37.36687"
"176.40000","1.02764","37.57105"
"176.80000","1.02815","37.48040"
"177.20000","1.02869","37.43640"
"177.60000","1.02921","37.47688"
"178.00000","1.02974","37.90724"
"178.40000","1.03025","37.82539"
"178.80000","1.03079","37.94596"
"179.20000","1.03132","37.63441"
"179.60000","1.03183","37.83595"
"180.00000","1.03234","37.45752"
"180.40000","1.03288","38.12814"
"180.80000","1.03341","37.89052"
"181.20000","1.03394","37.90724"
"181.60000","1.03447","37.94420"
"182.00000","1.03498","38.13694"
"182.40000","1.03552","38.36135"
"182.80000","1.03604","38.26367"
"183.20000","1.03655","37.93804"
"183.60000","1.03708","38.45200"
"184.00000","1.03761","38.07621"
"184.40000","1.03814","37.99261"
"184.80000","1.03865","38.55321"
"185.20000","1.03918","38.50481"
"185.60000","1.03972","38.58929"
"186.00000","1.04025","38.32879"
"186.40000","1.04075","38.05861"
"186.80000","1.04128","38.44320"
"187.20000","1.04182","38.44760"
"187.60000","1.04234","38.32263"
"188.00000","1.04286","38.97036"
"188.40000","1.04337","39.02669"
"188.80000","1.04392","39.07069"
"189.20000","1.04444","38.88236"
"189.60000","1.04496","38.81283"
"190.00000","1.04547","38.67202"
"190.40000","1.04601","39.08301"
"190.80000","1.04655","38.95981"
"191.20000","1.04705","39.07685"
"191.60000","1.04757","39.06189"
"192.00000","1.04811","39.20446"
"192.40000","1.04864","39.22646"
"192.80000","1.04915","39.19126"
"193.20000","1.04968","39.26871"
"193.60000","1.05021","39.45792"
"194.00000","1.05072","39.20006"
"194.40000","1.05126","39.24758"
"194.80000","1.05178","39.23879"
"195.20000","1.05230","39.18686"
"195.60000","1.05284","39.33383"
"196.00000","1.05337","39.67002"
"196.40000","1.05388","39.51161"
"196.80000","1.05440","39.29511"
"197.20000","1.05494","39.64978"
"197.60000","1.05547","39.74131"
"198.00000","1.05598","39.50633"
"198.40000","1.05651","39.86892"
"198.80000","1.05704","39.72106"
"199.20000","1.05756","40.21214"
"199.60000","1.05809","39.46672"
"200.00000","1.05858","39.77475"
"200.40000","1.05912","40.09862"
"200.80000","1.05966","39.77123"
"201.20000","1.06019","40.19455"
"201.60000","1.06070","40.39080"
"202.00000","1.06123","40.01765"
"202.40000","1.06177","40.18311"
"202.80000","1.06229","40.50257"
"203.20000","1.06279","40.07662"
"203.60000","1.06334","40.44977"
"204.00000","1.06387","40.05109"
"204.40000","1.06439","40.42424"
"204.80000","1.06490","40.29487"
"205.20000","1.06543","40.72699"
"205.60000","1.06596","40.51929"
"206.00000","1.06649","40.54041"
"206.40000","1.06701","40.91092"
"206.80000","1.06752","40.55802"
"207.20000","1.06805","40.82820"
"207.60000","1.06857","41.04733"
"208.00000","1.06909","40.80356"
"208.40000","1.06962","41.26207"
"208.80000","1.07016","41.16438"
"209.20000","1.07069","41.28584"
"209.60000","1.07120","41.31399"
"210.00000","1.07173","41.63875"
"210.40000","1.07225","41.41080"
"210.80000","1.07278","41.76988"
"211.20000","1.07332","41.86668"
"211.60000","1.07383","41.94501"
"212.00000","1.07435","42.21959"
"212.40000","1.07488","41.87636"
"212.80000","1.07540","42.05678"
"213.20000","1.07592","41.86492"
"213.60000","1.07645","42.12190"
"214.00000","1.07699","42.45985"
"214.40000","1.07752","42.30320"
"214.80000","1.07803","42.46425"
"215.20000","1.07855","42.48185"
"215.60000","1.07909","42.65611"
"216.00000","1.07962","42.60154"
"216.40000","1.08013","42.84180"
"216.80000","1.08065","42.33576"
"217.20000","1.08119","42.66843"
"217.60000","1.08171","42.83916"
"218.00000","1.08223","42.91045"
"218.40000","1.08274","43.35665"
"218.80000","1.08328","42.86997"
"219.20000","1.08381","43.16743"
"219.60000","1.08434","42.86381"
"220.00000","1.08484","43.50362"
"220.40000","1.08537","43.07502"
"220.80000","1.08591","43.76324"
"221.20000","1.08643","43.04510"
"221.60000","1.08695","43.60571"
"222.00000","1.08747","43.13311"
"222.40000","1.08799","43.55202"
"222.80000","1.08852","44.04398"
"223.20000","1.08904","43.71923"
"223.60000","1.08958","43.93221"
"224.00000","1.09010","43.89877"
"224.40000","1.09062","43.80020"
"224.80000","1.09115","44.42681"
"225.20000","1.09166","43.88909"
"225.60000","1.09221","43.85125"
"226.00000","1.09274","44.29568"
"226.40000","1.09325","44.26136"
"226.80000","1.09377","44.39777"
"227.20000","1.09430","44.29744"
"227.60000","1.09484","44.54738"
"228.00000","1.09535","44.79733"
"228.40000","1.09587","44.93109"
"228.80000","1.09641","45.26288"
"229.20000","1.09694","44.43914"
"229.60000","1.09745","45.01206"
"230.00000","1.09797","44.71988"
"230.40000","1.09849","45.30248"
"230.80000","1.09904","45.19776"
"231.20000","1.09956","45.19688"
"231.60000","1.10006","45.27960"
"232.00000","1.10060","45.24616"
"232.40000","1.10113","45.48642"
"232.80000","1.10166","45.82525"
"233.20000","1.10217","45.99774"
"233.60000","1.10270","45.81469"
"234.00000","1.10324","45.38873"
"234.40000","1.10376","45.87806"
"234.80000","1.10427","46.04262"
"235.20000","1.10480","46.18256"
"235.60000","1.10532","46.23888"
"236.00000","1.10585","46.32953"
"236.40000","1.10638","46.26704"
"236.80000","1.10689","46.55483"
"237.20000","1.10742","46.26880"
"237.60000","1.10796","46.40610"
"238.00000","1.10848","46.75813"
"238.40000","1.10899","46.69828"
"238.80000","1.10952","46.88926"
"239.20000","1.11006","46.68244"
"239.60000","1.11057","46.23184"
"240.00000","1.11108","46.83381"
"240.40000","1.11163","46.99926"
"240.80000","1.11215","47.34953"
"241.20000","1.11267","47.25537"
"241.60000","1.11320","47.19552"
"242.00000","1.11372","47.27737"
"242.40000","1.11425","47.43754"
"242.80000","1.11478","47.28529"
"243.20000","1.11529","47.51499"
"243.60000","1.11583","47.79661"
"244.00000","1.11636","47.21136"
"244.40000","1.11688","47.57483"
"244.80000","1.11739","47.66372"
"245.20000","1.11791","48.02807"
"245.60000","1.11846","48.18296"
"246.00000","1.11899","47.91014"
"246.40000","1.11949","47.89606"
"246.80000","1.12002","48.46459"
"247.20000","1.12054","48.38714"
"247.60000","1.12108","48.04743"
"248.00000","1.12160","47.98847"
"248.40000","1.12211","48.38274"
"248.80000","1.12265","48.42850"
"249.20000","1.12318","48.63796"
"249.60000","1.12370","48.46899"
"250.00000","1.12421","48.22696"
"250.40000","1.12474","49.18184"
"250.80000","1.12527","48.95831"
"251.20000","1.12579","49.05511"
"251.60000","1.12631","48.99967"
"252.00000","1.12685","48.85094"
"252.40000","1.12738","49.24169"
"252.80000","1.12790","49.03047"
"253.20000","1.12841","49.30066"
"253.60000","1.12895","49.48987"
"254.00000","1.12947","49.29890"
"254.40000","1.13001","49.38162"
"254.80000","1.13050","49.82870"
"255.20000","1.13104","49.23553"
"255.60000","1.13158","49.95190"
"256.00000","1.13211","50.02055"
"256.40000","1.13262","50.12616"
"256.80000","1.13314","50.13672"
"257.20000","1.13368","50.26433"
"257.60000","1.13421","50.21417"
"258.00000","1.13471","50.18161"
"258.40000","1.13524","50.23001"
"258.80000","1.13577","50.14376"
"259.20000","1.13630","50.94023"
"259.60000","1.13682","50.72813"
"260.00000","1.13734","50.17897"
"260.40000","1.13786","50.66917"
"260.80000","1.13841","50.35146"
"261.20000","1.13893","51.13472"
"261.60000","1.13944","51.10568"
"262.00000","1.13997","50.78094"
"262.40000","1.14051","50.83198"
"262.80000","1.14103","51.10656"
"263.20000","1.14153","51.01767"
"263.60000","1.14207","51.41371"
"264.00000","1.14260","51.46123"
"264.40000","1.14312","51.09776"
"264.80000","1.14364","51.30106"
"265.20000","1.14416","51.36355"
"265.60000","1.14469","51.73581"
"266.00000","1.14522","51.72789"
"266.40000","1.14574","51.43483"
"266.80000","1.14626","51.59060"
"267.20000","1.14679","51.65484"
"267.60000","1.14732","51.93471"
"268.00000","1.14785","51.78862"
"268.40000","1.14836","51.86430"
"268.80000","1.14890","52.39235"
"269.20000","1.14944","51.92855"
"269.60000","1.14994","52.56572"
"270.00000","1.15046","51.79126"
"270.40000","1.15099","52.50852"
"270.80000","1.15152","52.03504"
"271.20000","1.15205","52.56396"
"271.60000","1.15257","52.39323"
"272.00000","1.15309","52.80070"
"272.40000","1.15363","52.96439"
"272.80000","1.15414","52.80598"
"273.20000","1.15467","53.07529"
"273.60000","1.15519","52.81478"
"274.00000","1.15572","53.18353"
"274.40000","1.15626","53.26714"
"274.80000","1.15675","53.22490"
"275.20000","1.15729","53.36131"
"275.60000","1.15783","53.46252"
"276.00000","1.15836","53.45195"
"276.40000","1.15887","53.31466"
"276.80000","1.15939","53.71422"
"277.20000","1.15994","53.44843"
"277.60000","1.16045","53.69574"
"278.00000","1.16097","53.86823"
"278.40000","1.16148","54.24754"
"278.80000","1.16202","53.85767"
"279.20000","1.16255","53.56900"
"279.60000","1.16307","53.97912"
"280.00000","1.16358","53.85327"
"280.40000","1.16411","54.43236"
"280.80000","1.16465","54.66470"
"281.20000","1.16517","54.65854"
"281.60000","1.16569","54.26954"
"282.00000","1.16622","54.61453"
"282.40000","1.16675","54.60837"
"282.80000","1.16727","54.86887"
"283.20000","1.16779","54.77647"
"283.60000","1.16832","54.75710"
"284.00000","1.16884","54.89967"
"284.40000","1.16937","54.71662"
"284.80000","1.16989","54.73862"
"285.20000","1.17041","55.12233"
"285.60000","1.17095","55.23851"
"286.00000","1.17148","55.29219"
"286.40000","1.17199","55.54917"
"286.80000","1.17251","55.66974"
"287.20000","1.17304","55.61430"
"287.60000","1.17358","55.88360"
"288.00000","1.17409","55.83255"
"288.40000","1.17461","56.37468"
"288.80000","1.17515","56.08689"
"289.20000","1.17567","56.30515"
"289.60000","1.17619","56.13706"
"290.00000","1.17671","56.24971"
"290.40000","1.17723","56.54981"
"290.80000","1.17777","56.08425"
"291.20000","1.17830","56.65278"
"291.60000","1.17881","56.99161"
"292.00000","1.17933","57.10602"
"292.40000","1.17987","56.67654"
"292.80000","1.18038","56.91240"
"293.20000","1.18091","57.05498"
"293.60000","1.18143","56.96433"
"294.00000","1.18197","57.03385"
"294.40000","1.18249","57.50997"
"294.80000","1.18300","57.53462"
"295.20000","1.18354","57.19315"
"295.60000","1.18407","57.64990"
"296.00000","1.18460","57.41316"
"296.40000","1.18512","57.86464"
"296.80000","1.18563","57.28468"
"297.20000","1.18617","57.53901"
"297.60000","1.18670","58.04858"
"298.00000","1.18722","58.06090"
"298.40000","1.18773","58.39268"
"298.80000","1.18827","57.98081"
"299.20000","1.18880","58.52205"
"299.60000","1.18931","58.32668"
"300.00000","1.18983","58.37684"
"300.40000","1.19036","58.17882"
"300.80000","1.19089","59.06594"
"301.20000","1.19142","58.11106"
"301.60000","1.19194","59.03161"
"302.00000","1.19246","59.02369"
"302.40000","1.19300","58.89256"
"302.80000","1.19352","58.99641"
"303.20000","1.19402","59.28595"
"303.60000","1.19456","59.04394"
"304.00000","1.19510","59.10818"
"304.40000","1.19563","59.38981"
"304.80000","1.19613","59.38717"
"305.20000","1.19666","59.52270"
"305.60000","1.19719","59.33524"
"306.00000","1.19773","59.52974"
"306.40000","1.19824","59.54030"
"306.80000","1.19876","59.37044"
"307.20000","1.19928","59.77440"
"307.60000","1.19981","59.88001"
"308.00000","1.20033","59.93632"
"308.40000","1.20084","59.96449"
"308.80000","1.20139","59.91785"
"309.20000","1.20193","60.07714"
"309.60000","1.20243","59.82896"
"310.00000","1.20295","60.03138"
"310.40000","1.20348","60.39837"
"310.80000","1.20403","60.56206"
"311.20000","1.20455","60.16603"
"311.60000","1.20505","60.45821"
"312.00000","1.20559","60.66239"
"312.40000","1.20612","60.42477"
"312.80000","1.20663","60.97570"
"313.20000","1.20716","61.34181"
"313.60000","1.20769","60.72311"
"314.00000","1.20821","61.33125"
"314.40000","1.20875","61.55742"
"314.80000","1.20926","61.02498"
"315.20000","1.20978","61.32948"
"315.60000","1.21031","61.12795"
"316.00000","1.21084","60.91585"
"316.40000","1.21136","61.42805"
"316.80000","1.21188","61.76952"
"317.20000","1.21242","61.72024"
"317.60000","1.21295","61.59351"
"318.00000","1.21346","61.63399"
"318.40000","1.21399","61.87865"
"318.80000","1.21452","61.57767"
"319.20000","1.21504","62.11363"
"319.60000","1.21557","62.20692"
"320.00000","1.21608","62.39965"
"320.40000","1.21661","62.22892"
"320.80000","1.21714","62.29228"
"321.20000","1.21767","62.71736"
"321.60000","1.21817","62.51054"
"322.00000","1.21870","62.63551"
"322.40000","1.21923","62.82649"
"322.80000","1.21977","62.95146"
"323.20000","1.22027","62.52902"
"323.60000","1.22081","63.11340"
"324.00000","1.22134","63.05354"
"324.40000","1.22186","63.23308"
"324.80000","1.22238","63.40469"
"325.20000","1.22290","63.59304"
"325.60000","1.22344","63.82361"
"326.00000","1.22397","64.03219"
"326.40000","1.22448","63.92921"
"326.80000","1.22500","63.43021"
"327.20000","1.22553","63.95210"
"327.60000","1.22606","64.01547"
"328.00000","1.22660","64.02867"
"328.40000","1.22710","63.73472"
"328.80000","1.22765","64.28125"
"329.20000","1.22817","64.21524"
"329.60000","1.22868","64.51886"
"330.00000","1.22920","64.79433"
"330.40000","1.22973","64.68873"
"330.80000","1.23026","64.73888"
"331.20000","1.23079","64.64560"
"331.60000","1.23131","64.73097"
"332.00000","1.23183","64.60160"
"332.40000","1.23236","64.91050"
"332.80000","1.23288","64.86561"
"333.20000","1.23341","65.23524"
"333.60000","1.23393","65.29861"
"334.00000","1.23446","65.11732"
"334.40000","1.23500","65.60312"
"334.80000","1.23550","65.37958"
"335.20000","1.23603","65.68232"
"335.60000","1.23656","65.57319"
"336.00000","1.23708","65.65768"
"336.40000","1.23761","65.76065"
"336.80000","1.23813","65.77913"
"337.20000","1.23867","66.02731"
"337.60000","1.23919","66.24996"
"338.00000","1.23971","66.15405"
"338.40000","1.24022","66.28429"
"338.80000","1.24075","66.32038"
"339.20000","1.24129","66.52191"
"339.60000","1.24181","66.14876"
"340.00000","1.24232","66.24996"
"340.40000","1.24286","66.72785"
"340.80000","1.24339","66.40310"
"341.20000","1.24392","66.82378"
"341.60000","1.24443","66.52984"
"342.00000","1.24495","67.30254"
"342.40000","1.24549","66.98659"
"342.80000","1.24601","67.16613"
"343.20000","1.24652","67.07460"
"343.60000","1.24707","67.37911"
"344.00000","1.24758","67.54719"
"344.40000","1.24812","67.38174"
"344.80000","1.24863","67.98723"
"345.20000","1.24915","67.68801"
"345.60000","1.24969","67.78834"
"346.00000","1.25023","68.07964"
"346.40000","1.25073","68.05324"
"346.80000","1.25126","67.91419"
"347.20000","1.25179","68.14212"
"347.60000","1.25232","68.43167"
"348.00000","1.25283","68.67369"
"348.40000","1.25335","68.32342"
"348.80000","1.25389","68.74321"
"349.20000","1.25443","68.77490"
"349.60000","1.25493","68.68777"
"350.00000","1.25545","68.71593"
"350.40000","1.25596","68.47039"
"350.80000","1.25651","69.15509"
"351.20000","1.25704","69.66641"
"351.60000","1.25755","69.12869"
"352.00000","1.25808","69.37335"
"352.40000","1.25861","69.75794"
"352.80000","1.25912","69.57049"
"353.20000","1.25965","69.57664"
"353.60000","1.26018","69.32934"
"354.00000","1.26072","69.70777"
"354.40000","1.26124","70.00788"
"354.80000","1.26175","70.21382"
"355.20000","1.26228","70.33702"
"355.60000","1.26280","69.91019"
"356.00000","1.26333","70.42240"
"356.40000","1.26386","70.38719"
"356.80000","1.26437","70.06420"
"357.20000","1.26490","70.39159"
"357.60000","1.26544","70.10996"
"358.00000","1.26596","70.67145"
"358.40000","1.26648","70.81226"
"358.80000","1.26701","70.89940"
"359.20000","1.26755","70.77530"
"359.60000","1.26805","70.93811"
"360.00000","1.26856","71.24438"
"360.40000","1.26910","71.05252"
"360.80000","1.26963","70.95307"
"361.20000","1.27016","71.59641"
"361.60000","1.27068","71.30159"
"362.00000","1.27120","72.23447"
"362.40000","1.27174","71.99509"
"362.80000","1.27226","71.63425"
"363.20000","1.27278","72.31983"
"363.60000","1.27331","71.66857"
"364.00000","1.27384","72.39903"
"364.40000","1.27436","71.80059"
"364.80000","1.27487","72.33567"
"365.20000","1.27539","72.19222"
"365.60000","1.27594","72.38055"
"366.00000","1.27647","72.48000"
"366.40000","1.27697","72.74667"
"366.80000","1.27750","72.86899"
"367.20000","1.27802","72.89363"
"367.60000","1.27855","72.36823"
"368.00000","1.27908","72.89451"
"368.40000","1.27959","72.71498"
"368.80000","1.28013","73.08989"
"369.20000","1.28067","73.01157"
"369.60000","1.28118","72.96756"
"370.00000","1.28169","73.73850"
"370.40000","1.28222","73.22718"
"370.80000","1.28276","73.27383"
"371.20000","1.28330","73.58097"
"371.60000","1.28379","73.97261"
"372.00000","1.28433","73.48504"
"372.40000","1.28486","74.20231"
"372.80000","1.28537","74.09494"
"373.20000","1.28590","73.67954"
"373.60000","1.28643","74.12309"
"374.00000","1.28696","74.26479"
"374.40000","1.28749","74.58602"
"374.80000","1.28798","74.55609"
"375.20000","1.28852","74.25071"
"375.60000","1.28906","74.23839"
"376.00000","1.28959","74.64234"
"376.40000","1.29010","74.45048"
"376.80000","1.29062","74.79019"
"377.20000","1.29116","74.91692"
"377.60000","1.29169","75.07974"
"378.00000","1.29220","75.08678"
"378.40000","1.29272","74.82539"
"378.80000","1.29325","75.74859"
"379.20000","1.29378","75.29975"
"379.60000","1.29430","75.60689"
"380.00000","1.29480","75.69667"
"380.40000","1.29534","75.78995"
"380.80000","1.29588","75.55762"
"381.20000","1.29640","75.92108"
"381.60000","1.29692","76.05397"
"382.00000","1.29745","75.81108"
"382.40000","1.29799","75.95364"
"382.80000","1.29851","75.72307"
"383.20000","1.29901","76.34264"
"383.60000","1.29956","76.89269"
"384.00000","1.30009","76.29424"
"384.40000","1.30060","76.49049"
"384.80000","1.30112","76.63659"
"385.20000","1.30165","77.14175"
"385.60000","1.30217","76.67354"
"386.00000","1.30271","77.20247"
"386.40000","1.30323","76.88652"
"386.80000","1.30376","77.35384"
"387.20000","1.30427","77.02118"
"387.60000","1.30480","77.33360"
"388.00000","1.30534","77.23415"
"388.40000","1.30585","77.65042"
"388.80000","1.30638","77.77540"
"389.20000","1.30691","77.95053"
"389.60000","1.30742","77.69179"
"390.00000","1.30794","78.03678"
"390.40000","1.30848","78.13798"
"390.80000","1.30902","77.99454"
"391.20000","1.30953","78.06758"
"391.60000","1.31005","78.09487"
"392.00000","1.31057","78.13975"
"392.40000","1.31109","78.28144"
"392.80000","1.31162","78.47418"
"393.20000","1.31215","78.96789"
"393.60000","1.31267","78.90453"
"394.00000","1.31320","79.10607"
"394.40000","1.31373","79.18527"
"394.80000","1.31424","79.06470"
"395.20000","1.31477","79.39297"
"395.60000","1.31531","79.76260"
"396.00000","1.31584","79.89637"
"396.40000","1.31635","79.61211"
"396.80000","1.31687","79.61563"
"397.20000","1.31741","79.65347"
"397.60000","1.31793","79.63499"
"398.00000","1.31845","79.62883"
"398.40000","1.31896","80.29152"
"398.80000","1.31950","80.19912"
"399.20000","1.32003","80.43850"
"399.60000","1.32056","80.12607"
"400.00000","1.32106","80.55291"
"400.40000","1.32159","80.05038"
"400.80000","1.32213","80.64003"
"401.20000","1.32266","80.19384"
"401.60000","1.32317","80.42002"
"402.00000","1.32369","80.91022"
"402.40000","1.32423","80.47194"
"402.80000","1.32475","81.15223"
"403.20000","1.32527","80.96830"
"403.60000","1.32581","81.10207"
"404.00000","1.32633","81.28248"
"404.40000","1.32685","81.58347"
"404.80000","1.32736","81.34937"
"405.20000","1.32789","81.53242"
"405.60000","1.32843","82.04551"
"406.00000","1.32896","81.65475"
"406.40000","1.32948","81.73661"
"406.80000","1.32999","82.03055"
"407.20000","1.33052","82.47762"
"407.60000","1.33106","82.43715"
"408.00000","1.33157","82.24528"
"408.40000","1.33209","82.28753"
"408.80000","1.33262","82.42482"
"409.20000","1.33315","82.07631"
"409.60000","1.33367","82.52515"
"410.00000","1.33419","82.52867"
"410.40000","1.33471","83.05143"
"410.80000","1.33526","82.94582"
"411.20000","1.33578","82.83582"
"411.60000","1.33629","83.10336"
"412.00000","1.33682","83.01887"
"412.40000","1.33736","83.51874"
"412.80000","1.33788","82.77509"
"413.20000","1.33839","83.20368"
"413.60000","1.33892","83.61027"
"414.00000","1.33946","83.71589"
"414.40000","1.33998","83.86022"
"414.80000","1.34049","83.68772"
"415.20000","1.34102","83.92271"
"415.60000","1.34154","83.52755"
"416.00000","1.34207","83.87694"
"416.40000","1.34260","84.18584"
"416.80000","1.34311","84.37946"
"417.20000","1.34364","83.94470"
"417.60000","1.34417","84.56955"
"418.00000","1.34470","84.25185"
"418.40000","1.34522","84.42434"
"418.80000","1.34575","84.77021"
"419.20000","1.34629","84.54844"
"419.60000","1.34679","84.82390"
"420.00000","1.34730","84.36714"
"420.40000","1.34784","84.91982"
"420.80000","1.34837","85.28857"
"421.20000","1.34890","85.26746"
"421.60000","1.34942","84.86966"
"422.00000","1.34993","85.07296"
"422.40000","1.35046","85.15657"
"422.80000","1.35099","85.56844"
"423.20000","1.35150","85.63796"
"423.60000","1.35204","85.82014"
"424.00000","1.35257","86.05160"
"424.40000","1.35310","85.77525"
"424.80000","1.35361","85.79022"
"425.20000","1.35414","85.82807"
"425.60000","1.35468","86.40362"
"426.00000","1.35521","86.55588"
"426.40000","1.35571","86.60868"
"426.80000","1.35624","86.12025"
"427.20000","1.35676","86.46875"
"427.60000","1.35729","86.42211"
"428.00000","1.35782","86.78030"
"428.40000","1.35834","86.97391"
"428.80000","1.35888","86.98448"
"429.20000","1.35941","87.37259"
"429.60000","1.35992","87.51163"
"430.00000","1.36043","87.41659"
"430.40000","1.36096","87.63837"
"430.80000","1.36150","87.71406"
"431.20000","1.36203","87.32243"
"431.60000","1.36254","87.82230"
"432.00000","1.36307","87.54948"
"432.40000","1.36361","87.86015"
"432.80000","1.36412","87.99744"
"433.20000","1.36464","88.31779"
"433.60000","1.36517","88.24473"
"434.00000","1.36569","88.00800"
"434.40000","1.36623","88.17521"
"434.80000","1.36674","87.72901"
"435.20000","1.36726","88.49028"
"435.60000","1.36779","88.57389"
"436.00000","1.36832","88.61525"
"436.40000","1.36884","89.10369"
"436.80000","1.36936","88.49292"
"437.20000","1.36990","88.78335"
"437.60000","1.37042","89.01568"
"438.00000","1.37094","89.13977"
"438.40000","1.37146","88.93384"
"438.80000","1.37200","88.93912"
"439.20000","1.37252","89.14594"
"439.60000","1.37305","89.42580"
"440.00000","1.37354","89.04384"
"440.40000","1.37408","89.64318"
"440.80000","1.37462","89.47156"
"441.20000","1.37515","89.41787"
"441.60000","1.37566","89.73118"
"442.00000","1.37618","89.67750"
"442.40000","1.37672","90.02336"
"442.80000","1.37725","90.10961"
"443.20000","1.37776","89.83591"
"443.60000","1.37830","90.18706"
"444.00000","1.37883","90.00136"
"444.40000","1.37934","90.45284"
"444.80000","1.37986","90.15977"
"445.20000","1.38039","90.69574"
"445.60000","1.38091","90.37804"
"446.00000","1.38145","90.70718"
"446.40000","1.38197","90.74942"
"446.80000","1.38248","90.48980"
"447.20000","1.38301","90.76878"
"447.60000","1.38354","91.24931"
"448.00000","1.38407","91.39628"
"448.40000","1.38458","91.31532"
"448.80000","1.38512","91.58902"
"449.20000","1.38566","91.44116"
"449.60000","1.38616","91.96745"
"450.00000","1.38668","91.46141"
"450.40000","1.38721","91.61277"
"450.80000","1.38774","91.87768"
"451.20000","1.38827","92.01145"
"451.60000","1.38878","92.29835"
"452.00000","1.38932","92.38548"
"452.40000","1.38984","92.80527"
"452.80000","1.39036","92.37668"
"453.20000","1.39089","92.59318"
"453.60000","1.39141","93.02793"
"454.00000","1.39195","92.88712"
"454.40000","1.39248","92.83960"
"454.80000","1.39297","93.10890"
"455.20000","1.39351","93.00505"
"455.60000","1.39405","92.94344"
"456.00000","1.39458","93.17754"
"456.40000","1.39509","93.45477"
"456.80000","1.39561","93.87632"
"457.20000","1.39615","93.54542"
"457.60000","1.39667","93.94321"
"458.00000","1.39719","94.16763"
"458.40000","1.39771","93.91592"
"458.80000","1.39824","94.17731"
"459.20000","1.39877","94.47829"
"459.60000","1.39929","94.36388"
"460.00000","1.39979","94.17819"
"460.40000","1.40033","94.18699"
"460.80000","1.40087","94.79512"
"461.20000","1.40140","94.99313"
"461.60000","1.40191","94.96937"
"462.00000","1.40244","95.20788"
"462.40000","1.40297","95.09170"
"462.80000","1.40349","95.15419"
"463.20000","1.40400","95.03626"
"463.60000","1.40454","95.39180"
"464.00000","1.40506","95.41909"
"464.40000","1.40559","95.64791"
"464.80000","1.40611","95.45165"
"465.20000","1.40662","95.71304"
"465.60000","1.40716","96.15131"
"466.00000","1.40770","96.27100"
"466.40000","1.40820","96.57462"
"466.80000","1.40873","96.02370"
"467.20000","1.40926","96.28860"
"467.60000","1.40980","96.40213"
"468.00000","1.41031","96.06154"
"468.40000","1.41083","96.67407"
"468.80000","1.41137","96.80784"
"469.20000","1.41191","96.81929"
"469.60000","1.41241","96.68903"
"470.00000","1.41293","96.92577"
"470.40000","1.41345","96.92753"
"470.80000","1.41400","97.22060"
"471.20000","1.41452","97.81904"
"471.60000","1.41503","97.71608"
"472.00000","1.41556","97.77681"
"472.40000","1.41609","97.72224"
"472.80000","1.41661","97.88417"
"473.20000","1.41713","97.77681"
"473.60000","1.41766","97.66239"
"474.00000","1.41819","97.74249"
"474.40000","1.41873","97.80848"
"474.80000","1.41923","98.05138"
"475.20000","1.41976","98.46238"
"475.60000","1.42028","98.43070"
"476.00000","1.42082","98.93057"
"476.40000","1.42134","98.46326"
"476.80000","1.42185","98.26084"
"477.20000","1.42239","98.76688"
"477.60000","1.42292","98.71496"
"478.00000","1.42344","99.19372"
"478.40000","1.42395","99.06611"
"478.80000","1.42449","99.34421"
"479.20000","1.42501","99.43222"
"479.60000","1.42553","99.64168"
"480.00000","1.42605","99.54223"
"480.40000","1.42658","99.11187"
"480.80000","1.42712","99.72529"
"481.20000","1.42764","99.74817"
"481.60000","1.42816","100.01307"
"482.00000","1.42869","99.83441"
"482.40000","1.42922","100.23397"
"482.80000","1.42974","100.18380"
"483.20000","1.43024","100.30261"
"483.60000","1.43078","100.21020"
"484.00000","1.43131","100.54463"
"484.40000","1.43184","100.59391"
"484.80000","1.43235","100.85969"
"485.20000","1.43287","101.11052"
"485.60000","1.43342","101.38334"
"486.00000","1.43395","100.91954"
"486.40000","1.43445","100.94594"
"486.80000","1.43498","101.13779"
"487.20000","1.43552","101.78113"
"487.60000","1.43604","101.75032"
"488.00000","1.43656","101.52063"
"488.40000","1.43708","101.97739"
"488.80000","1.43761","101.99763"
"489.20000","1.43815","101.62976"
"489.60000","1.43866","101.78730"
"490.00000","1.43917","102.40687"
"490.40000","1.43970","101.96947"
"490.80000","1.44025","102.25110"
"491.20000","1.44077","102.25373"
"491.60000","1.44127","102.57848"
"492.00000","1.44181","102.44823"
"492.40000","1.44234","103.00532"
"492.80000","1.44285","102.91555"
"493.20000","1.44338","103.18661"
"493.60000","1.44391","102.48871"
"494.00000","1.44443","103.48407"
"494.40000","1.44496","102.89971"
"494.80000","1.44547","103.51576"
"495.20000","1.44600","103.27814"
"495.60000","1.44654","103.76393"
"496.00000","1.44707","103.82466"
"496.40000","1.44759","103.92675"
"496.80000","1.44810","103.45591"
"497.20000","1.44864","103.67240"
"497.60000","1.44917","103.91003"
"498.00000","1.44968","104.14941"
"498.40000","1.45021","104.40375"
"498.80000","1.45073","104.40199"
"499.20000","1.45126","104.07020"
"499.60000","1.45179","104.19605"
"500.00000","1.45230","104.43631"
"500.40000","1.45282","104.65017"
"500.80000","1.45336","104.92299"
"501.20000","1.45389","104.87635"
"501.60000","1.45440","105.14653"
"502.00000","1.45493","104.84378"
"502.40000","1.45547","104.82970"
"502.80000","1.45599","105.09548"
"503.20000","1.45649","105.19581"
"503.60000","1.45703","105.66489"
"504.00000","1.45757","105.63673"
"504.40000","1.45808","105.72033"
"504.80000","1.45860","105.85674"
"505.20000","1.45913","106.23958"
"505.60000","1.45965","105.60241"
"506.00000","1.46019","106.62417"
"506.40000","1.46071","106.10669"
"506.80000","1.46122","106.01428"
"507.20000","1.46175","106.30382"
"507.60000","1.46228","106.31967"
"508.00000","1.46279","106.60305"
"508.40000","1.46332","106.98060"
"508.80000","1.46386","107.09589"
"509.20000","1.46440","106.33463"
"509.60000","1.46490","107.04572"
"510.00000","1.46542","107.16190"
"510.40000","1.46595","107.23935"
"510.80000","1.46648","107.16366"
"511.20000","1.46702","107.34759"
"511.60000","1.46753","108.05869"
"512.00000","1.46806","107.66970"
"512.40000","1.46858","107.15134"
"512.80000","1.46911","107.45232"
"513.20000","1.46963","107.62041"
"513.60000","1.47015","107.88708"
"514.00000","1.47069","108.03317"
"514.40000","1.47122","107.94340"
"514.80000","1.47173","107.99972"
"515.20000","1.47226","108.38872"
"515.60000","1.47279","108.38783"
"516.00000","1.47332","108.85956"
"516.40000","1.47383","108.66065"
"516.80000","1.47435","108.40808"
"517.20000","1.47489","108.62281"
"517.60000","1.47541","109.01005"
"518.00000","1.47593","109.17023"
"518.40000","1.47646","109.18782"
"518.80000","1.47698","109.35152"
"519.20000","1.47751","109.33656"
"519.60000","1.47803","109.77395"
"520.00000","1.47853","109.55217"
"520.40000","1.47908","109.41928"
"520.80000","1.47962","110.08990"
"521.20000","1.48014","109.68154"
"521.60000","1.48065","110.09694"
"522.00000","1.48118","109.95173"
"522.40000","1.48171","110.29495"
"522.80000","1.48223","110.27647"
"523.20000","1.48274","110.43312"
"523.60000","1.48328","110.78516"
"524.00000","1.48381","110.72443"
"524.40000","1.48434","111.06855"
"524.80000","1.48485","110.55633"
"525.20000","1.48537","111.27360"
"525.60000","1.48591","110.91453"
"526.00000","1.48644","111.42409"
"526.40000","1.48696","111.18647"
"526.80000","1.48747","111.33169"
"527.20000","1.48800","111.68195"
"527.60000","1.48853","111.42321"
"528.00000","1.48905","111.60715"
"528.40000","1.48957","111.56841"
"528.80000","1.49011","111.94949"
"529.20000","1.49063","112.37809"
"529.60000","1.49116","112.37896"
"530.00000","1.49168","111.91781"
"530.40000","1.49219","112.29449"
"530.80000","1.49274","112.69579"
"531.20000","1.49326","112.47401"
"531.60000","1.49376","112.79085"
"532.00000","1.49430","113.01350"
"532.40000","1.49483","113.09887"
"532.80000","1.49535","112.81461"
"533.20000","1.49587","112.77852"
"533.60000","1.49640","112.93606"
"534.00000","1.49694","113.10768"
"534.40000","1.49747","113.11559"
"534.80000","1.49797","113.22823"
"535.20000","1.49850","113.26697"
"535.60000","1.49902","113.18599"
"536.00000","1.49955","113.62866"
"536.40000","1.50008","113.91645"
"536.80000","1.50059","113.86893"
"537.20000","1.50113","114.03967"
"537.60000","1.50166","113.93229"
"538.00000","1.50218","114.28696"
"538.40000","1.50269","114.16464"
"538.80000","1.50322","114.69356"
"539.20000","1.50376","114.78157"
"539.60000","1.50427","114.58532"
"540.00000","1.50478","114.67156"
"540.40000","1.50533","114.94262"
"540.80000","1.50587","115.21633"
"541.20000","1.50638","114.80884"
"541.60000","1.50690","114.88805"
"542.00000","1.50741","115.44074"
"542.40000","1.50794","115.17936"
"542.80000","1.50848","115.61147"
"543.20000","1.50898","115.72765"
"543.60000","1.50952","116.02424"
"544.00000","1.51006","115.57187"
"544.40000","1.51059","115.98022"
"544.80000","1.51109","115.93621"
"545.20000","1.51162","115.76460"
"545.60000","1.51216","116.46339"
"546.00000","1.51269","116.62620"
"546.40000","1.51319","116.60156"
"546.80000","1.51372","116.72125"
"547.20000","1.51425","116.62003"
"547.60000","1.51477","116.86206"
"548.00000","1.51530","116.83918"
"548.40000","1.51582","117.25105"
"548.80000","1.51635","116.90869"
"549.20000","1.51689","117.37162"
"549.60000","1.51740","117.38042"
"550.00000","1.51791","116.93774"
"550.40000","1.51844","117.38921"
"550.80000","1.51898","117.62157"
"551.20000","1.51951","117.38921"
"551.60000","1.52001","117.85477"
"552.00000","1.52055","117.93662"
"552.40000","1.52108","117.99823"
"552.80000","1.52159","118.01231"
"553.20000","1.52212","118.29745"
"553.60000","1.52265","118.38546"
"554.00000","1.52318","118.18743"
"554.40000","1.52371","118.41891"
"554.80000","1.52422","118.32562"
"555.20000","1.52474","118.59932"
"555.60000","1.52528","118.60988"
"556.00000","1.52580","118.90647"
"556.40000","1.52633","118.99888"
"556.80000","1.52684","119.08600"
"557.20000","1.52738","118.91615"
"557.60000","1.52791","119.62988"
"558.00000","1.52842","119.14848"
"558.40000","1.52894","119.23386"
"558.80000","1.52947","119.34387"
"559.20000","1.53000","120.06815"
"559.60000","1.53052","120.01975"
"560.00000","1.53104","119.81734"
"560.40000","1.53156","119.73726"
"560.80000","1.53210","119.92646"
"561.20000","1.53263","120.29522"
"561.60000","1.53315","119.60084"
"562.00000","1.53367","119.83055"
"562.40000","1.53420","120.20809"
"562.80000","1.53473","120.42723"
"563.20000","1.53524","120.31634"
"563.60000","1.53578","120.87167"
"564.00000","1.53631","120.71325"
"564.40000","1.53682","120.87256"
"564.80000","1.53734","121.02920"
"565.20000","1.53786","121.19377"
"565.60000","1.53839","121.16209"
"566.00000","1.53893","121.44460"
"566.40000","1.53944","121.23953"
"566.80000","1.53996","121.39178"
"567.20000","1.54049","121.32666"
"567.60000","1.54103","121.56780"
"568.00000","1.54155","121.86614"
"568.40000","1.54206","121.55899"
"568.80000","1.54260","122.27802"
"569.20000","1.54313","122.07208"
"569.60000","1.54364","122.75327"
"570.00000","1.54416","122.76735"
"570.40000","1.54469","122.68902"
"570.80000","1.54523","122.54116"
"571.20000","1.54575","122.85887"
"571.60000","1.54627","122.77262"
"572.00000","1.54680","122.53500"
"572.40000","1.54732","122.62390"
"572.80000","1.54784","122.96096"
"573.20000","1.54835","123.35523"
"573.60000","1.54889","123.06745"
"574.00000","1.54943","123.22410"
"574.40000","1.54996","123.33939"
"574.80000","1.55046","123.31826"
"575.20000","1.55099","124.05664"
"575.60000","1.55153","124.28723"
"576.00000","1.55204","124.17635"
"576.40000","1.55257","124.07072"
"576.80000","1.55309","124.27931"
"577.20000","1.55363","124.28019"
"577.60000","1.55415","124.40780"
"578.00000","1.55467","124.49932"
"578.40000","1.55519","124.97632"
"578.80000","1.55572","124.70703"
"579.20000","1.55625","124.81615"
"579.60000","1.55677","125.27731"
"580.00000","1.55727","125.13563"
"580.40000","1.55781","125.23243"
"580.80000","1.55835","125.42429"
"581.20000","1.55888","125.09513"
"581.60000","1.55939","125.57741"
"582.00000","1.55992","125.61439"
"582.40000","1.56045","125.56509"
"582.80000","1.56097","125.51406"
"583.20000","1.56149","125.80887"
"583.60000","1.56203","125.99721"
"584.00000","1.56255","125.97081"
"584.40000","1.56308","126.37476"
"584.80000","1.56360","126.47948"
"585.20000","1.56411","126.11425"
"585.60000","1.56464","126.43460"
"586.00000","1.56518","126.49972"
"586.40000","1.56568","126.68455"
"586.80000","1.56621","126.57014"
"587.20000","1.56675","126.65023"
"587.60000","1.56728","126.88256"
"588.00000","1.56779","127.29003"
"588.40000","1.56832","126.78751"
"588.80000","1.56885","127.31116"
"589.20000","1.56937","127.15011"
"589.60000","1.56989","127.37540"
"590.00000","1.57041","127.62798"
"590.40000","1.57093","127.44141"
"590.80000","1.57148","128.07066"
"591.20000","1.57200","127.98530"
"591.60000","1.57252","127.99586"
"592.00000","1.57304","127.77144"
"592.40000","1.57357","128.29859"
"592.80000","1.57410","128.64095"
"593.20000","1.57461","128.71136"
"593.60000","1.57513","128.61542"
"594.00000","1.57567","128.40949"
"594.40000","1.57619","128.38660"
"594.80000","1.57670","129.04930"
"595.20000","1.57724","128.94368"
"595.60000","1.57776","128.87504"
"596.00000","1.57830","129.13994"
"596.40000","1.57882","128.81432"
"596.77200","1.57930","129.20420"