File: DataAnalyzer/TestFiles/Specimen_RawData_4.csv
Specimen properties : Specimen label,"orgn_80_NA_2_wblk_3ptbnd_run4"
Maximum Load : Flexure extension at Maximum Load,"1.60063",in
Maximum Load : Maximum Load,"133.21203",lbf

Time,Extension,Load
(s),(in),(lbf)
"0.00000","0.83231","15.03240"
"0.40000","0.83314","15.50147"
"0.80000","0.83336","15.08432"
"1.20000","0.83384","15.24097"
"1.60000","0.83437","14.81238"
"2.00000","0.83488","14.87486"
"2.40000","0.83540","14.94703"
"2.80000","0.83594","15.45835"
"3.20000","0.83646","14.90126"
"3.60000","0.83699","15.51643"
"4.00000","0.83751","14.79741"
"4.40000","0.83802","15.02624"
"4.80000","0.83857","14.91887"
"5.20000","0.83910","15.16177"
"5.60000","0.83961","15.25945"
"6.00000","0.84014","15.27089"
"6.40000","0.84067","15.27177"
"6.80000","0.84120","15.81654"
"7.20000","0.84170","15.25065"
"7.60000","0.84223","15.84822"
"8.00000","0.84277","15.51643"
"8.40000","0.84329","15.70565"
"8.80000","0.84381","15.65109"
"9.20000","0.84433","15.38266"
"9.60000","0.84485","15.41259"
"10.00000","0.84539","15.91247"
"10.40000","0.84592","15.63965"
"10.80000","0.84642","15.84118"
"11.20000","0.84696","16.39299"
"11.60000","0.84749","15.75141"
"12.00000","0.84802","16.11752"
"12.40000","0.84853","16.26890"
"12.80000","0.84906","16.23633"
"13.20000","0.84960","16.23809"
"13.60000","0.85011","16.31378"
"14.00000","0.85062","16.47483"
"14.40000","0.85116","16.24073"
"14.80000","0.85169","16.56020"
"15.20000","0.85222","16.49947"
"15.60000","0.85274","16.67725"
"16.00000","0.85325","16.90607"
"16.40000","0.85379","16.85502"
"16.80000","0.85431","16.85238"
"17.20000","0.85482","16.97383"
"17.60000","0.85536","17.20089"
"18.00000","0.85588","17.14369"
"18.40000","0.85643","17.22730"
"18.80000","0.85693","17.18065"
"19.20000","0.85745","16.95359"
"19.60000","0.85799","17.01872"
"20.00000","0.85851","17.16305"
"20.40000","0.85904","17.02752"
"20.80000","0.85956","17.07856"
"21.20000","0.86008","17.67173"
"21.60000","0.86061","17.55644"
"22.00000","0.86114","17.19825"
"22.40000","0.86164","17.24490"
"22.80000","0.86217","17.29946"
"23.20000","0.86271","18.22706"
"23.60000","0.86325","17.81166"
"24.00000","0.86375","18.14697"
"24.40000","0.86428","17.92431"
"24.80000","0.86483","17.97976"
"25.20000","0.86533","17.98064"
"25.60000","0.86586","18.09857"
"26.00000","0.86639","17.90583"
"26.40000","0.86692","18.18658"
"26.80000","0.86744","17.82839"
"27.20000","0.86795","18.26490"
"27.60000","0.86847","18.17249"
"28.00000","0.86901","18.53332"
"28.40000","0.86954","18.08009"
"28.80000","0.87007","18.75950"
"29.20000","0.87058","18.69086"
"29.60000","0.87110","18.36875"
"30.00000","0.87164","18.74190"
"30.40000","0.87217","18.71902"
"30.80000","0.87268","18.88623"
"31.20000","0.87322","19.06049"
"31.60000","0.87375","18.91175"
"32.00000","0.87426","18.93640"
"32.40000","0.87477","18.93992"
"32.80000","0.87531","19.46884"
"33.20000","0.87584","19.26554"
"33.60000","0.87636","19.12297"
"34.00000","0.87688","19.01824"
"34.40000","0.87740","19.53661"
"34.80000","0.87794","19.43804"
"35.20000","0.87847","19.48820"
"35.60000","0.87898","19.08865"
"36.00000","0.87950","19.43980"
"36.40000","0.88004","19.68886"
"36.80000","0.88057","19.43100"
"37.20000","0.88107","19.68534"
"37.60000","0.88160","19.68182"
"38.00000","0.88214","20.09105"
"38.40000","0.88267","19.67654"
"38.80000","0.88318","19.85871"
"39.20000","0.88370","19.93880"
"39.60000","0.88423","20.04881"
"40.00000","0.88476","20.19930"
"40.40000","0.88529","20.66662"
"40.80000","0.88580","20.13505"
"41.20000","0.88633","20.38236"
"41.60000","0.88687","20.60061"
"42.00000","0.88739","20.59885"
"42.40000","0.88789","20.31195"
"42.80000","0.88843","20.19314"
"43.20000","0.88897","20.04881"
"43.60000","0.88949","20.94560"
"44.00000","0.89000","20.64550"
"44.40000","0.89053","21.01249"
"44.80000","0.89106","20.74934"
"45.20000","0.89158","20.83823"
"45.60000","0.89211","20.80215"
"46.00000","0.89264","20.84527"
"46.40000","0.89316","20.95528"
"46.80000","0.89369","21.50621"
"47.20000","0.89419","20.98256"
"47.60000","0.89472","20.99577"
"48.00000","0.89527","20.99665"
"48.40000","0.89580","21.13746"
"48.80000","0.89631","21.22986"
"49.20000","0.89683","21.38652"
"49.60000","0.89736","21.68134"
"50.00000","0.89788","21.26507"
"50.40000","0.89841","21.42788"
"50.80000","0.89893","21.46308"
"51.20000","0.89945","21.39884"
"51.60000","0.89998","21.77551"
"52.00000","0.90051","21.80719"
"52.40000","0.90101","21.61974"
"52.80000","0.90154","22.15482"
"53.20000","0.90209","21.61710"
"53.60000","0.90261","21.89696"
"54.00000","0.90312","22.29915"
"54.40000","0.90365","22.43116"
"54.80000","0.90418","22.36692"
"55.20000","0.90472","22.41004"
"55.60000","0.90523","22.27539"
"56.00000","0.90576","22.30795"
"56.40000","0.90629","22.50333"
"56.80000","0.90681","22.65030"
"57.20000","0.90733","22.49893"
"57.60000","0.90784","22.28067"
"58.00000","0.90838","22.93456"
"58.40000","0.90892","22.96009"
"58.80000","0.90943","22.63974"
"59.20000","0.90994","22.97769"
"59.60000","0.91048","23.34732"
"60.00000","0.91101","22.93281"
"60.40000","0.91154","22.98561"
"60.80000","0.91205","22.89848"
"61.20000","0.91258","23.34644"
"61.60000","0.91312","23.63422"
"62.00000","0.91363","23.33588"
"62.40000","0.91415","23.45381"
"62.80000","0.91468","23.33148"
"63.20000","0.91521","23.54973"
"63.60000","0.91574","23.26899"
"64.00000","0.91626","23.45821"
"64.40000","0.91677","23.43621"
"64.80000","0.91731","23.46701"
"65.20000","0.91783","23.41772"
"65.60000","0.91835","23.63070"
"66.00000","0.91887","23.83664"
"66.40000","0.91940","23.99593"
"66.80000","0.91994","23.67735"
"67.20000","0.92044","24.12178"
"67.60000","0.92097","23.85864"
"68.00000","0.92151","24.05490"
"68.40000","0.92205","24.14291"
"68.80000","0.92255","24.09450"
"69.20000","0.92308","24.37700"
"69.60000","0.92360","24.20187"
"70.00000","0.92414","24.33740"
"70.40000","0.92466","24.57414"
"70.80000","0.92517","24.44213"
"71.20000","0.92570","24.69823"
"71.60000","0.92623","24.60934"
"72.00000","0.92676","24.64102"
"72.40000","0.92727","24.97985"
"72.80000","0.92780","24.80648"
"73.20000","0.92834","24.43421"
"73.60000","0.92886","25.21483"
"74.00000","0.92937","24.91033"
"74.40000","0.92990","25.15587"
"74.80000","0.93044","24.81880"
"75.20000","0.93096","24.93585"
"75.60000","0.93148","25.34948"
"76.00000","0.93199","25.62406"
"76.40000","0.93253","25.30372"
"76.80000","0.93306","25.39437"
"77.20000","0.93358","25.44189"
"77.60000","0.93410","25.25004"
"78.00000","0.93463","25.53782"
"78.40000","0.93517","26.01306"
"78.80000","0.93568","25.84496"
"79.20000","0.93619","25.49029"
"79.60000","0.93673","25.34684"
"80.00000","0.93725","25.64959"
"80.40000","0.93778","26.00162"
"80.80000","0.93830","25.89249"
"81.20000","0.93882","25.97169"
"81.60000","0.93936","26.08170"
"82.00000","0.93988","26.33165"
"82.40000","0.94038","26.01306"
"82.80000","0.94092","26.20315"
"83.20000","0.94145","26.28236"
"83.60000","0.94199","26.47862"
"84.00000","0.94249","26.44957"
"84.40000","0.94302","26.30436"
"84.80000","0.94356","26.90193"
"85.20000","0.94409","26.39677"
"85.60000","0.94460","26.78488"
"86.00000","0.94513","26.86409"
"86.40000","0.94566","26.58862"
"86.80000","0.94618","27.02426"
"87.20000","0.94670","26.36861"
"87.60000","0.94722","26.83505"
"88.00000","0.94775","27.66231"
"88.40000","0.94828","27.00842"
"88.80000","0.94881","27.02514"
"89.20000","0.94931","27.01458"
"89.60000","0.94984","27.53118"
"90.00000","0.95039","26.99610"
"90.40000","0.95091","27.62271"
"90.80000","0.95142","27.20556"
"91.20000","0.95196","27.41941"
"91.60000","0.95248","27.72744"
"92.00000","0.95300","27.29445"
"92.40000","0.95351","27.64735"
"92.80000","0.95405","27.18179"
"93.20000","0.95458","27.64823"
"93.60000","0.95511","27.64295"
"94.00000","0.95562","27.83041"
"94.40000","0.95614","28.10675"
"94.80000","0.95667","27.99850"
"95.20000","0.95720","28.18948"
"95.60000","0.95771","28.28188"
"96.00000","0.95824","28.05043"
"96.40000","0.95878","28.07507"
"96.80000","0.95931","28.10411"
"97.20000","0.95981","28.55031"
"97.60000","0.96035","28.66648"
"98.00000","0.96088","28.40333"
"98.40000","0.96142","28.61103"
"98.80000","0.96192","28.45438"
"99.20000","0.96244","28.73600"
"99.60000","0.96297","28.37429"
"100.00000","0.96350","28.76240"
"100.40000","0.96403","28.85833"
"100.80000","0.96454","28.71224"
"101.20000","0.96507","28.78617"
"101.60000","0.96561","28.87241"
"102.00000","0.96613","29.04931"
"102.40000","0.96663","28.93666"
"102.80000","0.96718","29.17692"
"103.20000","0.96771","29.09771"
"103.60000","0.96823","29.02994"
"104.00000","0.96875","29.41718"
"104.40000","0.96927","29.12939"
"104.80000","0.96981","29.37934"
"105.20000","0.97033","29.44710"
"105.60000","0.97085","29.62048"
"106.00000","0.97138","29.36790"
"106.40000","0.97190","29.47086"
"106.80000","0.97243","29.59143"
"107.20000","0.97295","30.10364"
"107.60000","0.97346","29.86866"
"108.00000","0.97401","29.50606"
"108.40000","0.97453","29.83610"
"108.80000","0.97504","30.15468"
"109.20000","0.97556","29.58263"
"109.60000","0.97609","30.17580"
"110.00000","0.97662","29.69616"
"110.40000","0.97715","30.14852"
"110.80000","0.97767","30.25237"
"111.20000","0.97820","30.56655"
"111.60000","0.97872","30.86930"
"112.00000","0.97925","30.68624"
"112.40000","0.97977","30.62640"
"112.80000","0.98029","30.94410"
"113.20000","0.98083","30.86138"
"113.60000","0.98135","31.12716"
"114.00000","0.98186","30.78921"
"114.40000","0.98239","31.30493"
"114.80000","0.98293","31.37358"
"115.20000","0.98346","30.75401"
"115.60000","0.98397","31.01275"
"116.00000","0.98450","31.46159"
"116.40000","0.98503","31.39382"
"116.80000","0.98555","31.33486"
"117.20000","0.98607","31.23893"
"117.60000","0.98659","31.02859"
"118.00000","0.98711","31.31285"
"118.40000","0.98766","31.43518"
"118.80000","0.98817","31.55224"
"119.20000","0.98868","31.09459"
"119.60000","0.98922","31.74761"
"120.00000","0.98975","31.88490"
"120.40000","0.99028","31.69744"
"120.80000","0.99079","31.93594"
"121.20000","0.99132","32.09964"
"121.60000","0.99186","32.13132"
"122.00000","0.99237","31.76521"
"122.40000","0.99288","32.26333"
"122.80000","0.99342","32.16564"
"123.20000","0.99395","32.54143"
"123.60000","0.99448","32.36190"
"124.00000","0.99499","32.16564"
"124.40000","0.99550","32.51152"
"124.80000","0.99605","32.60656"
"125.20000","0.99657","32.76585"
"125.60000","0.99708","32.65144"
"126.00000","0.99762","32.81426"
"126.40000","0.99815","32.61096"
"126.80000","0.99868","33.12668"
"127.20000","0.99919","32.80370"
"127.60000","0.99972","33.14164"
"128.00000","1.00026","32.93483"
"128.40000","1.00079","33.22613"
"128.80000","1.00130","32.90403"
"129.20000","1.00182","32.98675"
"129.60000","1.00234","33.48751"
"130.00000","1.00287","33.34142"
"130.40000","1.00340","33.35022"
"130.80000","1.00391","33.51479"
"131.20000","1.00444","33.00875"
"131.60000","1.00497","33.57200"
"132.00000","1.00550","33.60456"
"132.40000","1.00600","34.01292"
"132.80000","1.00654","33.76914"
"133.20000","1.00708","33.34318"
"133.60000","1.00760","33.95395"
"134.00000","1.00811","33.81050"
"134.40000","1.00864","33.73745"
"134.80000","1.00918","33.60984"
"135.20000","1.00970","33.98387"
"135.60000","1.01022","34.25054"
"136.00000","1.01073","33.87827"
"136.40000","1.01127","34.56296"
"136.80000","1.01180","34.41687"
"137.20000","1.01230","34.20565"
"137.60000","1.01283","34.32534"
"138.00000","1.01336","34.44415"
"138.40000","1.01390","34.44855"
"138.80000","1.01441","34.43359"
"139.20000","1.01493","34.40279"
"139.60000","1.01547","34.48992"
"140.00000","1.01599","34.80762"
"140.40000","1.01652","34.45471"
"140.80000","1.01705","34.79442"
"141.20000","1.01758","34.83050"
"141.60000","1.01810","34.97571"
"142.00000","1.01862","35.13501"
"142.40000","1.01914","35.36647"
"142.80000","1.01966","35.54776"
"143.20000","1.02020","35.30838"
"143.60000","1.02073","35.34975"
"144.00000","1.02124","35.79682"
"144.40000","1.02176","35.01092"
"144.80000","1.02230","35.44391"
"145.20000","1.02281","35.56536"
"145.60000","1.02334","35.69209"
"146.00000","1.02387","35.82235"
"146.40000","1.02440","35.39639"
"146.80000","1.02493","35.73610"
"147.20000","1.02544","35.64809"
"147.60000","1.02596","36.17525"
"148.00000","1.02650","36.04236"
"148.40000","1.02703","35.74754"
"148.80000","1.02755","35.97020"
"149.20000","1.02806","35.96316"
"149.60000","1.02858","36.34071"
"150.00000","1.02912","36.31342"
"150.40000","1.02963","36.33719"
"150.80000","1.03016","36.30903"
"151.20000","1.03070","36.52464"
"151.60000","1.03122","36.70770"
"152.00000","1.03174","37.02188"
"152.40000","1.03226","37.01044"
"152.80000","1.03277","36.62321"
"153.20000","1.03332","36.97348"
"153.60000","1.03385","36.92507"
"154.00000","1.03437","36.90836"
"154.40000","1.03489","36.88371"
"154.80000","1.03542","36.90923"
"155.20000","1.03595","37.32023"
"155.60000","1.03647","37.55345"
"156.00000","1.03699","37.30263"
"156.40000","1.03752","37.37215"
"156.80000","1.03805","37.83419"
"157.20000","1.03855","37.74530"
"157.60000","1.03908","37.39063"
"158.00000","1.03962","37.75146"
"158.40000","1.04016","38.13342"
"158.80000","1.04067","37.79987"
"159.20000","1.04118","37.93276"
"159.60000","1.04171","38.05157"
"160.00000","1.04224","38.37807"
"160.40000","1.04277","37.91516"
"160.80000","1.04328","38.18006"
"161.20000","1.04381","37.99525"
"161.60000","1.04435","38.05949"
"162.00000","1.04487","38.79435"
"162.40000","1.04537","38.48896"
"162.80000","1.04591","38.39128"
"163.20000","1.04645","38.37279"
"163.60000","1.04697","38.55409"
"164.00000","1.04748","39.03021"
"164.40000","1.04801","38.80051"
"164.80000","1.04855","38.80227"
"165.20000","1.04907","39.35584"
"165.60000","1.04958","39.26431"
"166.00000","1.05010","39.04869"
"166.40000","1.05063","39.43768"
"166.80000","1.05117","39.35232"
"167.20000","1.05169","39.46672"
"167.60000","1.05220","39.59609"
"168.00000","1.05274","39.24055"
"168.40000","1.05327","39.64274"
"168.80000","1.05379","39.80115"
"169.20000","1.05431","39.60842"
"169.60000","1.05483","39.77915"
"170.00000","1.05538","40.11886"
"170.40000","1.05589","40.03437"
"170.80000","1.05641","40.12326"
"171.20000","1.05695","40.19279"
"171.60000","1.05747","40.17342"
"172.00000","1.05799","40.54041"
"172.40000","1.05851","39.91908"
"172.80000","1.05902","39.90676"
"173.20000","1.05957","40.50961"
"173.60000","1.06010","40.28607"
"174.00000","1.06060","40.58002"
"174.40000","1.06114","40.57122"
"174.80000","1.06167","40.71467"
"175.20000","1.06220","40.62842"
"175.60000","1.06271","40.91884"
"176.00000","1.06324","40.94965"
"176.40000","1.06378","41.00333"
"176.80000","1.06429","40.64690"
"177.20000","1.06481","41.27880"
"177.60000","1.06533","41.29287"
"178.00000","1.06586","41.10630"
"178.40000","1.06640","41.33248"
"178.80000","1.06692","41.16174"
"179.20000","1.06742","41.37648"
"179.60000","1.06796","41.27880"
"180.00000","1.06848","41.41873"
"180.40000","1.06902","41.37472"
"180.80000","1.06953","41.82444"
"181.20000","1.07006","41.73467"
"181.60000","1.07060","41.88076"
"182.00000","1.07111","42.00749"
"182.40000","1.07162","41.99693"
"182.80000","1.07216","42.12806"
"183.20000","1.07269","41.99517"
"183.60000","1.07322","42.01101"
"184.00000","1.07374","42.42113"
"184.40000","1.07425","42.32168"
"184.80000","1.07479","42.10871"
"185.20000","1.07531","42.40265"
"185.60000","1.07582","42.36920"
"186.00000","1.07636","42.54786"
"186.40000","1.07689","42.52850"
"186.80000","1.07742","42.89901"
"187.20000","1.07793","42.59979"
"187.60000","1.07845","42.61123"
"188.00000","1.07900","43.11198"
"188.40000","1.07953","43.21759"
"188.80000","1.08003","43.03542"
"189.20000","1.08056","42.93245"
"189.60000","1.08108","42.73003"
"190.00000","1.08162","43.07590"
"190.40000","1.08214","43.15775"
"190.80000","1.08265","43.09350"
"191.20000","1.08318","43.22111"
"191.60000","1.08371","43.41649"
"192.00000","1.08424","43.67699"
"192.40000","1.08475","43.38657"
"192.80000","1.08528","43.86533"
"193.20000","1.08583","43.75884"
"193.60000","1.08635","44.03078"
"194.00000","1.08685","43.92253"
"194.40000","1.08738","43.93485"
"194.80000","1.08790","44.07038"
"195.20000","1.08843","43.86357"
"195.60000","1.08895","44.23056"
"196.00000","1.08947","44.26048"
"196.40000","1.09001","44.04662"
"196.80000","1.09054","44.35641"
"197.20000","1.09104","44.47698"
"197.60000","1.09157","44.41273"
"198.00000","1.09211","44.11527"
"198.40000","1.09265","44.61603"
"198.80000","1.09316","44.49986"
"199.20000","1.09367","44.77972"
"199.60000","1.09421","44.82021"
"200.00000","1.09473","44.90557"
"200.40000","1.09526","44.98918"
"200.80000","1.09578","45.13263"
"201.20000","1.09631","45.26640"
"201.60000","1.09684","45.07807"
"202.00000","1.09736","45.01118"
"202.40000","1.09786","45.53131"
"202.80000","1.09840","45.48378"
"203.20000","1.09894","45.11327"
"203.60000","1.09947","45.63603"
"204.00000","1.09997","45.53394"
"204.40000","1.10049","45.58147"
"204.80000","1.10104","45.95022"
"205.20000","1.10155","45.95110"
"205.60000","1.10208","45.82965"
"206.00000","1.10261","46.25648"
"206.40000","1.10314","46.04790"
"206.80000","1.10366","45.98542"
"207.20000","1.10418","46.09719"
"207.60000","1.10470","46.20984"
"208.00000","1.10523","46.13591"
"208.40000","1.10576","46.54603"
"208.80000","1.10629","46.52402"
"209.20000","1.10679","46.16144"
"209.60000","1.10732","46.37705"
"210.00000","1.10786","46.47474"
"210.40000","1.10839","46.34449"
"210.80000","1.10890","46.53019"
"211.20000","1.10943","46.79949"
"211.60000","1.10996","46.69212"
"212.00000","1.11048","47.28793"
"212.40000","1.11099","46.69036"
"212.80000","1.11153","46.92006"
"213.20000","1.11206","46.64195"
"213.60000","1.11259","47.05823"
"214.00000","1.11310","47.00102"
"214.40000","1.11363","47.63292"
"214.80000","1.11415","46.98430"
"215.20000","1.11469","47.45514"
"215.60000","1.11521","47.51587"
"216.00000","1.11572","47.30201"
"216.40000","1.11626","47.74645"
"216.80000","1.11678","47.68660"
"217.20000","1.11729","47.24569"
"217.60000","1.11782","47.91982"
"218.00000","1.11835","47.92246"
"218.40000","1.11890","47.83973"
"218.80000","1.11941","48.22432"
"219.20000","1.11992","47.89166"
"219.60000","1.12045","48.62124"
"220.00000","1.12098","48.61860"
"220.40000","1.12151","48.72156"
"220.80000","1.12202","48.10903"
"221.20000","1.12255","48.79197"
"221.60000","1.12309","48.56403"
"222.00000","1.12361","48.26921"
"222.40000","1.12411","48.60452"
"222.80000","1.12465","48.86326"
"223.20000","1.12518","49.13872"
"223.60000","1.12570","49.42122"
"224.00000","1.12622","49.03575"
"224.40000","1.12674","49.04895"
"224.80000","1.12729","49.44323"
"225.20000","1.12780","49.27865"
"225.60000","1.12832","49.44147"
"226.00000","1.12884","49.54355"
"226.40000","1.12938","49.68788"
"226.80000","1.12992","49.88414"
"227.20000","1.13041","49.94223"
"227.60000","1.13094","49.75301"
"228.00000","1.13149","50.02847"
"228.40000","1.13202","49.99943"
"228.80000","1.13252","50.07424"
"229.20000","1.13305","49.77237"
"229.60000","1.13358","49.94046"
"230.00000","1.13412","50.30570"
"230.40000","1.13463","49.86918"
"230.80000","1.13514","50.13057"
"231.20000","1.13568","50.13848"
"231.60000","1.13620","50.05576"
"232.00000","1.13673","50.95167"
"232.40000","1.13725","50.78622"
"232.80000","1.13777","50.27490"
"233.20000","1.13831","50.75893"
"233.60000","1.13884","50.91823"
"234.00000","1.13934","50.56267"
"234.40000","1.13987","51.30282"
"234.80000","1.14041","51.04496"
"235.20000","1.14094","50.83462"
"235.60000","1.14145","50.76774"
"236.00000","1.14197","50.74661"
"236.40000","1.14251","51.32834"
"236.80000","1.14302","51.20513"
"237.20000","1.14354","51.25706"
"237.60000","1.14407","51.22449"
"238.00000","1.14459","51.58268"
"238.40000","1.14513","51.30458"
"238.80000","1.14565","51.25882"
"239.20000","1.14616","51.59412"
"239.60000","1.14670","51.46475"
"240.00000","1.14723","51.61084"
"240.40000","1.14776","51.53692"
"240.80000","1.14827","52.12041"
"241.20000","1.14880","51.90919"
"241.60000","1.14934","51.99104"
"242.00000","1.14985","51.73493"
"242.40000","1.15036","52.19697"
"242.80000","1.15090","51.75870"
"243.20000","1.15143","52.30434"
"243.60000","1.15196","52.06056"
"244.00000","1.15248","52.12304"
"244.40000","1.15299","52.54372"
"244.80000","1.15353","52.73206"
"245.20000","1.15405","52.54020"
"245.60000","1.15458","52.72590"
"246.00000","1.15510","52.60268"
"246.40000","1.15562","52.46539"
"246.80000","1.15616","53.28034"
"247.20000","1.15666","52.36771"
"247.60000","1.15720","52.81390"
"248.00000","1.15774","53.31378"
"248.40000","1.15827","53.03480"
"248.80000","1.15877","53.46076"
"249.20000","1.15930","53.30674"
"249.60000","1.15982","53.14657"
"250.00000","1.16036","52.98112"
"250.40000","1.16088","53.26450"
"250.80000","1.16139","53.32698"
"251.20000","1.16192","53.43611"
"251.60000","1.16245","54.45612"
"252.00000","1.16297","53.79958"
"252.40000","1.16348","53.84183"
"252.80000","1.16401","53.64029"
"253.20000","1.16456","53.97736"
"253.60000","1.16507","53.98880"
"254.00000","1.16559","53.78198"
"254.40000","1.16612","53.84183"
"254.80000","1.16666","53.66229"
"255.20000","1.16718","54.13753"
"255.60000","1.16770","54.49924"
"256.00000","1.16821","54.36019"
"256.40000","1.16875","54.37779"
"256.80000","1.16928","54.09881"
"257.20000","1.16980","54.38571"
"257.60000","1.17032","53.98000"
"258.00000","1.17085","55.01937"
"258.40000","1.17139","54.91552"
"258.80000","1.17190","54.94808"
"259.20000","1.17241","55.18218"
"259.60000","1.17295","54.88648"
"260.00000","1.17348","54.81518"
"260.40000","1.17400","55.16898"
"260.80000","1.17452","55.39252"
"261.20000","1.17505","55.15138"
"261.60000","1.17558","55.18130"
"262.00000","1.17610","55.03608"
"262.40000","1.17660","55.39692"
"262.80000","1.17714","55.53773"
"263.20000","1.17768","55.43300"
"263.60000","1.17821","55.63190"
"264.00000","1.17871","55.71639"
"264.40000","1.17924","56.25058"
"264.80000","1.17978","56.08425"
"265.20000","1.18031","55.71726"
"265.60000","1.18082","56.09129"
"266.00000","1.18134","56.01737"
"266.40000","1.18187","56.38964"
"266.80000","1.18239","55.69086"
"267.20000","1.18291","56.18634"
"267.60000","1.18344","56.60613"
"268.00000","1.18397","56.32451"
"268.40000","1.18450","56.87104"
"268.80000","1.18503","56.57621"
"269.20000","1.18553","56.49437"
"269.60000","1.18607","56.84023"
"270.00000","1.18661","56.37908"
"270.40000","1.18713","56.54101"
"270.80000","1.18764","56.40020"
"271.20000","1.18817","56.61054"
"271.60000","1.18870","56.81471"
"272.00000","1.18922","56.90272"
"272.40000","1.18973","57.06554"
"272.80000","1.19027","57.47125"
"273.20000","1.19080","57.36564"
"273.60000","1.19133","57.56981"
"274.00000","1.19185","57.75375"
"274.40000","1.19236","57.94648"
"274.80000","1.19289","58.08554"
"275.20000","1.19343","57.93065"
"275.60000","1.19395","58.11986"
"276.00000","1.19446","58.03801"
"276.40000","1.19500","58.29940"
"276.80000","1.19554","58.10402"
"277.20000","1.19603","58.43053"
"277.60000","1.19657","58.30907"
"278.00000","1.19709","58.22195"
"278.40000","1.19764","58.41469"
"278.80000","1.19815","58.75879"
"279.20000","1.19866","58.40060"
"279.60000","1.19919","59.31764"
"280.00000","1.19971","58.84152"
"280.40000","1.20025","59.17859"
"280.80000","1.20077","59.19971"
"281.20000","1.20129","59.19267"
"281.60000","1.20183","59.70487"
"282.00000","1.20235","59.47517"
"282.40000","1.20285","59.26748"
"282.80000","1.20339","59.49453"
"283.20000","1.20393","59.23140"
"283.60000","1.20446","59.56494"
"284.00000","1.20496","59.76648"
"284.40000","1.20548","59.95921"
"284.80000","1.20601","59.92137"
"285.20000","1.20654","59.59046"
"285.60000","1.20706","59.51654"
"286.00000","1.20760","59.81048"
"286.40000","1.20812","59.92665"
"286.80000","1.20865","60.41069"
"287.20000","1.20917","60.35700"
"287.60000","1.20968","59.98034"
"288.00000","1.21022","60.11938"
"288.40000","1.21075","60.35700"
"288.80000","1.21127","60.83929"
"289.20000","1.21179","60.57438"
"289.60000","1.21231","60.84545"
"290.00000","1.21286","60.94489"
"290.40000","1.21337","60.86304"
"290.80000","1.21389","61.05491"
"291.20000","1.21442","60.92554"
"291.60000","1.21494","61.37085"
"292.00000","1.21547","61.20099"
"292.40000","1.21599","61.90065"
"292.80000","1.21651","61.03202"
"293.20000","1.21705","61.72288"
"293.60000","1.21758","61.63839"
"294.00000","1.21808","61.62079"
"294.40000","1.21861","61.97106"
"294.80000","1.21914","61.76952"
"295.20000","1.21966","61.77128"
"295.60000","1.22018","61.79768"
"296.00000","1.22071","62.25972"
"296.40000","1.22125","62.14619"
"296.80000","1.22177","62.08195"
"297.20000","1.22229","62.47270"
"297.60000","1.22281","62.57126"
"298.00000","1.22334","62.43398"
"298.40000","1.22388","62.22188"
"298.80000","1.22440","62.34421"
"299.20000","1.22490","62.51846"
"299.60000","1.22544","62.46302"
"300.00000","1.22597","62.83881"
"300.40000","1.22650","63.00162"
"300.80000","1.22701","63.13539"
"301.20000","1.22754","62.88898"
"301.60000","1.22808","63.08787"
"302.00000","1.22859","63.28941"
"302.40000","1.22910","63.34573"
"302.80000","1.22964","63.26565"
"303.20000","1.23017","64.05595"
"303.60000","1.23070","63.20932"
"304.00000","1.23122","63.94946"
"304.40000","1.23173","63.87466"
"304.80000","1.23227","63.93098"
"305.20000","1.23279","63.92394"
"305.60000","1.23332","63.75937"
"306.00000","1.23384","63.85530"
"306.40000","1.23437","64.19324"
"306.80000","1.23491","64.32349"
"307.20000","1.23541","64.51534"
"307.60000","1.23593","64.45110"
"308.00000","1.23647","64.44670"
"308.40000","1.23699","64.45287"
"308.80000","1.23751","64.66320"
"309.20000","1.23803","64.89906"
"309.60000","1.23855","65.01083"
"310.00000","1.23910","64.96155"
"310.40000","1.23962","65.14372"
"310.80000","1.24014","65.03459"
"311.20000","1.24066","64.95010"
"311.60000","1.24119","65.17893"
"312.00000","1.24172","65.34966"
"312.40000","1.24223","65.66560"
"312.80000","1.24276","65.30301"
"313.20000","1.24330","65.24140"
"313.60000","1.24383","65.70697"
"314.00000","1.24433","65.72281"
"314.40000","1.24486","66.17780"
"314.80000","1.24538","65.85218"
"315.20000","1.24592","65.86978"
"315.60000","1.24644","66.12764"
"316.00000","1.24695","65.84514"
"316.40000","1.24749","66.17516"
"316.80000","1.24802","66.41102"
"317.20000","1.24853","66.77977"
"317.60000","1.24906","66.52719"
"318.00000","1.24959","66.54216"
"318.40000","1.25013","66.43567"
"318.80000","1.25063","66.39695"
"319.20000","1.25115","67.03236"
"319.60000","1.25169","67.02707"
"320.00000","1.25222","66.94083"
"320.40000","1.25274","66.85898"
"320.80000","1.25326","67.02091"
"321.20000","1.25379","66.91706"
"321.60000","1.25432","67.35358"
"322.00000","1.25484","67.41255"
"322.40000","1.25534","67.64312"
"322.80000","1.25587","67.20837"
"323.20000","1.25642","67.65456"
"323.60000","1.25695","67.85610"
"324.00000","1.25746","68.06116"
"324.40000","1.25798","67.54456"
"324.80000","1.25852","67.74521"
"325.20000","1.25904","68.08844"
"325.60000","1.25955","68.44487"
"326.00000","1.26009","68.37534"
"326.40000","1.26062","68.48799"
"326.80000","1.26114","68.47832"
"327.20000","1.26166","68.04356"
"327.60000","1.26218","68.48799"
"328.00000","1.26271","68.77050"
"328.40000","1.26324","68.97203"
"328.80000","1.26377","68.76258"
"329.20000","1.26428","68.53552"
"329.60000","1.26480","69.14629"
"330.00000","1.26534","69.29238"
"330.40000","1.26587","68.97996"
"330.80000","1.26638","69.16653"
"331.20000","1.26691","69.13749"
"331.60000","1.26745","70.01140"
"332.00000","1.26796","69.73066"
"332.40000","1.26847","69.99292"
"332.80000","1.26901","69.39799"
"333.20000","1.26954","69.67961"
"333.60000","1.27007","69.93395"
"334.00000","1.27058","69.96564"
"334.40000","1.27110","69.62241"
"334.80000","1.27163","69.88378"
"335.20000","1.27217","70.06420"
"335.60000","1.27269","69.99204"
"336.00000","1.27320","70.62393"
"336.40000","1.27374","70.54736"
"336.80000","1.27427","70.36694"
"337.20000","1.27477","70.41799"
"337.60000","1.27531","70.52184"
"338.00000","1.27584","70.61337"
"338.40000","1.27638","71.29278"
"338.80000","1.27688","71.13526"
"339.20000","1.27740","70.88443"
"339.60000","1.27793","71.10973"
"340.00000","1.27846","71.52689"
"340.40000","1.27899","71.34559"
"340.80000","1.27951","71.63601"
"341.20000","1.28004","71.36671"
"341.60000","1.28057","71.93523"
"342.00000","1.28109","71.75835"
"342.40000","1.28159","71.44416"
"342.80000","1.28213","71.68001"
"343.20000","1.28266","71.55504"
"343.60000","1.28320","72.03908"
"344.00000","1.28370","72.29254"
"344.40000","1.28423","72.06725"
"344.80000","1.28477","72.50992"
"345.20000","1.28529","72.27671"
"345.60000","1.28581","72.63753"
"346.00000","1.28634","72.63050"
"346.40000","1.28686","72.93940"
"346.80000","1.28739","72.62433"
"347.20000","1.28790","72.62785"
"347.60000","1.28842","72.92972"
"348.00000","1.28896","73.22542"
"348.40000","1.28950","73.30199"
"348.80000","1.29002","72.90772"
"349.20000","1.29053","73.08374"
"349.60000","1.29105","73.13389"
"350.00000","1.29160","73.53257"
"350.40000","1.29211","73.49209"
"350.80000","1.29263","74.00252"
"351.20000","1.29316","73.50969"
"351.60000","1.29368","73.53081"
"352.00000","1.29421","73.62498"
"352.40000","1.29471","74.12309"
"352.80000","1.29524","73.96644"
"353.20000","1.29579","74.15303"
"353.60000","1.29632","74.28240"
"354.00000","1.29682","74.39064"
"354.40000","1.29735","74.60802"
"354.80000","1.29788","73.89076"
"355.20000","1.29842","74.28415"
"355.60000","1.29893","74.79987"
"356.00000","1.29946","74.65114"
"356.40000","1.30000","74.65026"
"356.80000","1.30051","74.68018"
"357.20000","1.30102","74.75323"
"357.60000","1.30155","75.20911"
"358.00000","1.30207","75.03309"
"358.40000","1.30262","75.67731"
"358.80000","1.30314","75.14838"
"359.20000","1.30365","75.34904"
"359.60000","1.30418","75.67731"
"360.00000","1.30471","75.61042"
"360.40000","1.30524","75.77235"
"360.80000","1.30575","75.59546"
"361.20000","1.30628","76.11118"
"361.60000","1.30682","76.39281"
"362.00000","1.30733","76.20623"
"362.40000","1.30785","76.15078"
"362.80000","1.30838","75.93957"
"363.20000","1.30891","76.31272"
"363.60000","1.30944","76.70699"
"364.00000","1.30996","76.42537"
"364.40000","1.31047","76.69379"
"364.80000","1.31100","76.58730"
"365.20000","1.31153","77.09335"
"365.60000","1.31204","76.88212"
"366.00000","1.31257","76.77300"
"366.40000","1.31310","76.97189"
"366.80000","1.31363","77.32832"
"367.20000","1.31414","77.45769"
"367.60000","1.31467","77.29048"
"368.00000","1.31521","77.67947"
"368.40000","1.31575","77.56154"
"368.80000","1.31625","77.70499"
"369.20000","1.31678","77.94613"
"369.60000","1.31729","77.43569"
"370.00000","1.31784","77.59850"
"370.40000","1.31836","77.79124"
"370.80000","1.31886","78.17759"
"371.20000","1.31941","78.04382"
"371.60000","1.31993","78.32193"
"372.00000","1.32046","78.44337"
"372.40000","1.32097","78.50586"
"372.80000","1.32150","78.53666"
"373.20000","1.32204","78.62555"
"373.60000","1.32257","78.60266"
"374.00000","1.32307","78.89133"
"374.40000","1.32360","79.16679"
"374.80000","1.32412","79.24952"
"375.20000","1.32466","79.37009"
"375.60000","1.32518","79.38593"
"376.00000","1.32571","79.68251"
"376.40000","1.32624","79.05590"
"376.80000","1.32677","79.77140"
"377.20000","1.32727","79.56194"
"377.60000","1.32779","79.79164"
"378.00000","1.32833","79.85501"
"378.40000","1.32887","80.30648"
"378.80000","1.32939","79.90606"
"379.20000","1.32989","80.00110"
"379.60000","1.33043","79.96061"
"380.00000","1.33096","80.28273"
"380.40000","1.33148","80.82133"
"380.80000","1.33200","80.57227"
"381.20000","1.33253","80.65675"
"381.60000","1.33306","80.50362"
"382.00000","1.33358","80.71835"
"382.40000","1.33408","80.81165"
"382.80000","1.33462","81.03255"
"383.20000","1.33516","80.96390"
"383.60000","1.33569","80.86005"
"384.00000","1.33620","80.64003"
"384.40000","1.33672","81.07743"
"384.80000","1.33726","81.48402"
"385.20000","1.33779","81.41626"
"385.60000","1.33830","81.93550"
"386.00000","1.33883","81.57643"
"386.40000","1.33936","81.71813"
"386.80000","1.33988","82.10007"
"387.20000","1.34040","82.10535"
"387.60000","1.34092","81.72252"
"388.00000","1.34145","81.99447"
"388.40000","1.34198","82.29368"
"388.80000","1.34250","82.31130"
"389.20000","1.34301","82.39754"
"389.60000","1.34354","82.40634"
"390.00000","1.34408","82.48291"
"390.40000","1.34461","82.53131"
"390.80000","1.34512","82.64924"
"391.20000","1.34566","82.80589"
"391.60000","1.34619","82.91502"
"392.00000","1.34670","82.96255"
"392.40000","1.34722","83.01095"
"392.80000","1.34775","83.24417"
"393.20000","1.34828","83.45891"
"393.60000","1.34881","83.40962"
"394.00000","1.34933","83.33834"
"394.40000","1.34984","83.62964"
"394.80000","1.35037","83.71589"
"395.20000","1.35090","83.47298"
"395.60000","1.35141","83.51874"
"396.00000","1.35194","84.07935"
"396.40000","1.35247","84.02567"
"396.80000","1.35301","84.20521"
"397.20000","1.35351","84.06703"
"397.60000","1.35404","84.31081"
"398.00000","1.35458","84.78430"
"398.40000","1.35512","84.45866"
"398.80000","1.35562","84.94534"
"399.20000","1.35614","84.59244"
"399.60000","1.35668","84.92863"
"400.00000","1.35720","84.78869"
"400.40000","1.35773","84.87406"
"400.80000","1.35825","85.12928"
"401.20000","1.35877","84.97351"
"401.60000","1.35931","85.52268"
"402.00000","1.35983","85.26481"
"402.40000","1.36033","85.42323"
"402.80000","1.36087","85.31762"
"403.20000","1.36141","85.72333"
"403.60000","1.36194","85.44963"
"404.00000","1.36245","85.79638"
"404.40000","1.36297","86.07976"
"404.80000","1.36351","85.79638"
"405.20000","1.36403","86.53036"
"405.60000","1.36455","85.92575"
"406.00000","1.36508","86.33323"
"406.40000","1.36559","86.41595"
"406.80000","1.36613","86.31913"
"407.20000","1.36664","86.51188"
"407.60000","1.36716","86.51452"
"408.00000","1.36770","86.56204"
"408.40000","1.36823","86.56380"
"408.80000","1.36874","86.98535"
"409.20000","1.36927","86.97568"
"409.60000","1.36979","87.37963"
"410.00000","1.37034","87.02232"
"410.40000","1.37085","87.57500"
"410.80000","1.37137","87.01352"
"411.20000","1.37191","87.67973"
"411.60000","1.37243","87.47028"
"412.00000","1.37295","87.39283"
"412.40000","1.37347","87.65949"
"412.80000","1.37398","87.64981"
"413.20000","1.37453","88.29755"
"413.60000","1.37505","88.38995"
"414.00000","1.37556","88.07137"
"414.40000","1.37609","88.24386"
"414.80000","1.37662","87.86631"
"415.20000","1.37716","88.52548"
"415.60000","1.37767","88.24210"
"416.00000","1.37819","87.99392"
"416.40000","1.37873","87.78798"
"416.80000","1.37925","88.06344"
"417.20000","1.37976","87.93144"
"417.60000","1.38029","88.48412"
"418.00000","1.38082","88.85463"
"418.40000","1.38136","88.58092"
"418.80000","1.38187","88.57741"
"419.20000","1.38238","88.89159"
"419.60000","1.38292","88.93560"
"420.00000","1.38345","89.20490"
"420.40000","1.38398","89.14153"
"420.80000","1.38449","89.40996"
"421.20000","1.38502","89.26739"
"421.60000","1.38556","89.43548"
"422.00000","1.38607","89.65198"
"422.40000","1.38658","89.51029"
"422.80000","1.38712","89.87551"
"423.20000","1.38764","89.64053"
"423.60000","1.38817","90.03129"
"424.00000","1.38869","90.07705"
"424.40000","1.38920","90.26186"
"424.80000","1.38975","90.18794"
"425.20000","1.39028","90.77495"
"425.60000","1.39080","90.51181"
"426.00000","1.39132","90.92984"
"426.40000","1.39185","91.12874"
"426.80000","1.39239","90.93776"
"427.20000","1.39288","91.36899"
"427.60000","1.39341","91.10409"
"428.00000","1.39395","91.19826"
"428.40000","1.39447","91.44732"
"428.80000","1.39500","91.64182"
"429.20000","1.39552","92.01233"
"429.60000","1.39605","91.47988"
"430.00000","1.39658","91.83895"
"430.40000","1.39710","92.25259"
"430.80000","1.39762","91.92785"
"431.20000","1.39814","92.15138"
"431.60000","1.39868","92.47348"
"432.00000","1.39920","92.89944"
"432.40000","1.39970","92.43476"
"432.80000","1.40023","92.92849"
"433.20000","1.40078","92.97337"
"433.60000","1.40131","92.85719"
"434.00000","1.40182","92.71111"
"434.40000","1.40235","93.04817"
"434.80000","1.40286","93.39492"
"435.20000","1.40340","93.70295"
"435.60000","1.40392","93.08514"
"436.00000","1.40444","93.21275"
"436.40000","1.40497","93.52166"
"436.80000","1.40550","93.53750"
"437.20000","1.40601","93.70647"
"437.60000","1.40653","93.92561"
"438.00000","1.40707","94.04706"
"438.40000","1.40761","94.13507"
"438.80000","1.40811","94.07873"
"439.20000","1.40863","94.65871"
"439.60000","1.40917","94.48005"
"440.00000","1.40970","94.77223"
"440.40000","1.41022","94.83032"
"440.80000","1.41074","95.03626"
"441.20000","1.41127","95.06090"
"441.60000","1.41180","95.26243"
"442.00000","1.41232","94.92977"
"442.40000","1.41283","95.28620"
"442.80000","1.41337","95.14979"
"443.20000","1.41390","95.48950"
"443.60000","1.41443","95.58630"
"444.00000","1.41495","96.04922"
"444.40000","1.41547","95.94449"
"444.80000","1.41601","95.80456"
"445.20000","1.41652","95.88817"
"445.60000","1.41703","95.94713"
"446.00000","1.41757","96.83600"
"446.40000","1.41810","96.41885"
"446.80000","1.41862","96.68551"
"447.20000","1.41914","97.04986"
"447.60000","1.41966","96.78760"
"448.00000","1.42019","96.49190"
"448.40000","1.42073","97.07187"
"448.80000","1.42124","96.81401"
"449.20000","1.42176","97.38341"
"449.60000","1.42228","97.55151"
"450.00000","1.42283","97.03138"
"450.40000","1.42335","97.25492"
"450.80000","1.42386","97.74336"
"451.20000","1.42440","97.97218"
"451.60000","1.42492","97.89474"
"452.00000","1.42543","97.77592"
"452.40000","1.42595","97.88681"
"452.80000","1.42649","98.07691"
"453.20000","1.42703","98.06723"
"453.60000","1.42755","98.36997"
"454.00000","1.42806","98.76776"
"454.40000","1.42858","98.79945"
"454.80000","1.42912","98.85841"
"455.20000","1.42965","98.90594"
"455.60000","1.43017","98.91474"
"456.00000","1.43068","99.13652"
"456.40000","1.43122","99.54751"
"456.80000","1.43175","99.41725"
"457.20000","1.43226","99.21836"
"457.60000","1.43278","99.77809"
"458.00000","1.43332","99.59679"
"458.40000","1.43386","99.78777"
"458.80000","1.43437","99.97523"
"459.20000","1.43488","99.97346"
"459.60000","1.43542","99.59239"
"460.00000","1.43594","100.24541"
"460.40000","1.43647","100.53407"
"460.80000","1.43699","100.02539"
"461.20000","1.43752","100.93274"
"461.60000","1.43806","100.57896"
"462.00000","1.43857","100.60623"
"462.40000","1.43907","100.81833"
"462.80000","1.43961","100.77257"
"463.20000","1.44015","100.94330"
"463.60000","1.44068","100.99083"
"464.00000","1.44118","100.79017"
"464.40000","1.44170","101.40534"
"464.80000","1.44225","101.32790"
"465.20000","1.44276","101.56463"
"465.60000","1.44329","101.54792"
"466.00000","1.44382","101.82514"
"466.40000","1.44433","101.56463"
"466.80000","1.44487","101.75121"
"467.20000","1.44538","102.47199"
"467.60000","1.44590","102.17276"
"468.00000","1.44645","102.11292"
"468.40000","1.44697","102.11292"
"468.80000","1.44750","102.24317"
"469.20000","1.44801","102.51423"
"469.60000","1.44854","102.40422"
"470.00000","1.44908","103.03699"
"470.40000","1.44959","102.81610"
"470.80000","1.45011","102.65416"
"471.20000","1.45064","102.86450"
"471.60000","1.45117","103.33270"
"472.00000","1.45169","103.30542"
"472.40000","1.45221","103.39167"
"472.80000","1.45272","103.38374"
"473.20000","1.45327","104.16877"
"473.60000","1.45380","103.71993"
"474.00000","1.45430","103.84402"
"474.40000","1.45484","104.32278"
"474.80000","1.45537","104.13445"
"475.20000","1.45590","104.23742"
"475.60000","1.45641","104.31046"
"476.00000","1.45693","104.60793"
"476.40000","1.45747","104.18902"
"476.80000","1.45799","104.40463"
"477.20000","1.45851","104.67481"
"477.60000","1.45904","105.13861"
"478.00000","1.45956","105.23630"
"478.40000","1.46010","104.87019"
"478.80000","1.46062","105.37447"
"479.20000","1.46112","105.17470"
"479.60000","1.46166","105.32695"
"480.00000","1.46218","105.35422"
"480.40000","1.46271","105.43960"
"480.80000","1.46322","105.45984"
"481.20000","1.46376","105.39823"
"481.60000","1.46430","106.21230"
"482.00000","1.46481","105.51792"
"482.40000","1.46532","106.06445"
"482.80000","1.46586","106.24926"
"483.20000","1.46640","106.72626"
"483.60000","1.46692","106.28535"
"484.00000","1.46744","106.52208"
"484.40000","1.46795","106.53088"
"484.80000","1.46849","107.26223"
"485.20000","1.46901","107.05628"
"485.60000","1.46952","107.11437"
"486.00000","1.47006","107.19534"
"486.40000","1.47058","107.15486"
"486.80000","1.47112","106.94628"
"487.20000","1.47163","107.14166"
"487.60000","1.47215","107.51216"
"488.00000","1.47269","107.48224"
"488.40000","1.47323","107.82283"
"488.80000","1.47374","107.85099"
"489.20000","1.47425","107.89060"
"489.60000","1.47477","108.21710"
"490.00000","1.47532","107.95836"
"490.40000","1.47584","108.05693"
"490.80000","1.47636","108.54185"
"491.20000","1.47689","108.70642"
"491.60000","1.47741","108.93348"
"492.00000","1.47794","108.43624"
"492.40000","1.47845","108.63073"
"492.80000","1.47898","108.91500"
"493.20000","1.47952","108.75042"
"493.60000","1.48003","109.23447"
"494.00000","1.48055","109.39640"
"494.40000","1.48108","109.48000"
"494.80000","1.48162","109.28727"
"495.20000","1.48214","109.46768"
"495.60000","1.48265","109.43953"
"496.00000","1.48318","109.92092"
"496.40000","1.48371","109.80827"
"496.80000","1.48424","110.10927"
"497.20000","1.48475","110.40408"
"497.60000","1.48528","109.83292"
"498.00000","1.48581","110.63554"
"498.40000","1.48635","110.77723"
"498.80000","1.48687","110.30111"
"499.20000","1.48737","110.77459"
"499.60000","1.48791","110.57042"
"500.00000","1.48844","110.93829"
"500.40000","1.48896","111.02190"
"500.80000","1.48948","110.92948"
"501.20000","1.49001","111.11343"
"501.60000","1.49054","110.87140"
"502.00000","1.49106","111.33433"
"502.40000","1.49157","111.17679"
"502.80000","1.49210","111.20055"
"503.20000","1.49264","111.51649"
"503.60000","1.49317","111.94510"
"504.00000","1.49367","111.88436"
"504.40000","1.49420","111.54730"
"504.80000","1.49474","111.97238"
"505.20000","1.49526","112.05157"
"505.60000","1.49577","112.42649"
"506.00000","1.49631","112.64563"
"506.40000","1.49684","112.79260"
"506.80000","1.49738","112.84364"
"507.20000","1.49787","113.09710"
"507.60000","1.49840","112.48810"
"508.00000","1.49893","112.98182"
"508.40000","1.49946","113.48786"
"508.80000","1.49998","113.28280"
"509.20000","1.50049","113.33384"
"509.60000","1.50102","113.56883"
"510.00000","1.50157","113.44473"
"510.40000","1.50209","113.41834"
"510.80000","1.50260","113.81965"
"511.20000","1.50313","113.68323"
"511.60000","1.50366","114.01766"
"512.00000","1.50418","113.84868"
"512.40000","1.50469","113.85924"
"512.80000","1.50523","114.70589"
"513.20000","1.50577","114.32568"
"513.60000","1.50629","114.68740"
"514.00000","1.50680","114.84317"
"514.40000","1.50732","114.63195"
"514.80000","1.50785","114.71820"
"515.20000","1.50838","114.71996"
"515.60000","1.50891","115.28673"
"516.00000","1.50943","115.22248"
"516.40000","1.50996","115.04031"
"516.80000","1.51049","115.25593"
"517.20000","1.51099","115.49178"
"517.60000","1.51152","115.80245"
"518.00000","1.51206","115.70389"
"518.40000","1.51260","115.55164"
"518.80000","1.51311","116.26360"
"519.20000","1.51362","116.20640"
"519.60000","1.51416","115.89133"
"520.00000","1.51468","116.38242"
"520.40000","1.51521","116.51971"
"520.80000","1.51573","116.39386"
"521.20000","1.51625","116.90166"
"521.60000","1.51680","116.80485"
"522.00000","1.51731","116.47395"
"522.40000","1.51781","116.79694"
"522.80000","1.51835","117.08824"
"523.20000","1.51889","117.01606"
"523.60000","1.51940","117.20089"
"524.00000","1.51992","117.49570"
"524.40000","1.52044","117.39539"
"524.80000","1.52099","118.02552"
"525.20000","1.52150","117.89086"
"525.60000","1.52203","117.48427"
"526.00000","1.52256","118.23408"
"526.40000","1.52308","118.49107"
"526.80000","1.52362","118.21472"
"527.20000","1.52412","117.77470"
"527.60000","1.52464","118.22001"
"528.00000","1.52519","118.39514"
"528.40000","1.52572","118.86598"
"528.80000","1.52624","118.94784"
"529.20000","1.52675","118.66356"
"529.60000","1.52727","118.45235"
"530.00000","1.52781","118.62045"
"530.40000","1.52833","119.11768"
"530.80000","1.52885","118.90735"
"531.20000","1.52939","119.13705"
"531.60000","1.52991","119.41338"
"532.00000","1.53043","119.57796"
"532.40000","1.53094","119.47587"
"532.80000","1.53147","119.51900"
"533.20000","1.53201","119.36146"
"533.60000","1.53254","119.67565"
"534.00000","1.53304","119.80326"
"534.40000","1.53358","119.91942"
"534.80000","1.53411","120.12976"
"535.20000","1.53464","119.72141"
"535.60000","1.53515","120.14121"
"536.00000","1.53567","120.41491"
"536.40000","1.53621","120.55660"
"536.80000","1.53673","120.96320"
"537.20000","1.53725","120.54779"
"537.60000","1.53777","120.78014"
"538.00000","1.53829","120.96583"
"538.40000","1.53884","121.38211"
"538.80000","1.53936","121.42876"
"539.20000","1.53986","121.01424"
"539.60000","1.54040","121.17529"
"540.00000","1.54093","121.24041"
"540.40000","1.54146","121.58717"
"540.80000","1.54198","121.80191"
"541.20000","1.54250","122.03248"
"541.60000","1.54304","122.09232"
"542.00000","1.54355","121.78782"
"542.40000","1.54406","121.80455"
"542.80000","1.54460","122.12753"
"543.20000","1.54514","122.55611"
"543.60000","1.54566","121.99817"
"544.00000","1.54617","122.49188"
"544.40000","1.54668","122.59221"
"544.80000","1.54723","122.92048"
"545.20000","1.54776","123.09824"
"545.60000","1.54828","122.96359"
"546.00000","1.54880","122.94864"
"546.40000","1.54933","123.22850"
"546.80000","1.54987","123.44235"
"547.20000","1.55036","123.24434"
"547.60000","1.55089","123.14754"
"548.00000","1.55143","123.70726"
"548.40000","1.55197","123.79439"
"548.80000","1.55247","123.53300"
"549.20000","1.55300","123.64214"
"549.60000","1.55353","123.52773"
"550.00000","1.55405","124.28194"
"550.40000","1.55458","124.04697"
"550.80000","1.55510","124.45180"
"551.20000","1.55563","124.16578"
"551.60000","1.55615","124.52749"
"552.00000","1.55668","125.09338"
"552.40000","1.55718","124.62253"
"552.80000","1.55771","124.75542"
"553.20000","1.55826","124.78359"
"553.60000","1.55879","125.12506"
"554.00000","1.55929","125.28258"
"554.40000","1.55983","125.54485"
"554.80000","1.56035","125.44804"
"555.20000","1.56088","125.67949"
"555.60000","1.56140","125.25707"
"556.00000","1.56193","125.44717"
"556.40000","1.56245","125.99897"
"556.80000","1.56298","125.76838"
"557.20000","1.56350","126.04473"
"557.60000","1.56402","126.36685"
"558.00000","1.56455","125.98224"
"558.40000","1.56509","126.36420"
"558.80000","1.56561","126.47773"
"559.20000","1.56611","126.62647"
"559.60000","1.56665","126.85704"
"560.00000","1.56718","126.89313"
"560.40000","1.56770","126.58158"
"560.80000","1.56822","126.85263"
"561.20000","1.56875","126.99081"
"561.60000","1.56928","126.97849"
"562.00000","1.56980","127.31379"
"562.40000","1.57031","127.29884"
"562.80000","1.57084","127.70191"
"563.20000","1.57138","128.17188"
"563.60000","1.57191","128.05658"
"564.00000","1.57241","127.75471"
"564.40000","1.57293","128.25460"
"564.80000","1.57348","128.11378"
"565.20000","1.57401","128.07506"
"565.60000","1.57452","128.19563"
"566.00000","1.57504","128.08034"
"566.40000","1.57557","128.63479"
"566.80000","1.57610","128.89265"
"567.20000","1.57661","128.79055"
"567.60000","1.57714","128.75887"
"568.00000","1.57767","129.00354"
"568.40000","1.57820","129.05986"
"568.80000","1.57872","129.17339"
"569.20000","1.57923","129.07659"
"569.60000","1.57976","129.14082"
"570.00000","1.58031","129.25524"
"570.40000","1.58083","129.57470"
"570.80000","1.58133","129.69352"
"571.20000","1.58188","129.99977"
"571.60000","1.58240","130.13002"
"572.00000","1.58292","129.80793"
"572.40000","1.58343","129.58967"
"572.80000","1.58397","130.12035"
"573.20000","1.58451","130.26293"
"573.60000","1.58503","130.12123"
"574.00000","1.58554","130.40814"
"574.40000","1.58606","130.73728"
"574.80000","1.58660","130.77513"
"575.20000","1.58713","130.87985"
"575.60000","1.58765","130.88689"
"576.00000","1.58817","131.03650"
"576.40000","1.58871","130.73641"
"576.80000","1.58923","131.51351"
"577.20000","1.58974","131.83825"
"577.60000","1.59027","131.60591"
"578.00000","1.59080","131.69569"
"578.40000","1.59134","131.99138"
"578.80000","1.59184","131.92185"
"579.20000","1.59236","131.92185"
"579.60000","1.59290","132.12076"
"580.00000","1.59342","132.21933"
"580.40000","1.59395","132.20083"
"580.80000","1.59447","132.57310"
"581.20000","1.59499","132.75265"
"581.60000","1.59553","132.56078"
"582.00000","1.59605","132.60919"
"582.40000","1.59655","132.71305"
"582.80000","1.59709","132.62416"
"583.20000","1.59763","132.83625"
"583.60000","1.59816","132.67872"
"584.00000","1.59867","133.02459"
"584.40000","1.59919","132.84241"
"584.80000","1.59973","132.69367"
"585.20000","1.60024","133.10819"
"585.60000","1.60076","132.74912"
"585.91600","1.60117","133.14956"