File: DataAnalyzer/TestFiles/Specimen_RawData_5.csv
Specimen properties : Specimen label,"orgn_80_NA_2_wblk_3ptbnd_run5"
Maximum Load : Flexure extension at Maximum Load,"1.59323",in
Maximum Load : Maximum Load,"127.53469",lbf

Time,Extension,Load
(s),(in),(lbf)
"0.00000","0.82307","15.03328"
"0.40000","0.82390","14.90126"
"0.80000","0.82411","15.00951"
"1.20000","0.82457","14.92414"
"1.60000","0.82511","14.64956"
"2.00000","0.82564","14.80710"
"2.40000","0.82615","14.66364"
"2.80000","0.82668","14.77013"
"3.20000","0.82721","14.76045"
"3.60000","0.82775","14.94263"
"4.00000","0.82827","15.08784"
"4.40000","0.82879","15.24889"
"4.80000","0.82931","15.31490"
"5.20000","0.82985","15.37386"
"5.60000","0.83037","15.39674"
"6.00000","0.83089","15.19521"
"6.40000","0.83142","15.64757"
"6.80000","0.83194","15.07376"
"7.20000","0.83248","15.38442"
"7.60000","0.83299","15.61676"
"8.00000","0.83351","15.43723"
"8.40000","0.83405","15.27001"
"8.80000","0.83458","15.51996"
"9.20000","0.83509","15.57364"
"9.60000","0.83561","15.80510"
"10.00000","0.83614","15.98023"
"10.40000","0.83668","15.68013"
"10.80000","0.83719","16.01895"
"11.20000","0.83771","15.68101"
"11.60000","0.83825","16.05680"
"12.00000","0.83877","15.85878"
"12.40000","0.83930","15.83414"
"12.80000","0.83981","16.12281"
"13.20000","0.84034","16.10696"
"13.60000","0.84088","16.38595"
"14.00000","0.84140","16.18705"
"14.40000","0.84190","15.91863"
"14.80000","0.84243","16.44491"
"15.20000","0.84297","15.89838"
"15.60000","0.84350","16.64205"
"16.00000","0.84401","16.50299"
"16.40000","0.84454","16.23721"
"16.80000","0.84508","16.73446"
"17.20000","0.84559","16.60772"
"17.60000","0.84611","16.86735"
"18.00000","0.84664","16.69837"
"18.40000","0.84715","16.80486"
"18.80000","0.84770","16.52676"
"19.20000","0.84821","16.55580"
"19.60000","0.84873","16.78550"
"20.00000","0.84926","16.63589"
"20.40000","0.84979","16.83566"
"20.80000","0.85032","16.85414"
"21.20000","0.85083","17.01784"
"21.60000","0.85137","17.31178"
"22.00000","0.85190","16.85590"
"22.40000","0.85242","17.23434"
"22.80000","0.85293","16.96063"
"23.20000","0.85347","17.40507"
"23.60000","0.85399","17.38747"
"24.00000","0.85452","17.45523"
"24.40000","0.85503","17.72366"
"24.80000","0.85556","17.74390"
"25.20000","0.85610","18.10473"
"25.60000","0.85662","17.88207"
"26.00000","0.85713","17.69461"
"26.40000","0.85766","17.61981"
"26.80000","0.85819","17.87415"
"27.20000","0.85873","18.01672"
"27.60000","0.85924","17.87767"
"28.00000","0.85976","18.12233"
"28.40000","0.86030","18.15401"
"28.80000","0.86081","18.26930"
"29.20000","0.86134","18.08184"
"29.60000","0.86185","18.13641"
"30.00000","0.86238","18.02288"
"30.40000","0.86292","18.15489"
"30.80000","0.86344","19.13705"
"31.20000","0.86397","18.78942"
"31.60000","0.86449","18.35203"
"32.00000","0.86502","18.62837"
"32.40000","0.86555","18.96280"
"32.80000","0.86605","18.65301"
"33.20000","0.86659","18.93640"
"33.60000","0.86713","18.85367"
"34.00000","0.86764","18.93552"
"34.40000","0.86816","18.84311"
"34.80000","0.86868","19.11857"
"35.20000","0.86920","19.22858"
"35.60000","0.86974","19.33331"
"36.00000","0.87026","19.09217"
"36.40000","0.87079","19.14145"
"36.80000","0.87132","19.52516"
"37.20000","0.87184","19.21274"
"37.60000","0.87236","19.64925"
"38.00000","0.87288","19.91416"
"38.40000","0.87341","20.05585"
"38.80000","0.87396","19.71966"
"39.20000","0.87445","19.92032"
"39.60000","0.87498","19.50932"
"40.00000","0.87551","19.81471"
"40.40000","0.87603","19.76806"
"40.80000","0.87657","20.34099"
"41.20000","0.87709","20.44484"
"41.60000","0.87762","20.27763"
"42.00000","0.87814","19.95024"
"42.40000","0.87866","20.37708"
"42.80000","0.87918","20.26531"
"43.20000","0.87971","20.53637"
"43.60000","0.88023","20.75902"
"44.00000","0.88077","20.36035"
"44.40000","0.88127","20.22834"
"44.80000","0.88180","20.43780"
"45.20000","0.88234","21.00369"
"45.60000","0.88287","20.30843"
"46.00000","0.88338","20.90864"
"46.40000","0.88391","20.90688"
"46.80000","0.88444","21.03361"
"47.20000","0.88497","20.96936"
"47.60000","0.88549","21.19466"
"48.00000","0.88601","21.22106"
"48.40000","0.88654","21.03097"
"48.80000","0.88707","21.15858"
"49.20000","0.88759","21.35307"
"49.60000","0.88810","21.44108"
"50.00000","0.88863","21.30203"
"50.40000","0.88917","21.76407"
"50.80000","0.88969","21.72358"
"51.20000","0.89020","21.05473"
"51.60000","0.89074","21.52997"
"52.00000","0.89127","21.49037"
"52.40000","0.89178","21.68134"
"52.80000","0.89231","21.85471"
"53.20000","0.89283","21.89960"
"53.60000","0.89336","21.54845"
"54.00000","0.89389","21.66990"
"54.40000","0.89440","21.86176"
"54.80000","0.89493","21.43668"
"55.20000","0.89547","21.92688"
"55.60000","0.89600","21.96384"
"56.00000","0.89650","22.25867"
"56.40000","0.89703","22.66790"
"56.80000","0.89757","22.40564"
"57.20000","0.89809","22.03513"
"57.60000","0.89861","22.22523"
"58.00000","0.89913","21.92424"
"58.40000","0.89966","22.59398"
"58.80000","0.90020","22.51477"
"59.20000","0.90070","22.67142"
"59.60000","0.90122","22.46197"
"60.00000","0.90175","22.67318"
"60.40000","0.90229","22.80079"
"60.80000","0.90282","23.02521"
"61.20000","0.90334","22.74799"
"61.60000","0.90386","23.01817"
"62.00000","0.90439","23.04986"
"62.40000","0.90492","23.19067"
"62.80000","0.90542","22.63006"
"63.20000","0.90596","23.24963"
"63.60000","0.90649","22.98825"
"64.00000","0.90703","23.43180"
"64.40000","0.90753","23.11938"
"64.80000","0.90805","23.34380"
"65.20000","0.90860","23.23731"
"65.60000","0.90911","23.62102"
"66.00000","0.90963","24.01705"
"66.40000","0.91016","23.58318"
"66.80000","0.91068","23.55149"
"67.20000","0.91122","23.90088"
"67.60000","0.91173","23.73983"
"68.00000","0.91225","24.02849"
"68.40000","0.91279","23.96777"
"68.80000","0.91332","24.13410"
"69.20000","0.91385","23.83488"
"69.60000","0.91435","24.10066"
"70.00000","0.91488","24.43949"
"70.40000","0.91542","24.48525"
"70.80000","0.91593","24.30748"
"71.20000","0.91645","24.25819"
"71.60000","0.91699","24.72991"
"72.00000","0.91751","24.50725"
"72.40000","0.91803","24.92969"
"72.80000","0.91855","24.85400"
"73.20000","0.91907","25.17787"
"73.60000","0.91961","25.09426"
"74.00000","0.92014","25.14707"
"74.40000","0.92064","25.04850"
"74.80000","0.92118","25.24124"
"75.20000","0.92171","25.11010"
"75.60000","0.92225","25.34068"
"76.00000","0.92275","25.63463"
"76.40000","0.92328","25.42693"
"76.80000","0.92382","25.07314"
"77.20000","0.92433","25.08370"
"77.60000","0.92485","25.65487"
"78.00000","0.92538","25.63639"
"78.40000","0.92590","25.61174"
"78.80000","0.92644","26.06322"
"79.20000","0.92696","25.65751"
"79.60000","0.92747","25.59238"
"80.00000","0.92800","25.81680"
"80.40000","0.92854","25.81944"
"80.80000","0.92907","25.98930"
"81.20000","0.92958","25.91361"
"81.60000","0.93010","26.19876"
"82.00000","0.93064","26.26564"
"82.40000","0.93115","26.18731"
"82.80000","0.93167","25.77984"
"83.20000","0.93221","26.60359"
"83.60000","0.93273","26.20315"
"84.00000","0.93327","26.26476"
"84.40000","0.93377","26.83241"
"84.80000","0.93430","26.30700"
"85.20000","0.93484","26.04210"
"85.60000","0.93536","26.77256"
"86.00000","0.93588","26.57014"
"86.40000","0.93640","26.75408"
"86.80000","0.93693","26.72680"
"87.20000","0.93747","27.22228"
"87.60000","0.93797","27.34197"
"88.00000","0.93849","26.97498"
"88.40000","0.93903","27.07795"
"88.80000","0.93957","27.38773"
"89.20000","0.94008","27.32877"
"89.60000","0.94060","27.42293"
"90.00000","0.94112","27.60335"
"90.40000","0.94166","27.52590"
"90.80000","0.94218","27.52766"
"91.20000","0.94269","27.63415"
"91.60000","0.94323","27.54966"
"92.00000","0.94376","27.69488"
"92.40000","0.94429","27.67903"
"92.80000","0.94479","28.00906"
"93.20000","0.94532","28.12787"
"93.60000","0.94587","27.92546"
"94.00000","0.94638","28.35053"
"94.40000","0.94690","28.43678"
"94.80000","0.94743","27.82513"
"95.20000","0.94796","28.05043"
"95.60000","0.94848","28.18244"
"96.00000","0.94900","28.54943"
"96.40000","0.94953","28.73776"
"96.80000","0.95006","28.40422"
"97.20000","0.95058","28.82841"
"97.60000","0.95111","28.60839"
"98.00000","0.95162","29.17428"
"98.40000","0.95215","28.90849"
"98.80000","0.95269","29.12675"
"99.20000","0.95319","29.07571"
"99.60000","0.95372","28.72280"
"100.00000","0.95425","28.55295"
"100.40000","0.95479","28.82841"
"100.80000","0.95530","29.33445"
"101.20000","0.95582","29.19100"
"101.60000","0.95635","29.26669"
"102.00000","0.95688","28.75625"
"102.40000","0.95740","29.01411"
"102.80000","0.95790","29.42686"
"103.20000","0.95845","29.54655"
"103.60000","0.95898","29.55535"
"104.00000","0.95952","29.89066"
"104.40000","0.96001","29.53247"
"104.80000","0.96054","29.61872"
"105.20000","0.96109","29.93554"
"105.60000","0.96161","29.86690"
"106.00000","0.96212","30.03763"
"106.40000","0.96265","30.02443"
"106.80000","0.96319","29.85193"
"107.20000","0.96371","30.18284"
"107.60000","0.96422","29.83610"
"108.00000","0.96474","30.02795"
"108.40000","0.96528","29.88362"
"108.80000","0.96581","30.33862"
"109.20000","0.96633","29.73488"
"109.60000","0.96684","29.96018"
"110.00000","0.96737","30.17844"
"110.40000","0.96791","30.05963"
"110.80000","0.96843","30.71617"
"111.20000","0.96894","30.17492"
"111.60000","0.96948","30.70560"
"112.00000","0.97001","30.56039"
"112.40000","0.97053","30.49527"
"112.80000","0.97104","31.22572"
"113.20000","0.97157","30.21188"
"113.60000","0.97210","30.73464"
"114.00000","0.97263","30.65192"
"114.40000","0.97315","30.68184"
"114.80000","0.97367","31.11660"
"115.20000","0.97420","31.04707"
"115.60000","0.97473","30.81561"
"116.00000","0.97525","30.97931"
"116.40000","0.97577","31.23716"
"116.80000","0.97631","31.49151"
"117.20000","0.97683","31.29085"
"117.60000","0.97734","31.25213"
"118.00000","0.97787","31.43870"
"118.40000","0.97840","31.42990"
"118.80000","0.97894","31.27853"
"119.20000","0.97945","31.80305"
"119.60000","0.97997","31.65960"
"120.00000","0.98049","31.87874"
"120.40000","0.98102","32.16829"
"120.80000","0.98155","32.18149"
"121.20000","0.98206","32.25365"
"121.60000","0.98259","31.68600"
"122.00000","0.98313","32.36982"
"122.40000","0.98366","32.48775"
"122.80000","0.98416","32.21581"
"123.20000","0.98470","32.69281"
"123.60000","0.98523","32.50271"
"124.00000","0.98577","32.28269"
"124.40000","0.98626","32.33198"
"124.80000","0.98679","32.69809"
"125.20000","0.98733","32.79929"
"125.60000","0.98785","32.78258"
"126.00000","0.98837","32.83626"
"126.40000","0.98890","33.01403"
"126.80000","0.98943","33.41887"
"127.20000","0.98996","33.07828"
"127.60000","0.99047","33.26398"
"128.00000","0.99099","33.07916"
"128.40000","0.99153","33.28774"
"128.80000","0.99206","33.16805"
"129.20000","0.99257","33.25957"
"129.60000","0.99309","32.96123"
"130.00000","0.99362","33.53944"
"130.40000","0.99416","33.84394"
"130.80000","0.99467","33.23229"
"131.20000","0.99519","33.50775"
"131.60000","0.99573","33.80698"
"132.00000","0.99624","33.96627"
"132.40000","0.99677","33.81930"
"132.80000","0.99729","33.59488"
"133.20000","0.99782","34.00060"
"133.60000","0.99836","34.23381"
"134.00000","0.99888","34.00500"
"134.40000","0.99939","33.76033"
"134.80000","0.99992","34.57528"
"135.20000","1.00045","34.59200"
"135.60000","1.00098","34.59992"
"136.00000","1.00149","34.47583"
"136.40000","1.00202","34.41071"
"136.80000","1.00255","35.17021"
"137.20000","1.00307","35.00388"
"137.60000","1.00359","34.74602"
"138.00000","1.00412","34.76362"
"138.40000","1.00464","34.85163"
"138.80000","1.00518","34.81378"
"139.20000","1.00570","34.81026"
"139.60000","1.00621","35.13501"
"140.00000","1.00675","35.12973"
"140.40000","1.00728","35.29606"
"140.80000","1.00781","35.04260"
"141.20000","1.00831","35.41487"
"141.60000","1.00885","35.58209"
"142.00000","1.00939","35.71322"
"142.40000","1.00989","35.44567"
"142.80000","1.01041","35.40431"
"143.20000","1.01095","35.77482"
"143.60000","1.01147","35.79066"
"144.00000","1.01200","35.26262"
"144.40000","1.01251","36.15765"
"144.80000","1.01303","35.64633"
"145.20000","1.01357","36.07581"
"145.60000","1.01410","36.25974"
"146.00000","1.01462","36.16381"
"146.40000","1.01514","35.99132"
"146.80000","1.01567","36.71210"
"147.20000","1.01621","36.60121"
"147.60000","1.01672","36.69450"
"148.00000","1.01724","36.35039"
"148.40000","1.01778","36.61969"
"148.80000","1.01829","36.96028"
"149.20000","1.01882","37.00252"
"149.60000","1.01934","36.71122"
"150.00000","1.01986","36.83707"
"150.40000","1.02040","36.81243"
"150.80000","1.02092","36.96908"
"151.20000","1.02145","37.16710"
"151.60000","1.02197","37.54201"
"152.00000","1.02250","37.14069"
"152.40000","1.02303","37.36511"
"152.80000","1.02353","37.24806"
"153.20000","1.02407","37.09141"
"153.60000","1.02461","37.48568"
"154.00000","1.02513","37.40031"
"154.40000","1.02564","37.66786"
"154.80000","1.02617","37.55521"
"155.20000","1.02670","37.37656"
"155.60000","1.02723","37.65642"
"156.00000","1.02774","37.52792"
"156.40000","1.02827","38.35607"
"156.80000","1.02880","37.62825"
"157.20000","1.02933","37.77083"
"157.60000","1.02985","37.59217"
"158.00000","1.03035","38.18270"
"158.40000","1.03089","37.90108"
"158.80000","1.03143","38.34463"
"159.20000","1.03194","38.73186"
"159.60000","1.03245","38.30767"
"160.00000","1.03299","37.84211"
"160.40000","1.03353","38.25663"
"160.80000","1.03404","38.73186"
"161.20000","1.03457","38.43352"
"161.60000","1.03510","38.75211"
"162.00000","1.03564","38.24958"
"162.40000","1.03614","38.58137"
"162.80000","1.03667","39.11558"
"163.20000","1.03719","39.12086"
"163.60000","1.03772","38.74330"
"164.00000","1.03825","39.15166"
"164.40000","1.03875","38.84099"
"164.80000","1.03929","38.94132"
"165.20000","1.03982","38.97652"
"165.60000","1.04035","38.64210"
"166.00000","1.04086","39.25903"
"166.40000","1.04139","39.60050"
"166.80000","1.04192","39.58465"
"167.20000","1.04245","39.51161"
"167.60000","1.04296","39.30215"
"168.00000","1.04349","39.79675"
"168.40000","1.04402","39.84252"
"168.80000","1.04455","40.01413"
"169.20000","1.04507","39.92436"
"169.60000","1.04558","39.99653"
"170.00000","1.04611","39.91556"
"170.40000","1.04665","40.08189"
"170.80000","1.04717","39.84340"
"171.20000","1.04768","40.33007"
"171.60000","1.04822","40.55449"
"172.00000","1.04875","40.36088"
"172.40000","1.04927","40.42776"
"172.80000","1.04978","40.25703"
"173.20000","1.05031","40.55273"
"173.60000","1.05084","40.86956"
"174.00000","1.05136","40.74459"
"174.40000","1.05188","40.65218"
"174.80000","1.05241","40.95493"
"175.20000","1.05294","40.97077"
"175.60000","1.05348","41.13094"
"176.00000","1.05399","41.26383"
"176.40000","1.05451","41.47769"
"176.80000","1.05505","41.48473"
"177.20000","1.05557","41.29903"
"177.60000","1.05609","41.08430"
"178.00000","1.05661","41.56746"
"178.40000","1.05714","41.38176"
"178.80000","1.05769","41.38440"
"179.20000","1.05819","41.68011"
"179.60000","1.05870","40.99981"
"180.00000","1.05923","41.60002"
"180.40000","1.05977","41.74963"
"180.80000","1.06030","41.57714"
"181.20000","1.06082","41.89133"
"181.60000","1.06134","41.81300"
"182.00000","1.06188","42.12366"
"182.40000","1.06239","42.01717"
"182.80000","1.06290","41.44777"
"183.20000","1.06344","42.06294"
"183.60000","1.06398","42.18615"
"184.00000","1.06451","42.66227"
"184.40000","1.06500","42.39824"
"184.80000","1.06554","42.64731"
"185.20000","1.06607","42.22927"
"185.60000","1.06659","42.32432"
"186.00000","1.06712","42.88493"
"186.40000","1.06764","42.32256"
"186.80000","1.06816","42.74675"
"187.20000","1.06869","42.65787"
"187.60000","1.06921","42.74851"
"188.00000","1.06973","42.89989"
"188.40000","1.07026","43.12519"
"188.80000","1.07080","43.12959"
"189.20000","1.07131","43.18239"
"189.60000","1.07183","43.31352"
"190.00000","1.07236","43.25544"
"190.40000","1.07290","43.31968"
"190.80000","1.07341","43.52914"
"191.20000","1.07394","43.53090"
"191.60000","1.07447","43.92253"
"192.00000","1.07499","43.65235"
"192.40000","1.07551","43.59426"
"192.80000","1.07603","44.00966"
"193.20000","1.07656","44.19007"
"193.60000","1.07710","44.00790"
"194.00000","1.07762","43.83892"
"194.40000","1.07813","44.08007"
"194.80000","1.07866","43.77116"
"195.20000","1.07920","44.22528"
"195.60000","1.07972","44.73220"
"196.00000","1.08023","44.34937"
"196.40000","1.08076","44.32296"
"196.80000","1.08130","44.74540"
"197.20000","1.08181","44.61339"
"197.60000","1.08233","44.84221"
"198.00000","1.08286","44.30360"
"198.40000","1.08338","44.78148"
"198.80000","1.08392","45.09391"
"199.20000","1.08444","44.52274"
"199.60000","1.08495","45.37641"
"200.00000","1.08548","44.96894"
"200.40000","1.08602","45.55947"
"200.80000","1.08655","45.43890"
"201.20000","1.08705","45.15287"
"201.60000","1.08758","45.42041"
"202.00000","1.08811","45.45298"
"202.40000","1.08863","45.67916"
"202.80000","1.08915","45.69148"
"203.20000","1.08969","45.69676"
"203.60000","1.09021","45.85605"
"204.00000","1.09074","45.74340"
"204.40000","1.09125","46.30665"
"204.80000","1.09177","46.01271"
"205.20000","1.09232","46.19840"
"205.60000","1.09284","46.46066"
"206.00000","1.09336","45.96430"
"206.40000","1.09388","46.05495"
"206.80000","1.09441","46.26528"
"207.20000","1.09494","46.35681"
"207.60000","1.09545","46.40434"
"208.00000","1.09598","46.61819"
"208.40000","1.09652","46.77397"
"208.80000","1.09705","46.73876"
"209.20000","1.09756","46.39113"
"209.60000","1.09808","47.20256"
"210.00000","1.09859","46.89894"
"210.40000","1.09914","46.62172"
"210.80000","1.09966","47.26505"
"211.20000","1.10018","47.07847"
"211.60000","1.10071","46.71676"
"212.00000","1.10124","47.41202"
"212.40000","1.10177","47.55723"
"212.80000","1.10227","47.58187"
"213.20000","1.10281","47.49915"
"213.60000","1.10335","47.66900"
"214.00000","1.10387","47.59948"
"214.40000","1.10438","47.63028"
"214.80000","1.10491","47.68220"
"215.20000","1.10544","48.03951"
"215.60000","1.10596","47.99199"
"216.00000","1.10648","48.15832"
"216.40000","1.10699","47.71212"
"216.80000","1.10754","47.88110"
"217.20000","1.10806","47.76933"
"217.60000","1.10858","48.25777"
"218.00000","1.10910","48.21377"
"218.40000","1.10963","48.38890"
"218.80000","1.11017","48.40298"
"219.20000","1.11067","48.37922"
"219.60000","1.11120","48.35546"
"220.00000","1.11174","48.46018"
"220.40000","1.11227","48.62124"
"220.80000","1.11278","49.20296"
"221.20000","1.11330","48.85182"
"221.60000","1.11384","48.84830"
"222.00000","1.11438","48.97063"
"222.40000","1.11488","49.14312"
"222.80000","1.11540","49.37722"
"223.20000","1.11593","49.08328"
"223.60000","1.11646","48.95039"
"224.00000","1.11699","49.08680"
"224.40000","1.11749","49.12640"
"224.80000","1.11802","49.54971"
"225.20000","1.11857","49.35346"
"225.60000","1.11909","49.37106"
"226.00000","1.11960","49.65180"
"226.40000","1.12013","49.50131"
"226.80000","1.12067","49.55235"
"227.20000","1.12119","49.74157"
"227.60000","1.12171","49.93607"
"228.00000","1.12223","50.09976"
"228.40000","1.12277","50.42978"
"228.80000","1.12329","50.14640"
"229.20000","1.12381","50.04344"
"229.60000","1.12432","50.24585"
"230.00000","1.12484","50.71053"
"230.40000","1.12538","50.91383"
"230.80000","1.12589","50.95871"
"231.20000","1.12642","50.45443"
"231.60000","1.12696","50.71845"
"232.00000","1.12749","51.53164"
"232.40000","1.12800","51.21393"
"232.80000","1.12852","51.47971"
"233.20000","1.12906","50.83550"
"233.60000","1.12960","51.45419"
"234.00000","1.13011","51.39171"
"234.40000","1.13062","51.63373"
"234.80000","1.13116","51.43395"
"235.20000","1.13169","51.54044"
"235.60000","1.13221","51.95055"
"236.00000","1.13273","51.92239"
"236.40000","1.13325","51.83878"
"236.80000","1.13379","52.25418"
"237.20000","1.13432","52.04296"
"237.60000","1.13483","51.94439"
"238.00000","1.13535","52.06232"
"238.40000","1.13588","52.10016"
"238.80000","1.13642","51.88631"
"239.20000","1.13693","52.34482"
"239.60000","1.13744","52.81038"
"240.00000","1.13797","52.70829"
"240.40000","1.13851","52.96000"
"240.80000","1.13904","52.87199"
"241.20000","1.13956","52.91335"
"241.60000","1.14008","52.80246"
"242.00000","1.14062","52.90895"
"242.40000","1.14114","53.26538"
"242.80000","1.14164","52.53140"
"243.20000","1.14217","53.20818"
"243.60000","1.14271","53.45900"
"244.00000","1.14324","53.35251"
"244.40000","1.14374","53.88671"
"244.80000","1.14427","53.32787"
"245.20000","1.14481","53.56988"
"245.60000","1.14533","53.76790"
"246.00000","1.14585","53.69398"
"246.40000","1.14638","53.47924"
"246.80000","1.14690","54.01520"
"247.20000","1.14744","53.60949"
"247.60000","1.14795","53.74502"
"248.00000","1.14847","54.00464"
"248.40000","1.14901","53.89639"
"248.80000","1.14953","54.13753"
"249.20000","1.15006","54.30738"
"249.60000","1.15057","54.81607"
"250.00000","1.15110","54.47988"
"250.40000","1.15164","54.22906"
"250.80000","1.15216","54.96480"
"251.20000","1.15268","54.69990"
"251.60000","1.15321","54.95512"
"252.00000","1.15373","54.92784"
"252.40000","1.15426","55.04049"
"252.80000","1.15477","55.08098"
"253.20000","1.15529","55.11441"
"253.60000","1.15583","55.51309"
"254.00000","1.15636","55.57909"
"254.40000","1.15687","55.30187"
"254.80000","1.15740","55.33619"
"255.20000","1.15793","55.61165"
"255.60000","1.15847","55.40307"
"256.00000","1.15897","55.80703"
"256.40000","1.15950","55.61430"
"256.80000","1.16004","55.70318"
"257.20000","1.16056","55.90208"
"257.60000","1.16108","55.86512"
"258.00000","1.16160","55.95136"
"258.40000","1.16212","55.93904"
"258.80000","1.16266","56.32099"
"259.20000","1.16317","55.81143"
"259.60000","1.16368","56.22770"
"260.00000","1.16422","56.42660"
"260.40000","1.16476","56.47941"
"260.80000","1.16528","56.72671"
"261.20000","1.16579","56.75487"
"261.60000","1.16633","56.75663"
"262.00000","1.16686","56.53045"
"262.40000","1.16737","56.95464"
"262.80000","1.16789","57.36652"
"263.20000","1.16843","57.23715"
"263.60000","1.16895","56.93441"
"264.00000","1.16948","57.09194"
"264.40000","1.16999","57.31636"
"264.80000","1.17053","57.45452"
"265.20000","1.17106","57.57333"
"265.60000","1.17158","57.70887"
"266.00000","1.17210","57.54605"
"266.40000","1.17262","57.62702"
"266.80000","1.17315","58.02922"
"267.20000","1.17369","58.17090"
"267.60000","1.17420","57.72383"
"268.00000","1.17472","58.48333"
"268.40000","1.17526","58.20259"
"268.80000","1.17579","58.14186"
"269.20000","1.17630","58.28091"
"269.60000","1.17682","58.37332"
"270.00000","1.17734","58.29235"
"270.40000","1.17788","59.01050"
"270.80000","1.17840","58.67519"
"271.20000","1.17892","58.82480"
"271.60000","1.17944","58.93129"
"272.00000","1.17998","58.65054"
"272.40000","1.18051","59.30091"
"272.80000","1.18101","59.04130"
"273.20000","1.18154","58.71655"
"273.60000","1.18208","59.34141"
"274.00000","1.18261","59.45405"
"274.40000","1.18311","59.47253"
"274.80000","1.18365","59.28772"
"275.20000","1.18418","59.58694"
"275.60000","1.18470","59.35548"
"276.00000","1.18522","59.64591"
"276.40000","1.18575","59.73567"
"276.80000","1.18628","60.04458"
"277.20000","1.18680","60.42389"
"277.60000","1.18733","59.37484"
"278.00000","1.18783","60.29804"
"278.40000","1.18837","60.50574"
"278.80000","1.18891","60.10090"
"279.20000","1.18941","60.51101"
"279.60000","1.18994","60.30860"
"280.00000","1.19047","60.30772"
"280.40000","1.19101","60.18451"
"280.80000","1.19152","60.68263"
"281.20000","1.19205","60.99241"
"281.60000","1.19258","60.72399"
"282.00000","1.19310","60.65887"
"282.40000","1.19362","61.17019"
"282.80000","1.19414","60.89473"
"283.20000","1.19467","61.12091"
"283.60000","1.19520","61.26524"
"284.00000","1.19574","61.77920"
"284.40000","1.19623","61.67271"
"284.80000","1.19677","61.56095"
"285.20000","1.19731","61.71760"
"285.60000","1.19783","61.60583"
"286.00000","1.19834","61.78272"
"286.40000","1.19887","61.74752"
"286.80000","1.19940","62.10747"
"287.20000","1.19992","61.84169"
"287.60000","1.20044","62.13563"
"288.00000","1.20096","62.28789"
"288.40000","1.20151","62.18579"
"288.80000","1.20203","62.49910"
"289.20000","1.20255","62.99458"
"289.60000","1.20306","62.98138"
"290.00000","1.20359","62.56774"
"290.40000","1.20413","62.23508"
"290.80000","1.20465","63.24364"
"291.20000","1.20516","62.79921"
"291.60000","1.20570","62.85201"
"292.00000","1.20622","63.11515"
"292.40000","1.20674","63.15828"
"292.80000","1.20726","63.26212"
"293.20000","1.20779","63.07643"
"293.60000","1.20832","63.29117"
"294.00000","1.20885","63.78313"
"294.40000","1.20937","63.46190"
"294.80000","1.20990","63.51822"
"295.20000","1.21042","64.01459"
"295.60000","1.21095","63.74001"
"296.00000","1.21147","63.97586"
"296.40000","1.21198","63.78400"
"296.80000","1.21253","64.18268"
"297.20000","1.21306","64.18708"
"297.60000","1.21356","64.26101"
"298.00000","1.21409","64.77145"
"298.40000","1.21462","64.41414"
"298.80000","1.21516","64.87969"
"299.20000","1.21567","64.48014"
"299.60000","1.21618","64.77673"
"300.00000","1.21672","64.90786"
"300.40000","1.21725","64.75032"
"300.80000","1.21777","64.98266"
"301.20000","1.21829","64.98354"
"301.60000","1.21881","64.86650"
"302.00000","1.21935","64.98795"
"302.40000","1.21987","65.06099"
"302.80000","1.22037","65.50015"
"303.20000","1.22092","65.50543"
"303.60000","1.22145","65.67000"
"304.00000","1.22199","65.64095"
"304.40000","1.22249","65.87154"
"304.80000","1.22301","66.01235"
"305.20000","1.22355","65.85393"
"305.60000","1.22407","65.89178"
"306.00000","1.22459","65.87154"
"306.40000","1.22512","66.19717"
"306.80000","1.22564","65.99387"
"307.20000","1.22618","66.18484"
"307.60000","1.22669","66.54391"
"308.00000","1.22721","66.25877"
"308.40000","1.22775","67.01300"
"308.80000","1.22828","66.64952"
"309.20000","1.22880","66.75161"
"309.60000","1.22931","67.18636"
"310.00000","1.22984","66.88274"
"310.40000","1.23038","67.08780"
"310.80000","1.23089","66.95050"
"311.20000","1.23142","67.24709"
"311.60000","1.23195","67.22773"
"312.00000","1.23247","67.31662"
"312.40000","1.23300","67.46535"
"312.80000","1.23351","67.72409"
"313.20000","1.23403","67.19869"
"313.60000","1.23458","67.91330"
"314.00000","1.23510","68.04884"
"314.40000","1.23561","68.06028"
"314.80000","1.23614","67.68801"
"315.20000","1.23667","68.18349"
"315.60000","1.23720","68.51088"
"316.00000","1.23770","67.92827"
"316.40000","1.23824","68.41759"
"316.80000","1.23878","68.42111"
"317.20000","1.23929","68.49943"
"317.60000","1.23982","68.65168"
"318.00000","1.24034","69.00724"
"318.40000","1.24086","68.50295"
"318.80000","1.24140","69.08292"
"319.20000","1.24192","69.25982"
"319.60000","1.24243","69.06268"
"320.00000","1.24296","69.10844"
"320.40000","1.24350","69.31262"
"320.80000","1.24402","69.31526"
"321.20000","1.24453","69.67433"
"321.60000","1.24506","69.80018"
"322.00000","1.24560","69.43847"
"322.40000","1.24611","70.14429"
"322.80000","1.24663","69.60041"
"323.20000","1.24717","69.54761"
"323.60000","1.24770","70.48752"
"324.00000","1.24823","70.24726"
"324.40000","1.24873","70.18125"
"324.80000","1.24927","70.92228"
"325.20000","1.24980","70.72249"
"325.60000","1.25032","70.50776"
"326.00000","1.25085","70.62921"
"326.40000","1.25136","70.26750"
"326.80000","1.25190","70.48575"
"327.20000","1.25243","70.73306"
"327.60000","1.25294","70.46904"
"328.00000","1.25346","70.72074"
"328.40000","1.25400","70.83954"
"328.80000","1.25453","70.45936"
"329.20000","1.25504","71.21798"
"329.60000","1.25555","70.85627"
"330.00000","1.25607","71.25406"
"330.40000","1.25663","71.20918"
"330.80000","1.25714","71.34207"
"331.20000","1.25766","71.19422"
"331.60000","1.25819","71.90796"
"332.00000","1.25872","71.81027"
"332.40000","1.25925","71.87451"
"332.80000","1.25975","71.78915"
"333.20000","1.26029","72.18078"
"333.60000","1.26083","72.11037"
"334.00000","1.26135","71.86043"
"334.40000","1.26186","72.19046"
"334.80000","1.26239","72.59001"
"335.20000","1.26292","72.40431"
"335.60000","1.26344","72.21070"
"336.00000","1.26396","72.69914"
"336.40000","1.26449","72.50905"
"336.80000","1.26502","72.76514"
"337.20000","1.26554","73.00629"
"337.60000","1.26607","73.07933"
"338.00000","1.26658","72.77483"
"338.40000","1.26711","73.09870"
"338.80000","1.26765","73.17174"
"339.20000","1.26817","73.24478"
"339.60000","1.26867","73.36536"
"340.00000","1.26921","73.60649"
"340.40000","1.26975","73.72883"
"340.80000","1.27027","73.97964"
"341.20000","1.27078","73.74642"
"341.60000","1.27132","74.04741"
"342.00000","1.27184","73.91100"
"342.40000","1.27236","73.79131"
"342.80000","1.27289","73.92507"
"343.20000","1.27341","74.21110"
"343.60000","1.27394","74.18030"
"344.00000","1.27447","74.39416"
"344.40000","1.27497","74.73210"
"344.80000","1.27550","74.74619"
"345.20000","1.27605","74.91956"
"345.60000","1.27657","75.14838"
"346.00000","1.27708","74.58690"
"346.40000","1.27761","75.09030"
"346.80000","1.27814","74.84916"
"347.20000","1.27868","74.88084"
"347.60000","1.27919","75.66146"
"348.00000","1.27971","75.40888"
"348.40000","1.28025","75.48985"
"348.80000","1.28077","75.36576"
"349.20000","1.28129","75.40360"
"349.60000","1.28180","75.76531"
"350.00000","1.28233","75.46169"
"350.40000","1.28287","75.99589"
"350.80000","1.28339","76.15518"
"351.20000","1.28390","76.28016"
"351.60000","1.28444","76.45177"
"352.00000","1.28497","76.40513"
"352.40000","1.28548","76.51602"
"352.80000","1.28600","76.73956"
"353.20000","1.28654","76.72195"
"353.60000","1.28707","76.47026"
"354.00000","1.28759","76.61810"
"354.40000","1.28810","77.07750"
"354.80000","1.28864","77.05726"
"355.20000","1.28916","77.28344"
"355.60000","1.28970","77.42689"
"356.00000","1.29021","77.24295"
"356.40000","1.29073","77.44009"
"356.80000","1.29127","78.09135"
"357.20000","1.29179","77.62754"
"357.60000","1.29230","77.63019"
"358.00000","1.29283","77.81940"
"358.40000","1.29336","78.10366"
"358.80000","1.29390","78.31489"
"359.20000","1.29440","78.02534"
"359.60000","1.29492","78.80772"
"360.00000","1.29546","78.73115"
"360.40000","1.29598","78.32016"
"360.80000","1.29651","78.41257"
"361.20000","1.29703","78.56306"
"361.60000","1.29756","78.93269"
"362.00000","1.29809","79.06207"
"362.40000","1.29861","79.09375"
"362.80000","1.29912","79.36217"
"363.20000","1.29966","79.52146"
"363.60000","1.30019","79.50210"
"364.00000","1.30072","80.21144"
"364.40000","1.30122","79.38505"
"364.80000","1.30175","79.44489"
"365.20000","1.30230","79.97382"
"365.60000","1.30281","80.07767"
"366.00000","1.30333","79.94038"
"366.40000","1.30386","79.92013"
"366.80000","1.30439","79.93686"
"367.20000","1.30492","80.21583"
"367.60000","1.30544","80.58635"
"368.00000","1.30595","80.47898"
"368.40000","1.30649","80.31529"
"368.80000","1.30702","80.42969"
"369.20000","1.30754","80.93310"
"369.60000","1.30805","80.70780"
"370.00000","1.30858","80.96126"
"370.40000","1.30912","80.59603"
"370.80000","1.30963","81.26224"
"371.20000","1.31016","81.32297"
"371.60000","1.31069","81.50250"
"372.00000","1.31120","81.66179"
"372.40000","1.31173","81.09503"
"372.80000","1.31225","81.74013"
"373.20000","1.31277","81.85365"
"373.60000","1.31331","82.01471"
"374.00000","1.31384","82.15640"
"374.40000","1.31435","82.00327"
"374.80000","1.31488","82.14495"
"375.20000","1.31541","82.20304"
"375.60000","1.31595","82.53835"
"376.00000","1.31645","82.68004"
"376.40000","1.31698","82.60523"
"376.80000","1.31752","82.70645"
"377.20000","1.31803","83.12888"
"377.60000","1.31855","83.32425"
"378.00000","1.31908","82.94494"
"378.40000","1.31962","83.11744"
"378.80000","1.32015","83.48619"
"379.20000","1.32065","83.37882"
"379.60000","1.32116","83.68596"
"380.00000","1.32170","83.36386"
"380.40000","1.32224","84.03536"
"380.80000","1.32277","83.66396"
"381.20000","1.32328","83.79333"
"381.60000","1.32381","83.72205"
"382.00000","1.32435","84.17352"
"382.40000","1.32485","83.97111"
"382.80000","1.32537","84.09960"
"383.20000","1.32591","83.96319"
"383.60000","1.32645","84.63996"
"384.00000","1.32697","84.48506"
"384.40000","1.32747","84.56428"
"384.80000","1.32801","84.71741"
"385.20000","1.32854","84.82918"
"385.60000","1.32906","84.99639"
"386.00000","1.32958","85.09407"
"386.40000","1.33011","85.06592"
"386.80000","1.33063","85.33170"
"387.20000","1.33117","85.41707"
"387.60000","1.33167","85.28682"
"388.00000","1.33219","85.31234"
"388.40000","1.33273","85.32378"
"388.80000","1.33327","85.58868"
"389.20000","1.33378","85.81662"
"389.60000","1.33430","85.90903"
"390.00000","1.33483","85.86854"
"390.40000","1.33536","85.57636"
"390.80000","1.33588","86.28482"
"391.20000","1.33640","85.85270"
"391.60000","1.33693","86.72045"
"392.00000","1.33746","86.42123"
"392.40000","1.33798","86.42211"
"392.80000","1.33849","86.79526"
"393.20000","1.33903","86.63069"
"393.60000","1.33956","87.32858"
"394.00000","1.34009","87.14729"
"394.40000","1.34060","86.88855"
"394.80000","1.34113","87.22034"
"395.20000","1.34166","87.36907"
"395.60000","1.34218","87.59525"
"396.00000","1.34270","87.49931"
"396.40000","1.34323","87.50460"
"396.80000","1.34375","87.43331"
"397.20000","1.34428","87.66214"
"397.60000","1.34480","87.71229"
"398.00000","1.34532","87.87335"
"398.40000","1.34586","87.62868"
"398.80000","1.34639","87.70350"
"399.20000","1.34691","88.13033"
"399.60000","1.34741","88.50084"
"400.00000","1.34795","88.66893"
"400.40000","1.34848","88.71294"
"400.80000","1.34900","88.22362"
"401.20000","1.34953","89.04472"
"401.60000","1.35005","88.55981"
"402.00000","1.35058","88.74110"
"402.40000","1.35110","89.15561"
"402.80000","1.35162","89.11777"
"403.20000","1.35214","88.76222"
"403.60000","1.35268","89.45396"
"404.00000","1.35321","89.08785"
"404.40000","1.35371","89.48212"
"404.80000","1.35424","89.20666"
"405.20000","1.35479","89.52348"
"405.60000","1.35531","89.65725"
"406.00000","1.35582","90.06649"
"406.40000","1.35635","89.46980"
"406.80000","1.35689","90.11841"
"407.20000","1.35742","90.15714"
"407.60000","1.35793","90.52149"
"408.00000","1.35845","90.46516"
"408.40000","1.35899","90.58045"
"408.80000","1.35951","90.41676"
"409.20000","1.36003","90.41412"
"409.60000","1.36054","90.61389"
"410.00000","1.36107","90.75207"
"410.40000","1.36161","90.89640"
"410.80000","1.36213","90.91840"
"411.20000","1.36265","90.95184"
"411.60000","1.36318","91.45260"
"412.00000","1.36371","91.37516"
"412.40000","1.36424","91.44821"
"412.80000","1.36474","91.61190"
"413.20000","1.36528","91.63742"
"413.60000","1.36581","91.79407"
"414.00000","1.36633","91.93048"
"414.40000","1.36684","91.85215"
"414.80000","1.36738","92.13642"
"415.20000","1.36790","91.75007"
"415.60000","1.36843","92.19626"
"416.00000","1.36895","92.40484"
"416.40000","1.36947","92.02553"
"416.80000","1.37001","92.03257"
"417.20000","1.37053","92.40132"
"417.60000","1.37105","92.30627"
"418.00000","1.37157","92.77183"
"418.40000","1.37210","92.50957"
"418.80000","1.37264","92.78151"
"419.20000","1.37315","92.54565"
"419.60000","1.37366","92.87832"
"420.00000","1.37420","92.73751"
"420.40000","1.37473","93.10538"
"420.80000","1.37525","93.26115"
"421.20000","1.37577","93.52254"
"421.60000","1.37629","93.14587"
"422.00000","1.37684","93.02529"
"422.40000","1.37736","93.60086"
"422.80000","1.37786","93.44245"
"423.20000","1.37840","93.85256"
"423.60000","1.37893","93.80328"
"424.00000","1.37946","93.89304"
"424.40000","1.37996","93.58238"
"424.80000","1.38049","93.92561"
"425.20000","1.38103","94.15618"
"425.60000","1.38155","94.21868"
"426.00000","1.38207","94.11923"
"426.40000","1.38260","94.18259"
"426.80000","1.38313","94.53374"
"427.20000","1.38365","94.38412"
"427.60000","1.38417","94.61118"
"428.00000","1.38469","94.61118"
"428.40000","1.38523","94.61646"
"428.80000","1.38575","94.80832"
"429.20000","1.38628","94.70447"
"429.60000","1.38679","95.39093"
"430.00000","1.38731","95.05298"
"430.40000","1.38786","94.95265"
"430.80000","1.38836","95.29148"
"431.20000","1.38889","95.44901"
"431.60000","1.38943","95.61094"
"432.00000","1.38995","95.76407"
"432.40000","1.39048","95.62151"
"432.80000","1.39099","95.63118"
"433.20000","1.39152","95.89697"
"433.60000","1.39206","95.94009"
"434.00000","1.39258","96.06946"
"434.40000","1.39310","95.88289"
"434.80000","1.39362","96.05979"
"435.20000","1.39415","96.16803"
"435.60000","1.39469","96.02810"
"436.00000","1.39519","96.03866"
"436.40000","1.39572","96.14602"
"436.80000","1.39626","96.72072"
"437.20000","1.39677","96.43205"
"437.60000","1.39729","96.47606"
"438.00000","1.39782","96.43646"
"438.40000","1.39834","96.96009"
"438.80000","1.39888","97.05866"
"439.20000","1.39939","97.04106"
"439.60000","1.39990","96.98034"
"440.00000","1.40045","97.03843"
"440.40000","1.40098","96.92753"
"440.80000","1.40151","97.09563"
"441.20000","1.40202","97.52686"
"441.60000","1.40255","97.23732"
"442.00000","1.40308","97.23908"
"442.40000","1.40359","97.08594"
"442.80000","1.40411","97.73016"
"443.20000","1.40465","97.81025"
"443.60000","1.40518","97.39397"
"444.00000","1.40570","97.86129"
"444.40000","1.40621","97.87186"
"444.80000","1.40673","97.75832"
"445.20000","1.40727","97.84633"
"445.60000","1.40780","98.00738"
"446.00000","1.40832","97.75304"
"446.40000","1.40884","97.75216"
"446.80000","1.40937","98.00827"
"447.20000","1.40991","98.33213"
"447.60000","1.41041","98.34709"
"448.00000","1.41094","98.27228"
"448.40000","1.41148","98.30133"
"448.80000","1.41201","98.58030"
"449.20000","1.41252","98.70528"
"449.60000","1.41304","98.64895"
"450.00000","1.41357","98.21420"
"450.40000","1.41410","98.57415"
"450.80000","1.41462","98.57855"
"451.20000","1.41515","98.86809"
"451.60000","1.41567","98.76864"
"452.00000","1.41620","98.95434"
"452.40000","1.41673","98.95610"
"452.80000","1.41723","99.05467"
"453.20000","1.41776","99.21925"
"453.60000","1.41831","99.07491"
"454.00000","1.41883","99.18140"
"454.40000","1.41933","98.81617"
"454.80000","1.41987","99.25004"
"455.20000","1.42040","99.12067"
"455.60000","1.42092","99.16995"
"456.00000","1.42144","99.04499"
"456.40000","1.42197","99.24124"
"456.80000","1.42250","99.22629"
"457.20000","1.42302","99.39174"
"457.60000","1.42355","99.41462"
"458.00000","1.42406","99.45774"
"458.40000","1.42459","99.37854"
"458.80000","1.42513","99.38910"
"459.20000","1.42563","99.39174"
"459.60000","1.42616","99.37502"
"460.00000","1.42669","99.43838"
"460.40000","1.42723","99.90306"
"460.80000","1.42775","99.25532"
"461.20000","1.42827","99.30901"
"461.60000","1.42880","99.55455"
"462.00000","1.42932","99.77809"
"462.40000","1.42984","99.20516"
"462.80000","1.43036","99.46214"
"463.20000","1.43088","99.28613"
"463.60000","1.43142","99.14268"
"464.00000","1.43195","99.23596"
"464.40000","1.43247","99.15940"
"464.80000","1.43299","99.12859"
"465.20000","1.43353","99.12332"
"465.60000","1.43405","98.88833"
"466.00000","1.43456","98.56095"
"466.40000","1.43509","98.43422"
"466.80000","1.43563","98.06987"
"467.20000","1.43616","97.87273"
"467.60000","1.43666","97.56295"
"468.00000","1.43719","96.88177"
"468.40000","1.43773","95.22636"
"468.80000","1.43825","93.33596"
"469.20000","1.43877","93.31924"
"469.60000","1.43928","93.50933"
"470.00000","1.43981","93.96961"
"470.40000","1.44035","93.82176"
"470.80000","1.44087","93.75047"
"471.20000","1.44138","94.29523"
"471.60000","1.44192","94.11042"
"472.00000","1.44245","94.47565"
"472.40000","1.44296","94.62791"
"472.80000","1.44348","94.88224"
"473.20000","1.44401","95.26243"
"473.60000","1.44455","94.77752"
"474.00000","1.44506","95.44637"
"474.40000","1.44558","95.29676"
"474.80000","1.44612","95.63118"
"475.20000","1.44664","95.83272"
"475.60000","1.44717","95.88817"
"476.00000","1.44769","96.08442"
"476.40000","1.44821","96.43821"
"476.80000","1.44875","96.26396"
"477.20000","1.44928","96.37661"
"477.60000","1.44978","96.63447"
"478.00000","1.45031","96.73568"
"478.40000","1.45084","96.75328"
"478.80000","1.45138","97.23292"
"479.20000","1.45189","97.40981"
"479.60000","1.45240","97.33853"
"480.00000","1.45294","97.66767"
"480.40000","1.45347","97.87801"
"480.80000","1.45400","98.06899"
"481.20000","1.45452","97.89385"
"481.60000","1.45504","98.09451"
"482.00000","1.45558","98.26789"
"482.40000","1.45609","98.46326"
"482.80000","1.45660","98.48526"
"483.20000","1.45714","98.48526"
"483.60000","1.45767","98.54687"
"484.00000","1.45821","98.82409"
"484.40000","1.45870","99.24037"
"484.80000","1.45923","99.04587"
"485.20000","1.45978","99.55279"
"485.60000","1.46029","99.57215"
"486.00000","1.46081","99.47534"
"486.40000","1.46134","99.66984"
"486.80000","1.46186","99.82209"
"487.20000","1.46239","99.96906"
"487.60000","1.46290","100.14948"
"488.00000","1.46342","100.48479"
"488.40000","1.46397","100.73385"
"488.80000","1.46450","100.27973"
"489.20000","1.46502","100.50063"
"489.60000","1.46553","100.66696"
"490.00000","1.46606","101.09380"
"490.40000","1.46660","101.38158"
"490.80000","1.46711","101.34726"
"491.20000","1.46763","100.92306"
"491.60000","1.46817","101.37278"
"492.00000","1.46868","101.78641"
"492.40000","1.46922","101.83922"
"492.80000","1.46974","101.45727"
"493.20000","1.47025","101.71513"
"493.60000","1.47079","101.65352"
"494.00000","1.47132","102.07596"
"494.40000","1.47184","101.96859"
"494.80000","1.47236","102.54768"
"495.20000","1.47289","102.60928"
"495.60000","1.47342","102.77385"
"496.00000","1.47393","103.12060"
"496.40000","1.47446","103.41014"
"496.80000","1.47500","103.18924"
"497.20000","1.47551","103.23501"
"497.60000","1.47604","102.92962"
"498.00000","1.47656","103.47351"
"498.40000","1.47708","103.30806"
"498.80000","1.47762","103.19101"
"499.20000","1.47814","103.76041"
"499.60000","1.47866","103.83522"
"500.00000","1.47919","104.09397"
"500.40000","1.47972","103.88803"
"500.80000","1.48024","104.10364"
"501.20000","1.48075","104.01563"
"501.60000","1.48128","104.23390"
"502.00000","1.48182","104.32102"
"502.40000","1.48233","104.70737"
"502.80000","1.48285","105.20461"
"503.20000","1.48339","104.93531"
"503.60000","1.48392","104.93355"
"504.00000","1.48444","105.02156"
"504.40000","1.48495","104.85962"
"504.80000","1.48547","105.45720"
"505.20000","1.48601","105.27238"
"505.60000","1.48654","105.39999"
"506.00000","1.48706","106.09701"
"506.40000","1.48758","105.71770"
"506.80000","1.48811","105.67986"
"507.20000","1.48864","105.49504"
"507.60000","1.48915","106.31791"
"508.00000","1.48967","105.88403"
"508.40000","1.49022","106.23078"
"508.80000","1.49075","106.81163"
"509.20000","1.49126","106.52472"
"509.60000","1.49178","106.64266"
"510.00000","1.49229","106.57137"
"510.40000","1.49284","106.90580"
"510.80000","1.49336","107.26574"
"511.20000","1.49388","107.18390"
"511.60000","1.49441","107.10821"
"512.00000","1.49494","107.15397"
"512.40000","1.49546","107.43207"
"512.80000","1.49597","107.40040"
"513.20000","1.49651","107.09501"
"513.60000","1.49705","107.89147"
"514.00000","1.49757","107.80787"
"514.40000","1.49807","107.82811"
"514.80000","1.49861","107.87035"
"515.20000","1.49914","108.24527"
"515.60000","1.49966","108.11414"
"516.00000","1.50018","108.55857"
"516.40000","1.50070","108.33415"
"516.80000","1.50125","108.84019"
"517.20000","1.50177","108.47673"
"517.60000","1.50228","108.63425"
"518.00000","1.50279","108.99861"
"518.40000","1.50333","108.97132"
"518.80000","1.50387","109.04349"
"519.20000","1.50439","109.07781"
"519.60000","1.50490","109.14294"
"520.00000","1.50544","109.71322"
"520.40000","1.50597","109.81003"
"520.80000","1.50648","109.60498"
"521.20000","1.50700","109.24062"
"521.60000","1.50753","109.57681"
"522.00000","1.50806","110.02125"
"522.40000","1.50858","109.70442"
"522.80000","1.50910","110.21487"
"523.20000","1.50964","110.24215"
"523.60000","1.51016","110.30288"
"524.00000","1.51070","110.77019"
"524.40000","1.51119","110.37505"
"524.80000","1.51172","110.68747"
"525.20000","1.51227","110.98493"
"525.60000","1.51279","110.77019"
"526.00000","1.51330","111.01398"
"526.40000","1.51383","110.62938"
"526.80000","1.51437","110.94973"
"527.20000","1.51488","111.32112"
"527.60000","1.51540","110.97436"
"528.00000","1.51593","111.21463"
"528.40000","1.51647","111.87381"
"528.80000","1.51699","111.38536"
"529.20000","1.51751","111.79108"
"529.60000","1.51803","112.01550"
"530.00000","1.51854","111.89845"
"530.40000","1.51909","111.95741"
"530.80000","1.51961","112.04630"
"531.20000","1.52012","112.23112"
"531.60000","1.52066","112.34464"
"532.00000","1.52118","112.59194"
"532.40000","1.52170","112.03574"
"532.80000","1.52222","112.51186"
"533.20000","1.52275","112.54090"
"533.60000","1.52329","112.79700"
"534.00000","1.52381","112.92461"
"534.40000","1.52433","112.84452"
"534.80000","1.52486","112.63770"
"535.20000","1.52538","113.04782"
"535.60000","1.52591","113.18159"
"536.00000","1.52643","113.23000"
"536.40000","1.52695","113.53010"
"536.80000","1.52749","113.66563"
"537.20000","1.52802","113.68236"
"537.60000","1.52852","113.87157"
"538.00000","1.52905","113.53714"
"538.40000","1.52958","113.94110"
"538.80000","1.53012","114.08103"
"539.20000","1.53063","114.27553"
"539.60000","1.53115","114.05638"
"540.00000","1.53168","114.40578"
"540.40000","1.53221","114.61963"
"540.80000","1.53274","114.61787"
"541.20000","1.53326","114.69708"
"541.60000","1.53378","114.48147"
"542.00000","1.53432","114.78861"
"542.40000","1.53484","114.92853"
"542.80000","1.53535","114.74373"
"543.20000","1.53588","115.41610"
"543.60000","1.53641","114.95055"
"544.00000","1.53694","115.42489"
"544.40000","1.53744","115.41169"
"544.80000","1.53797","115.68188"
"545.20000","1.53851","115.99605"
"545.60000","1.53903","115.66164"
"546.00000","1.53955","116.01102"
"546.40000","1.54007","116.12104"
"546.80000","1.54060","116.19057"
"547.20000","1.54114","116.42554"
"547.60000","1.54166","116.49242"
"548.00000","1.54217","116.33225"
"548.40000","1.54271","116.32433"
"548.80000","1.54324","116.54611"
"549.20000","1.54376","116.86206"
"549.60000","1.54427","116.93334"
"550.00000","1.54480","116.59540"
"550.40000","1.54534","117.19824"
"550.80000","1.54585","117.09792"
"551.20000","1.54637","117.39978"
"551.60000","1.54691","117.33554"
"552.00000","1.54743","117.77382"
"552.40000","1.54796","117.63828"
"552.80000","1.54846","118.16192"
"553.20000","1.54901","117.60572"
"553.60000","1.54954","118.25608"
"554.00000","1.55006","117.96567"
"554.40000","1.55056","118.23673"
"554.80000","1.55110","118.20240"
"555.20000","1.55163","118.49635"
"555.60000","1.55216","118.43299"
"556.00000","1.55267","118.56588"
"556.40000","1.55320","118.90647"
"556.80000","1.55374","118.60284"
"557.20000","1.55427","118.92581"
"557.60000","1.55478","119.10183"
"558.00000","1.55530","118.78413"
"558.40000","1.55582","119.78741"
"558.80000","1.55636","119.67476"
"559.20000","1.55688","119.65101"
"559.60000","1.55738","119.35530"
"560.00000","1.55792","119.48732"
"560.40000","1.55846","119.83494"
"560.80000","1.55898","120.27235"
"561.20000","1.55949","120.34186"
"561.60000","1.56003","120.14473"
"562.00000","1.56056","120.42811"
"562.40000","1.56107","120.30226"
"562.80000","1.56159","120.47564"
"563.20000","1.56213","121.02481"
"563.60000","1.56266","121.45515"
"564.00000","1.56319","121.04328"
"564.40000","1.56370","121.22194"
"564.80000","1.56421","121.14449"
"565.20000","1.56476","121.58013"
"565.60000","1.56528","121.69277"
"566.00000","1.56580","121.62060"
"566.40000","1.56632","122.04216"
"566.80000","1.56686","121.58893"
"567.20000","1.56739","121.65493"
"567.60000","1.56791","122.36428"
"568.00000","1.56842","122.44612"
"568.40000","1.56896","121.83623"
"568.80000","1.56948","122.41267"
"569.20000","1.57000","122.12753"
"569.60000","1.57052","122.55701"
"570.00000","1.57105","122.29737"
"570.40000","1.57160","123.12200"
"570.80000","1.57210","122.46812"
"571.20000","1.57262","123.05336"
"571.60000","1.57314","123.36932"
"572.00000","1.57368","123.01553"
"572.40000","1.57421","123.50132"
"572.80000","1.57471","123.07098"
"573.20000","1.57524","123.68086"
"573.60000","1.57578","123.65534"
"574.00000","1.57630","123.57261"
"574.40000","1.57681","123.55413"
"574.80000","1.57735","123.71166"
"575.20000","1.57788","124.12529"
"575.60000","1.57842","123.91760"
"576.00000","1.57892","124.57942"
"576.40000","1.57945","124.15962"
"576.80000","1.57999","124.67270"
"577.20000","1.58050","124.43683"
"577.60000","1.58102","124.90151"
"578.00000","1.58154","125.04233"
"578.40000","1.58207","125.04760"
"578.80000","1.58262","125.47180"
"579.20000","1.58313","125.49821"
"579.60000","1.58364","125.20162"
"580.00000","1.58417","125.61350"
"580.40000","1.58471","125.53428"
"580.80000","1.58523","125.93385"
"581.20000","1.58575","125.87401"
"581.60000","1.58628","126.26563"
"582.00000","1.58681","126.26827"
"582.40000","1.58732","125.97873"
"582.80000","1.58784","126.29555"
"583.20000","1.58838","126.30259"
"583.60000","1.58890","126.53141"
"584.00000","1.58943","126.84207"
"584.40000","1.58993","126.94240"
"584.80000","1.59046","126.50588"
"585.20000","1.59101","127.13603"
"585.60000","1.59153","127.24427"
"586.00000","1.59204","127.30324"
"586.40000","1.59257","127.43789"
"586.80000","1.59310","127.38860"
"587.02000","1.59339","127.42469"